Workbook
Name AwardTypeCategories: 'Dashboard'!$AD$42:$AD$42
Name SetAsideCategories: 'Dashboard'!$AG$42:$AG$42
Name PerformanceStateCategories: 'Dashboard'!$AJ$42:$AJ$42
Name VendorChoices: 'Dashboard'!$AM$1:$AM$1
Name OfficeChoices: 'Dashboard'!$AN$1:$AN$1
Name TypeChoices: 'Dashboard'!$AO$1:$AO$1

Sheet Dashboard
AM1: All | AN1: All | AO1: All
B2: Contract awards & spend | T2: Logo here | AA2: Vendor ID | AB2: =IF(H7="All","All",IF(COUNTIFS(VendorGroups[Filter label],H7)=1,INDEX(VendorGroups[Record ID],MATCH(H7,VendorGroups[Filter label],0)),"Invalid")) -> All
B3: =IF(Transactions!B3="","Buyer / market",Transactions!B3) -> Buyer / market | Q3: =IF(Transactions!G4="","Retrieved: not supplied","Retrieved "&TEXT(Transactions!G4,"mmm d, yyyy")) -> Retrieved: not supplied | AA3: Office ID | AB3: =IF(B10="All","All",IF(COUNTIFS(OfficeGroups[Filter label],B10)=1,INDEX(OfficeGroups[Record ID],MATCH(B10,OfficeGroups[Filter label],0)),"Invalid")) -> All
B4: =IF(Transactions!G3="","Add reviewed records and reporting dates to populate this workbook.",Transactions!G3) -> Add reviewed records and reporting dates to populate this workbook.
B6: Fiscal year | H6: Vendor | AA6: Net obligations | AB6: =IF(Trends!$B$6<>"","",SUMIFS(TransactionsData[Obligations],TransactionsData[Selected],1))
H7: All | AA7: Awards with obligations | AB7: =IF(Trends!$B$6<>"","",SUM(TransactionsData[First selected award]))
AA8: Vendors with obligations | AB8: =IF(Trends!$B$6<>"","",SUM(TransactionsData[First selected vendor]))
B9: Funding office | N9: Current award type | AA9: Transactions | AB9: =IF(Trends!$B$6<>"","",SUM(TransactionsData[Selected]))
B10: All | N10: All
AB11: =IF(OR(Dashboard!$B$7="All",NOT(ISNUMBER(Dashboard!$B$7))),0,IF(AND(COUNTIFS(Trends!$I$26,Dashboard!$B$7)=1,COUNTIFS(Trends!$I$26,Dashboard!$B$7-1)=1),IF(AND(INDEX(Trends!$J$26,MATCH(Dashboard!$B$7,Trends!$I$26,0))=1,INDEX(Trends!$J$26,MATCH(Dashboard!$B$7-1,Trends!$I$26,0))=1),1,0),0)) -> 0
B12: =Trends!$B$6 -> Awaiting source data
AB13: =IF(AB11=1,INDEX(Trends!$D$26,MATCH(Dashboard!$B$7-1,Trends!$I$26,0)),"")
B14: Net obligations | H14: Awards with obligations | N14: Vendors with obligations | T14: Transactions | AB14: =IF(AB11=1,INDEX(Trends!$E$26,MATCH(Dashboard!$B$7-1,Trends!$I$26,0)),"")
B15: =IF(Trends!$B$6<>"","—",TEXT(AB6/1000000,"$0.00")&"M") -> — | H15: =IF(Trends!$B$6<>"","—",AB7) -> — | N15: =IF(Trends!$B$6<>"","—",AB8) -> — | T15: =IF(Trends!$B$6<>"","—",AB9) -> — | AB15: =IF(AB11=1,INDEX(Trends!$F$26,MATCH(Dashboard!$B$7-1,Trends!$I$26,0)),"")
AB16: =IF(AB11=1,INDEX(Trends!$G$26,MATCH(Dashboard!$B$7-1,Trends!$I$26,0)),"")
B17: =IF(OR(Trends!$B$6<>"",AB11<>1),"",IF(AB13>0,TEXT((AB6-AB13)/AB13,"+0.0%;-0.0%;+0.0%")&" vs FY"&(Dashboard!$B$7-1),"")) | H17: =IF(OR(Trends!$B$6<>"",AB11<>1),"",IF(AB7=AB14,"No change vs FY"&(Dashboard!$B$7-1),TEXT(AB7-AB14,"+#,##0;-#,##0;0")&" vs FY"&(Dashboard!$B$7-1))) | N17: =IF(OR(Trends!$B$6<>"",AB11<>1),"",IF(AB8=AB15,"No change vs FY"&(Dashboard!$B$7-1),TEXT(AB8-AB15,"+#,##0;-#,##0;0")&" vs FY"&(Dashboard!$B$7-1))) | T17: =IF(OR(Trends!$B$6<>"",AB11<>1),"",IF(AB9=AB16,"No change vs FY"&(Dashboard!$B$7-1),TEXT(AB9-AB16,"+#,##0;-#,##0;0")&" vs FY"&(Dashboard!$B$7-1)))
B19: =IF(Dashboard!$B$7="All","All covered years",IF(Dashboard!$B$7="","No reporting period","FY"&Dashboard!$B$7)) -> No reporting period | H19: =IF(Dashboard!$B$7="All","All covered years",IF(Dashboard!$B$7="","No reporting period","FY"&Dashboard!$B$7)) -> No reporting period | N19: =IF(Dashboard!$B$7="All","All covered years",IF(Dashboard!$B$7="","No reporting period","FY"&Dashboard!$B$7)) -> No reporting period | T19: =IF(Dashboard!$B$7="All","All covered years",IF(Dashboard!$B$7="","No reporting period","FY"&Dashboard!$B$7)) -> No reporting period
B20: Charts in USD millions
B21: Annual net obligations | N21: Leading vendors | AA21: Category | AB21: Net obligations | AD21: Category | AE21: Net obligations
AA22: =IF(Trends!A26="","",Trends!A26) | AB22: =IF((IF(Trends!$B$6<>"","",Trends!D26))="","",(IF(Trends!$B$6<>"","",Trends!D26))/1000000) | AD22: =IF(Trends!$B$6<>"","",IF(COUNTIFS(VendorGroups[Source actions],">0")>5,"Other vendors","")) | AE22: =IF((IF(Trends!$B$6<>"","",IF(AD22="","",SUMIFS(VendorGroups[Source net],VendorGroups[Source rank],">5"))))="","",(IF(Trends!$B$6<>"","",IF(AD22="","",SUMIFS(VendorGroups[Source net],VendorGroups[Source rank],">5"))))/1000000)
AD23: =IF('Vendors & Buyers'!B12="","",'Vendors & Buyers'!B12) | AE23: =IF((IF(AD23="","",'Vendors & Buyers'!D12))="","",(IF(AD23="","",'Vendors & Buyers'!D12))/1000000)
AD24: =IF('Vendors & Buyers'!B11="","",'Vendors & Buyers'!B11) | AE24: =IF((IF(AD24="","",'Vendors & Buyers'!D11))="","",(IF(AD24="","",'Vendors & Buyers'!D11))/1000000)
AD25: =IF('Vendors & Buyers'!B10="","",'Vendors & Buyers'!B10) | AE25: =IF((IF(AD25="","",'Vendors & Buyers'!D10))="","",(IF(AD25="","",'Vendors & Buyers'!D10))/1000000)
AD26: =IF('Vendors & Buyers'!B9="","",'Vendors & Buyers'!B9) | AE26: =IF((IF(AD26="","",'Vendors & Buyers'!D9))="","",(IF(AD26="","",'Vendors & Buyers'!D9))/1000000)
AD27: =IF('Vendors & Buyers'!B8="","",'Vendors & Buyers'!B8) | AE27: =IF((IF(AD27="","",'Vendors & Buyers'!D8))="","",(IF(AD27="","",'Vendors & Buyers'!D8))/1000000)
B36: Annual and quarterly history use all covered years. Rankings and breakdowns use the selected fiscal year.
B38: Contract awards & spend — breakdowns
B39: ="USD millions | Period: "&IF(B7="All","All covered years",IF(B7="","Not supplied","FY"&B7))&" | Award type: "&N10&CHAR(10)&"Vendor: "&H7&" | Funding office: "&B10 -> USD millions | Period: Not supplied | Award type: All Vendor: All | Funding office: All | AB39: =MAX(1,COUNTIFS(Trends!$K$32:$K$35,">0")) -> 1
B40: Quarterly history · all covered years | N40: Current award types
AA41: Category | AB41: Net obligations | AD41: Category | AE41: Net obligations | AG41: Category | AH41: Net obligations | AJ41: Category | AK41: Net obligations
AA42: =IF(Trends!A32="","",Trends!A32) | AB42: =IF((IF(OR(Trends!$B$6<>"",AA42=""),"",Trends!D32))="","",(IF(OR(Trends!$B$6<>"",AA42=""),"",Trends!D32))/1000000) | AE42: =IF((IF(AD42="","",IF(Trends!$B$6<>"","",SUMIFS(TransactionsData[Obligations],TransactionsData[Current award type],AD42,TransactionsData[Selected],1))))="","",(IF(AD42="","",IF(Trends!$B$6<>"","",SUMIFS(TransactionsData[Obligations],TransactionsData[Current award type],AD42,TransactionsData[Selected],1))))/1000000) | AH42: =IF((IF(AG42="","",IF(Trends!$B$6<>"","",SUMIFS(TransactionsData[Obligations],TransactionsData[Current set-aside],AG42,TransactionsData[Selected],1))))="","",(IF(AG42="","",IF(Trends!$B$6<>"","",SUMIFS(TransactionsData[Obligations],TransactionsData[Current set-aside],AG42,TransactionsData[Selected],1))))/1000000) | AK42: =IF((IF(AJ42="","",IF(Trends!$B$6<>"","",SUMIFS(TransactionsData[Obligations],TransactionsData[Performance state],AJ42,TransactionsData[Selected],1))))="","",(IF(AJ42="","",IF(Trends!$B$6<>"","",SUMIFS(TransactionsData[Obligations],TransactionsData[Performance state],AJ42,TransactionsData[Selected],1))))/1000000)
AA43: =IF(Trends!A33="","",Trends!A33) | AB43: =IF((IF(OR(Trends!$B$6<>"",AA43=""),"",Trends!D33))="","",(IF(OR(Trends!$B$6<>"",AA43=""),"",Trends!D33))/1000000)
AA44: =IF(Trends!A34="","",Trends!A34) | AB44: =IF((IF(OR(Trends!$B$6<>"",AA44=""),"",Trends!D34))="","",(IF(OR(Trends!$B$6<>"",AA44=""),"",Trends!D34))/1000000)
AA45: =IF(Trends!A35="","",Trends!A35) | AB45: =IF((IF(OR(Trends!$B$6<>"",AA45=""),"",Trends!D35))="","",(IF(OR(Trends!$B$6<>"",AA45=""),"",Trends!D35))/1000000)
B58: Current set-asides | N58: Place of performance by state
B76: Current award snapshots; set-asides do not measure small-business participation. Location is place of performance.

Sheet Trends
A2: Trends
A3: ="Buyer: "&IF(Transactions!B3="","Not supplied",Transactions!B3)&" | History: "&IF(Transactions!B4="","Not supplied",TEXT(Transactions!B4,"mmm d, yyyy"))&" through "&IF(Transactions!D4="","Not supplied",TEXT(Transactions!D4,"mmm d, yyyy"))&" | Award type: "&Dashboard!$N$10 -> Buyer: Not supplied | History: Not supplied through Not supplied | Award type: All
A4: ="Vendor: "&Dashboard!H7&CHAR(10)&"Funding office: "&Dashboard!B10 -> Vendor: All Funding office: All
A5: Chart in USD millions; supporting tables in USD.
A6: Report status | B6: =IF(COUNTIF(AwardsData[Input check],"New category: refresh report")>0,"Refresh report for new classifications",IF(COUNTA(TransactionsData[Transaction ID])=0,"Awaiting source data",IF(OR(NOT(ISNUMBER(Transactions!B4)),NOT(ISNUMBER(Transactions!D4)),Transactions!B4>Transactions!D4,NOT(ISNUMBER(Transactions!G4))),"Enter valid coverage and retrieval dates",IF(COUNTIFS(TransactionsData[Input check],"?*")+COUNTIFS(AwardsData[Input check],"?*")+COUNTIFS(VendorGroups[Input check],"?*")+COUNTIFS(OfficeGroups[Input check],"?*")>0,"Review source input checks",IF(OR(Dashboard!$AB$2="Invalid",Dashboard!$AB$3="Invalid",AND(Dashboard!$N$10<>"All",COUNTIFS(TypeChoices,Dashboard!$N$10)<>1)),"Choose valid Dashboard filters",IF(NOT(OR(Dashboard!$B$7="All",COUNTIFS($I$26,Dashboard!$B$7)=1)),"Choose a reporting year",IF(SUMPRODUCT((TransactionsData[Eligible]=1)*(COUNTIFS(VendorGroups[Record ID],TransactionsData[Vendor ID])<>1))+SUMPRODUCT((TransactionsData[Eligible]=1)*(COUNTIFS(OfficeGroups[Record ID],TransactionsData[Funding office ID])<>1))>0,"Add missing vendor or office registry IDs",""))))))) -> Awaiting source data
A23: Four-quarter average begins after four complete consecutive quarters. Negative values retain their sign.
A25: Fiscal year | B25: Positive obligations | C25: Deobligations | D25: Net obligations | E25: Awards with obligations | F25: Vendors with obligations | G25: Transactions | H25: YoY change | I25: Year key | J25: Complete year
A26: =IF(I26="","","FY"&I26) | B26: =IF(I26="","",IF(Trends!$B$6<>"","",SUMIFS(TransactionsData[Positive],TransactionsData[FY],I26,TransactionsData[Dimension match],1))) | C26: =IF(I26="","",IF(Trends!$B$6<>"","",SUMIFS(TransactionsData[Deobligations],TransactionsData[FY],I26,TransactionsData[Dimension match],1))) | D26: =IF(I26="","",IF(Trends!$B$6<>"","",SUMIFS(TransactionsData[Obligations],TransactionsData[FY],I26,TransactionsData[Dimension match],1))) | E26: =IF(I26="","",IF(Trends!$B$6<>"","",SUMIFS(TransactionsData[First annual award],TransactionsData[FY],I26,TransactionsData[Dimension match],1))) | F26: =IF(I26="","",IF(Trends!$B$6<>"","",SUMIFS(TransactionsData[First annual vendor],TransactionsData[FY],I26,TransactionsData[Dimension match],1))) | G26: =IF(I26="","",IF(Trends!$B$6<>"","",COUNTIFS(TransactionsData[FY],I26,TransactionsData[Dimension match],1))) | H26: ="" | J26: =IF(I26="","",IF(AND(Transactions!$B$4<=DATE(I26-1,10,1),Transactions!$D$4>=DATE(I26,9,30)),1,0))
A31: Quarter | B31: From | C31: Through | D31: Net obligations | E31: Deobligations | F31: Transactions | G31: 4-quarter average | H31: Coverage | I31: Year key | J31: Quarter key | K31: Selected order | L31: Net obligations | M31: 4-quarter average
A32: =IF(I32="","","FY"&I32&" Q"&J32) | B32: =IF(I32="","",DATE(I32-IF(J32=1,1,0),CHOOSE(J32,10,1,4,7),1)) | C32: =IF(B32="","",EDATE(B32,3)-1) | D32: =IF(I32="","",IF(Trends!$B$6<>"","",SUMIFS(TransactionsData[Obligations],TransactionsData[FY],I32,TransactionsData[Quarter],J32,TransactionsData[Dimension match],1))) | E32: =IF(I32="","",IF(Trends!$B$6<>"","",SUMIFS(TransactionsData[Deobligations],TransactionsData[FY],I32,TransactionsData[Quarter],J32,TransactionsData[Dimension match],1))) | F32: =IF(I32="","",IF(Trends!$B$6<>"","",COUNTIFS(TransactionsData[FY],I32,TransactionsData[Quarter],J32,TransactionsData[Dimension match],1))) | H32: =IF(I32="","",IF(AND(B32>=Transactions!$B$4,C32<=Transactions!$D$4),"Complete","Partial")) | K32: =IF(OR(I32="",AND(Dashboard!$B$7<>"All",I32<>Dashboard!$B$7)),0,IF(Dashboard!$B$7="All",ROW()-31,J32)) -> 0 | L32: =IF(OR(Trends!$B$6<>"",I32=""),"",D32/1000000)
A33: =IF(I33="","","FY"&I33&" Q"&J33) | B33: =IF(I33="","",DATE(I33-IF(J33=1,1,0),CHOOSE(J33,10,1,4,7),1)) | C33: =IF(B33="","",EDATE(B33,3)-1) | D33: =IF(I33="","",IF(Trends!$B$6<>"","",SUMIFS(TransactionsData[Obligations],TransactionsData[FY],I33,TransactionsData[Quarter],J33,TransactionsData[Dimension match],1))) | E33: =IF(I33="","",IF(Trends!$B$6<>"","",SUMIFS(TransactionsData[Deobligations],TransactionsData[FY],I33,TransactionsData[Quarter],J33,TransactionsData[Dimension match],1))) | F33: =IF(I33="","",IF(Trends!$B$6<>"","",COUNTIFS(TransactionsData[FY],I33,TransactionsData[Quarter],J33,TransactionsData[Dimension match],1))) | H33: =IF(I33="","",IF(AND(B33>=Transactions!$B$4,C33<=Transactions!$D$4),"Complete","Partial")) | K33: =IF(OR(I33="",AND(Dashboard!$B$7<>"All",I33<>Dashboard!$B$7)),0,IF(Dashboard!$B$7="All",ROW()-31,J33)) -> 0 | L33: =IF(OR(Trends!$B$6<>"",I33=""),"",D33/1000000)
A34: =IF(I34="","","FY"&I34&" Q"&J34) | B34: =IF(I34="","",DATE(I34-IF(J34=1,1,0),CHOOSE(J34,10,1,4,7),1)) | C34: =IF(B34="","",EDATE(B34,3)-1) | D34: =IF(I34="","",IF(Trends!$B$6<>"","",SUMIFS(TransactionsData[Obligations],TransactionsData[FY],I34,TransactionsData[Quarter],J34,TransactionsData[Dimension match],1))) | E34: =IF(I34="","",IF(Trends!$B$6<>"","",SUMIFS(TransactionsData[Deobligations],TransactionsData[FY],I34,TransactionsData[Quarter],J34,TransactionsData[Dimension match],1))) | F34: =IF(I34="","",IF(Trends!$B$6<>"","",COUNTIFS(TransactionsData[FY],I34,TransactionsData[Quarter],J34,TransactionsData[Dimension match],1))) | H34: =IF(I34="","",IF(AND(B34>=Transactions!$B$4,C34<=Transactions!$D$4),"Complete","Partial")) | K34: =IF(OR(I34="",AND(Dashboard!$B$7<>"All",I34<>Dashboard!$B$7)),0,IF(Dashboard!$B$7="All",ROW()-31,J34)) -> 0 | L34: =IF(OR(Trends!$B$6<>"",I34=""),"",D34/1000000)
A35: =IF(I35="","","FY"&I35&" Q"&J35) | B35: =IF(I35="","",DATE(I35-IF(J35=1,1,0),CHOOSE(J35,10,1,4,7),1)) | C35: =IF(B35="","",EDATE(B35,3)-1) | D35: =IF(I35="","",IF(Trends!$B$6<>"","",SUMIFS(TransactionsData[Obligations],TransactionsData[FY],I35,TransactionsData[Quarter],J35,TransactionsData[Dimension match],1))) | E35: =IF(I35="","",IF(Trends!$B$6<>"","",SUMIFS(TransactionsData[Deobligations],TransactionsData[FY],I35,TransactionsData[Quarter],J35,TransactionsData[Dimension match],1))) | F35: =IF(I35="","",IF(Trends!$B$6<>"","",COUNTIFS(TransactionsData[FY],I35,TransactionsData[Quarter],J35,TransactionsData[Dimension match],1))) | G35: =IF(AND(Trends!$B$6="",COUNTIFS(H32:H35,"Complete")=4),SUM(D32:D35)/4,"") | H35: =IF(I35="","",IF(AND(B35>=Transactions!$B$4,C35<=Transactions!$D$4),"Complete","Partial")) | K35: =IF(OR(I35="",AND(Dashboard!$B$7<>"All",I35<>Dashboard!$B$7)),0,IF(Dashboard!$B$7="All",ROW()-31,J35)) -> 0 | L35: =IF(OR(Trends!$B$6<>"",I35=""),"",D35/1000000) | M35: =IF(G35="","",G35/1000000)

Sheet Vendors & Buyers
A2: Vendors & Buyers
A3: ="Buyer: "&IF(Transactions!B3="","Not supplied",Transactions!B3)&" | Period: "&IF(Dashboard!$B$7="All","All covered years",IF(Dashboard!$B$7="","Not supplied","FY"&Dashboard!$B$7))&" | Award type: "&Dashboard!$N$10 -> Buyer: Not supplied | Period: Not supplied | Award type: All
A4: ="Vendor: "&Dashboard!H7 -> Vendor: All
A5: ="Funding office: "&Dashboard!B10 -> Funding office: All
A6: Rankings follow the filters above. Award counts include nonzero obligation or deobligation actions.
A7: Rank | B7: Vendor | C7: UEI | D7: Net obligations | E7: Deobligations | F7: Awards with obligations | G7: Transactions | H7: Record ID | I7: Source name | J7: Source UEI | K7: Source URL | L7: Filter label | M7: Source net | N7: Source deobligations | O7: Source awards | P7: Source actions | Q7: Source rank | R7: Input check
A8: =IF(Trends!$B$6<>"","",IF(COUNTIFS(VendorGroups[Source rank],1)=1,1,"")) | B8: =IF(Trends!$B$6<>"","",IF(COUNTIFS(VendorGroups[Source rank],1)=1,IF(INDEX(VendorGroups[Source URL],MATCH(1,VendorGroups[Source rank],0))="",INDEX(VendorGroups[Source name],MATCH(1,VendorGroups[Source rank],0)),HYPERLINK(INDEX(VendorGroups[Source URL],MATCH(1,VendorGroups[Source rank],0)),INDEX(VendorGroups[Source name],MATCH(1,VendorGroups[Source rank],0)))),"")) | C8: =IF(Trends!$B$6<>"","",IF(COUNTIFS(VendorGroups[Source rank],1)=1,IF(INDEX(VendorGroups[Source UEI],MATCH(1,VendorGroups[Source rank],0))="","Not supplied",INDEX(VendorGroups[Source UEI],MATCH(1,VendorGroups[Source rank],0))),"")) | D8: =IF(Trends!$B$6<>"","",IF(COUNTIFS(VendorGroups[Source rank],1)=1,INDEX(VendorGroups[Source net],MATCH(1,VendorGroups[Source rank],0)),"")) | E8: =IF(Trends!$B$6<>"","",IF(COUNTIFS(VendorGroups[Source rank],1)=1,INDEX(VendorGroups[Source deobligations],MATCH(1,VendorGroups[Source rank],0)),"")) | F8: =IF(Trends!$B$6<>"","",IF(COUNTIFS(VendorGroups[Source rank],1)=1,INDEX(VendorGroups[Source awards],MATCH(1,VendorGroups[Source rank],0)),"")) | G8: =IF(Trends!$B$6<>"","",IF(COUNTIFS(VendorGroups[Source rank],1)=1,INDEX(VendorGroups[Source actions],MATCH(1,VendorGroups[Source rank],0)),"")) | L8: =IF(H8="","",I8&IF(J8="",""," ["&J8&"]")) | M8: =IF(H8="","",SUMIFS(TransactionsData[Obligations],TransactionsData[Vendor ID],H8,TransactionsData[Selected],1)) | N8: =IF(H8="","",SUMIFS(TransactionsData[Deobligations],TransactionsData[Vendor ID],H8,TransactionsData[Selected],1)) | O8: =IF(H8="","",SUMIFS(TransactionsData[First vendor award],TransactionsData[Vendor ID],H8)) | P8: =IF(H8="","",COUNTIFS(TransactionsData[Vendor ID],H8,TransactionsData[Selected],1)) | Q8: =IF(OR(H8="",P8=0),"",COUNTIFS(VendorGroups[Source net],">"&M8,VendorGroups[Source actions],">0")+COUNTIFS(VendorGroups[Source net],M8,VendorGroups[Record ID],"<"&H8,VendorGroups[Source actions],">0")+1) | R8: =IF(H8="",IF(COUNTA(I8:K8)>0,"Missing record ID",""),IF(COUNTIFS(VendorGroups[Record ID],H8)<>1,"Duplicate record ID",IF(I8="","Add name","")))
A9: =IF(Trends!$B$6<>"","",IF(COUNTIFS(VendorGroups[Source rank],2)=1,2,"")) | B9: =IF(Trends!$B$6<>"","",IF(COUNTIFS(VendorGroups[Source rank],2)=1,IF(INDEX(VendorGroups[Source URL],MATCH(2,VendorGroups[Source rank],0))="",INDEX(VendorGroups[Source name],MATCH(2,VendorGroups[Source rank],0)),HYPERLINK(INDEX(VendorGroups[Source URL],MATCH(2,VendorGroups[Source rank],0)),INDEX(VendorGroups[Source name],MATCH(2,VendorGroups[Source rank],0)))),"")) | C9: =IF(Trends!$B$6<>"","",IF(COUNTIFS(VendorGroups[Source rank],2)=1,IF(INDEX(VendorGroups[Source UEI],MATCH(2,VendorGroups[Source rank],0))="","Not supplied",INDEX(VendorGroups[Source UEI],MATCH(2,VendorGroups[Source rank],0))),"")) | D9: =IF(Trends!$B$6<>"","",IF(COUNTIFS(VendorGroups[Source rank],2)=1,INDEX(VendorGroups[Source net],MATCH(2,VendorGroups[Source rank],0)),"")) | E9: =IF(Trends!$B$6<>"","",IF(COUNTIFS(VendorGroups[Source rank],2)=1,INDEX(VendorGroups[Source deobligations],MATCH(2,VendorGroups[Source rank],0)),"")) | F9: =IF(Trends!$B$6<>"","",IF(COUNTIFS(VendorGroups[Source rank],2)=1,INDEX(VendorGroups[Source awards],MATCH(2,VendorGroups[Source rank],0)),"")) | G9: =IF(Trends!$B$6<>"","",IF(COUNTIFS(VendorGroups[Source rank],2)=1,INDEX(VendorGroups[Source actions],MATCH(2,VendorGroups[Source rank],0)),"")) | L9: =IF(H9="","",I9&IF(J9="",""," ["&J9&"]")) | M9: =IF(H9="","",SUMIFS(TransactionsData[Obligations],TransactionsData[Vendor ID],H9,TransactionsData[Selected],1)) | N9: =IF(H9="","",SUMIFS(TransactionsData[Deobligations],TransactionsData[Vendor ID],H9,TransactionsData[Selected],1)) | O9: =IF(H9="","",SUMIFS(TransactionsData[First vendor award],TransactionsData[Vendor ID],H9)) | P9: =IF(H9="","",COUNTIFS(TransactionsData[Vendor ID],H9,TransactionsData[Selected],1)) | Q9: =IF(OR(H9="",P9=0),"",COUNTIFS(VendorGroups[Source net],">"&M9,VendorGroups[Source actions],">0")+COUNTIFS(VendorGroups[Source net],M9,VendorGroups[Record ID],"<"&H9,VendorGroups[Source actions],">0")+1) | R9: =IF(H9="",IF(COUNTA(I9:K9)>0,"Missing record ID",""),IF(COUNTIFS(VendorGroups[Record ID],H9)<>1,"Duplicate record ID",IF(I9="","Add name","")))
A10: =IF(Trends!$B$6<>"","",IF(COUNTIFS(VendorGroups[Source rank],3)=1,3,"")) | B10: =IF(Trends!$B$6<>"","",IF(COUNTIFS(VendorGroups[Source rank],3)=1,IF(INDEX(VendorGroups[Source URL],MATCH(3,VendorGroups[Source rank],0))="",INDEX(VendorGroups[Source name],MATCH(3,VendorGroups[Source rank],0)),HYPERLINK(INDEX(VendorGroups[Source URL],MATCH(3,VendorGroups[Source rank],0)),INDEX(VendorGroups[Source name],MATCH(3,VendorGroups[Source rank],0)))),"")) | C10: =IF(Trends!$B$6<>"","",IF(COUNTIFS(VendorGroups[Source rank],3)=1,IF(INDEX(VendorGroups[Source UEI],MATCH(3,VendorGroups[Source rank],0))="","Not supplied",INDEX(VendorGroups[Source UEI],MATCH(3,VendorGroups[Source rank],0))),"")) | D10: =IF(Trends!$B$6<>"","",IF(COUNTIFS(VendorGroups[Source rank],3)=1,INDEX(VendorGroups[Source net],MATCH(3,VendorGroups[Source rank],0)),"")) | E10: =IF(Trends!$B$6<>"","",IF(COUNTIFS(VendorGroups[Source rank],3)=1,INDEX(VendorGroups[Source deobligations],MATCH(3,VendorGroups[Source rank],0)),"")) | F10: =IF(Trends!$B$6<>"","",IF(COUNTIFS(VendorGroups[Source rank],3)=1,INDEX(VendorGroups[Source awards],MATCH(3,VendorGroups[Source rank],0)),"")) | G10: =IF(Trends!$B$6<>"","",IF(COUNTIFS(VendorGroups[Source rank],3)=1,INDEX(VendorGroups[Source actions],MATCH(3,VendorGroups[Source rank],0)),"")) | L10: =IF(H10="","",I10&IF(J10="",""," ["&J10&"]")) | M10: =IF(H10="","",SUMIFS(TransactionsData[Obligations],TransactionsData[Vendor ID],H10,TransactionsData[Selected],1)) | N10: =IF(H10="","",SUMIFS(TransactionsData[Deobligations],TransactionsData[Vendor ID],H10,TransactionsData[Selected],1)) | O10: =IF(H10="","",SUMIFS(TransactionsData[First vendor award],TransactionsData[Vendor ID],H10)) | P10: =IF(H10="","",COUNTIFS(TransactionsData[Vendor ID],H10,TransactionsData[Selected],1)) | Q10: =IF(OR(H10="",P10=0),"",COUNTIFS(VendorGroups[Source net],">"&M10,VendorGroups[Source actions],">0")+COUNTIFS(VendorGroups[Source net],M10,VendorGroups[Record ID],"<"&H10,VendorGroups[Source actions],">0")+1) | R10: =IF(H10="",IF(COUNTA(I10:K10)>0,"Missing record ID",""),IF(COUNTIFS(VendorGroups[Record ID],H10)<>1,"Duplicate record ID",IF(I10="","Add name","")))
A11: =IF(Trends!$B$6<>"","",IF(COUNTIFS(VendorGroups[Source rank],4)=1,4,"")) | B11: =IF(Trends!$B$6<>"","",IF(COUNTIFS(VendorGroups[Source rank],4)=1,IF(INDEX(VendorGroups[Source URL],MATCH(4,VendorGroups[Source rank],0))="",INDEX(VendorGroups[Source name],MATCH(4,VendorGroups[Source rank],0)),HYPERLINK(INDEX(VendorGroups[Source URL],MATCH(4,VendorGroups[Source rank],0)),INDEX(VendorGroups[Source name],MATCH(4,VendorGroups[Source rank],0)))),"")) | C11: =IF(Trends!$B$6<>"","",IF(COUNTIFS(VendorGroups[Source rank],4)=1,IF(INDEX(VendorGroups[Source UEI],MATCH(4,VendorGroups[Source rank],0))="","Not supplied",INDEX(VendorGroups[Source UEI],MATCH(4,VendorGroups[Source rank],0))),"")) | D11: =IF(Trends!$B$6<>"","",IF(COUNTIFS(VendorGroups[Source rank],4)=1,INDEX(VendorGroups[Source net],MATCH(4,VendorGroups[Source rank],0)),"")) | E11: =IF(Trends!$B$6<>"","",IF(COUNTIFS(VendorGroups[Source rank],4)=1,INDEX(VendorGroups[Source deobligations],MATCH(4,VendorGroups[Source rank],0)),"")) | F11: =IF(Trends!$B$6<>"","",IF(COUNTIFS(VendorGroups[Source rank],4)=1,INDEX(VendorGroups[Source awards],MATCH(4,VendorGroups[Source rank],0)),"")) | G11: =IF(Trends!$B$6<>"","",IF(COUNTIFS(VendorGroups[Source rank],4)=1,INDEX(VendorGroups[Source actions],MATCH(4,VendorGroups[Source rank],0)),"")) | L11: =IF(H11="","",I11&IF(J11="",""," ["&J11&"]")) | M11: =IF(H11="","",SUMIFS(TransactionsData[Obligations],TransactionsData[Vendor ID],H11,TransactionsData[Selected],1)) | N11: =IF(H11="","",SUMIFS(TransactionsData[Deobligations],TransactionsData[Vendor ID],H11,TransactionsData[Selected],1)) | O11: =IF(H11="","",SUMIFS(TransactionsData[First vendor award],TransactionsData[Vendor ID],H11)) | P11: =IF(H11="","",COUNTIFS(TransactionsData[Vendor ID],H11,TransactionsData[Selected],1)) | Q11: =IF(OR(H11="",P11=0),"",COUNTIFS(VendorGroups[Source net],">"&M11,VendorGroups[Source actions],">0")+COUNTIFS(VendorGroups[Source net],M11,VendorGroups[Record ID],"<"&H11,VendorGroups[Source actions],">0")+1) | R11: =IF(H11="",IF(COUNTA(I11:K11)>0,"Missing record ID",""),IF(COUNTIFS(VendorGroups[Record ID],H11)<>1,"Duplicate record ID",IF(I11="","Add name","")))
A12: =IF(Trends!$B$6<>"","",IF(COUNTIFS(VendorGroups[Source rank],5)=1,5,"")) | B12: =IF(Trends!$B$6<>"","",IF(COUNTIFS(VendorGroups[Source rank],5)=1,IF(INDEX(VendorGroups[Source URL],MATCH(5,VendorGroups[Source rank],0))="",INDEX(VendorGroups[Source name],MATCH(5,VendorGroups[Source rank],0)),HYPERLINK(INDEX(VendorGroups[Source URL],MATCH(5,VendorGroups[Source rank],0)),INDEX(VendorGroups[Source name],MATCH(5,VendorGroups[Source rank],0)))),"")) | C12: =IF(Trends!$B$6<>"","",IF(COUNTIFS(VendorGroups[Source rank],5)=1,IF(INDEX(VendorGroups[Source UEI],MATCH(5,VendorGroups[Source rank],0))="","Not supplied",INDEX(VendorGroups[Source UEI],MATCH(5,VendorGroups[Source rank],0))),"")) | D12: =IF(Trends!$B$6<>"","",IF(COUNTIFS(VendorGroups[Source rank],5)=1,INDEX(VendorGroups[Source net],MATCH(5,VendorGroups[Source rank],0)),"")) | E12: =IF(Trends!$B$6<>"","",IF(COUNTIFS(VendorGroups[Source rank],5)=1,INDEX(VendorGroups[Source deobligations],MATCH(5,VendorGroups[Source rank],0)),"")) | F12: =IF(Trends!$B$6<>"","",IF(COUNTIFS(VendorGroups[Source rank],5)=1,INDEX(VendorGroups[Source awards],MATCH(5,VendorGroups[Source rank],0)),"")) | G12: =IF(Trends!$B$6<>"","",IF(COUNTIFS(VendorGroups[Source rank],5)=1,INDEX(VendorGroups[Source actions],MATCH(5,VendorGroups[Source rank],0)),"")) | L12: =IF(H12="","",I12&IF(J12="",""," ["&J12&"]")) | M12: =IF(H12="","",SUMIFS(TransactionsData[Obligations],TransactionsData[Vendor ID],H12,TransactionsData[Selected],1)) | N12: =IF(H12="","",SUMIFS(TransactionsData[Deobligations],TransactionsData[Vendor ID],H12,TransactionsData[Selected],1)) | O12: =IF(H12="","",SUMIFS(TransactionsData[First vendor award],TransactionsData[Vendor ID],H12)) | P12: =IF(H12="","",COUNTIFS(TransactionsData[Vendor ID],H12,TransactionsData[Selected],1)) | Q12: =IF(OR(H12="",P12=0),"",COUNTIFS(VendorGroups[Source net],">"&M12,VendorGroups[Source actions],">0")+COUNTIFS(VendorGroups[Source net],M12,VendorGroups[Record ID],"<"&H12,VendorGroups[Source actions],">0")+1) | R12: =IF(H12="",IF(COUNTA(I12:K12)>0,"Missing record ID",""),IF(COUNTIFS(VendorGroups[Record ID],H12)<>1,"Duplicate record ID",IF(I12="","Add name","")))
A13: =IF(Trends!$B$6<>"","",IF(COUNTIFS(VendorGroups[Source rank],6)=1,6,"")) | B13: =IF(Trends!$B$6<>"","",IF(COUNTIFS(VendorGroups[Source rank],6)=1,IF(INDEX(VendorGroups[Source URL],MATCH(6,VendorGroups[Source rank],0))="",INDEX(VendorGroups[Source name],MATCH(6,VendorGroups[Source rank],0)),HYPERLINK(INDEX(VendorGroups[Source URL],MATCH(6,VendorGroups[Source rank],0)),INDEX(VendorGroups[Source name],MATCH(6,VendorGroups[Source rank],0)))),"")) | C13: =IF(Trends!$B$6<>"","",IF(COUNTIFS(VendorGroups[Source rank],6)=1,IF(INDEX(VendorGroups[Source UEI],MATCH(6,VendorGroups[Source rank],0))="","Not supplied",INDEX(VendorGroups[Source UEI],MATCH(6,VendorGroups[Source rank],0))),"")) | D13: =IF(Trends!$B$6<>"","",IF(COUNTIFS(VendorGroups[Source rank],6)=1,INDEX(VendorGroups[Source net],MATCH(6,VendorGroups[Source rank],0)),"")) | E13: =IF(Trends!$B$6<>"","",IF(COUNTIFS(VendorGroups[Source rank],6)=1,INDEX(VendorGroups[Source deobligations],MATCH(6,VendorGroups[Source rank],0)),"")) | F13: =IF(Trends!$B$6<>"","",IF(COUNTIFS(VendorGroups[Source rank],6)=1,INDEX(VendorGroups[Source awards],MATCH(6,VendorGroups[Source rank],0)),"")) | G13: =IF(Trends!$B$6<>"","",IF(COUNTIFS(VendorGroups[Source rank],6)=1,INDEX(VendorGroups[Source actions],MATCH(6,VendorGroups[Source rank],0)),"")) | L13: =IF(H13="","",I13&IF(J13="",""," ["&J13&"]")) | M13: =IF(H13="","",SUMIFS(TransactionsData[Obligations],TransactionsData[Vendor ID],H13,TransactionsData[Selected],1)) | N13: =IF(H13="","",SUMIFS(TransactionsData[Deobligations],TransactionsData[Vendor ID],H13,TransactionsData[Selected],1)) | O13: =IF(H13="","",SUMIFS(TransactionsData[First vendor award],TransactionsData[Vendor ID],H13)) | P13: =IF(H13="","",COUNTIFS(TransactionsData[Vendor ID],H13,TransactionsData[Selected],1)) | Q13: =IF(OR(H13="",P13=0),"",COUNTIFS(VendorGroups[Source net],">"&M13,VendorGroups[Source actions],">0")+COUNTIFS(VendorGroups[Source net],M13,VendorGroups[Record ID],"<"&H13,VendorGroups[Source actions],">0")+1) | R13: =IF(H13="",IF(COUNTA(I13:K13)>0,"Missing record ID",""),IF(COUNTIFS(VendorGroups[Record ID],H13)<>1,"Duplicate record ID",IF(I13="","Add name","")))
A14: =IF(Trends!$B$6<>"","",IF(COUNTIFS(VendorGroups[Source rank],7)=1,7,"")) | B14: =IF(Trends!$B$6<>"","",IF(COUNTIFS(VendorGroups[Source rank],7)=1,IF(INDEX(VendorGroups[Source URL],MATCH(7,VendorGroups[Source rank],0))="",INDEX(VendorGroups[Source name],MATCH(7,VendorGroups[Source rank],0)),HYPERLINK(INDEX(VendorGroups[Source URL],MATCH(7,VendorGroups[Source rank],0)),INDEX(VendorGroups[Source name],MATCH(7,VendorGroups[Source rank],0)))),"")) | C14: =IF(Trends!$B$6<>"","",IF(COUNTIFS(VendorGroups[Source rank],7)=1,IF(INDEX(VendorGroups[Source UEI],MATCH(7,VendorGroups[Source rank],0))="","Not supplied",INDEX(VendorGroups[Source UEI],MATCH(7,VendorGroups[Source rank],0))),"")) | D14: =IF(Trends!$B$6<>"","",IF(COUNTIFS(VendorGroups[Source rank],7)=1,INDEX(VendorGroups[Source net],MATCH(7,VendorGroups[Source rank],0)),"")) | E14: =IF(Trends!$B$6<>"","",IF(COUNTIFS(VendorGroups[Source rank],7)=1,INDEX(VendorGroups[Source deobligations],MATCH(7,VendorGroups[Source rank],0)),"")) | F14: =IF(Trends!$B$6<>"","",IF(COUNTIFS(VendorGroups[Source rank],7)=1,INDEX(VendorGroups[Source awards],MATCH(7,VendorGroups[Source rank],0)),"")) | G14: =IF(Trends!$B$6<>"","",IF(COUNTIFS(VendorGroups[Source rank],7)=1,INDEX(VendorGroups[Source actions],MATCH(7,VendorGroups[Source rank],0)),"")) | L14: =IF(H14="","",I14&IF(J14="",""," ["&J14&"]")) | M14: =IF(H14="","",SUMIFS(TransactionsData[Obligations],TransactionsData[Vendor ID],H14,TransactionsData[Selected],1)) | N14: =IF(H14="","",SUMIFS(TransactionsData[Deobligations],TransactionsData[Vendor ID],H14,TransactionsData[Selected],1)) | O14: =IF(H14="","",SUMIFS(TransactionsData[First vendor award],TransactionsData[Vendor ID],H14)) | P14: =IF(H14="","",COUNTIFS(TransactionsData[Vendor ID],H14,TransactionsData[Selected],1)) | Q14: =IF(OR(H14="",P14=0),"",COUNTIFS(VendorGroups[Source net],">"&M14,VendorGroups[Source actions],">0")+COUNTIFS(VendorGroups[Source net],M14,VendorGroups[Record ID],"<"&H14,VendorGroups[Source actions],">0")+1) | R14: =IF(H14="",IF(COUNTA(I14:K14)>0,"Missing record ID",""),IF(COUNTIFS(VendorGroups[Record ID],H14)<>1,"Duplicate record ID",IF(I14="","Add name","")))
A15: =IF(Trends!$B$6<>"","",IF(COUNTIFS(VendorGroups[Source rank],8)=1,8,"")) | B15: =IF(Trends!$B$6<>"","",IF(COUNTIFS(VendorGroups[Source rank],8)=1,IF(INDEX(VendorGroups[Source URL],MATCH(8,VendorGroups[Source rank],0))="",INDEX(VendorGroups[Source name],MATCH(8,VendorGroups[Source rank],0)),HYPERLINK(INDEX(VendorGroups[Source URL],MATCH(8,VendorGroups[Source rank],0)),INDEX(VendorGroups[Source name],MATCH(8,VendorGroups[Source rank],0)))),"")) | C15: =IF(Trends!$B$6<>"","",IF(COUNTIFS(VendorGroups[Source rank],8)=1,IF(INDEX(VendorGroups[Source UEI],MATCH(8,VendorGroups[Source rank],0))="","Not supplied",INDEX(VendorGroups[Source UEI],MATCH(8,VendorGroups[Source rank],0))),"")) | D15: =IF(Trends!$B$6<>"","",IF(COUNTIFS(VendorGroups[Source rank],8)=1,INDEX(VendorGroups[Source net],MATCH(8,VendorGroups[Source rank],0)),"")) | E15: =IF(Trends!$B$6<>"","",IF(COUNTIFS(VendorGroups[Source rank],8)=1,INDEX(VendorGroups[Source deobligations],MATCH(8,VendorGroups[Source rank],0)),"")) | F15: =IF(Trends!$B$6<>"","",IF(COUNTIFS(VendorGroups[Source rank],8)=1,INDEX(VendorGroups[Source awards],MATCH(8,VendorGroups[Source rank],0)),"")) | G15: =IF(Trends!$B$6<>"","",IF(COUNTIFS(VendorGroups[Source rank],8)=1,INDEX(VendorGroups[Source actions],MATCH(8,VendorGroups[Source rank],0)),"")) | L15: =IF(H15="","",I15&IF(J15="",""," ["&J15&"]")) | M15: =IF(H15="","",SUMIFS(TransactionsData[Obligations],TransactionsData[Vendor ID],H15,TransactionsData[Selected],1)) | N15: =IF(H15="","",SUMIFS(TransactionsData[Deobligations],TransactionsData[Vendor ID],H15,TransactionsData[Selected],1)) | O15: =IF(H15="","",SUMIFS(TransactionsData[First vendor award],TransactionsData[Vendor ID],H15)) | P15: =IF(H15="","",COUNTIFS(TransactionsData[Vendor ID],H15,TransactionsData[Selected],1)) | Q15: =IF(OR(H15="",P15=0),"",COUNTIFS(VendorGroups[Source net],">"&M15,VendorGroups[Source actions],">0")+COUNTIFS(VendorGroups[Source net],M15,VendorGroups[Record ID],"<"&H15,VendorGroups[Source actions],">0")+1) | R15: =IF(H15="",IF(COUNTA(I15:K15)>0,"Missing record ID",""),IF(COUNTIFS(VendorGroups[Record ID],H15)<>1,"Duplicate record ID",IF(I15="","Add name","")))
A16: =IF(Trends!$B$6<>"","",IF(COUNTIFS(VendorGroups[Source rank],9)=1,9,"")) | B16: =IF(Trends!$B$6<>"","",IF(COUNTIFS(VendorGroups[Source rank],9)=1,IF(INDEX(VendorGroups[Source URL],MATCH(9,VendorGroups[Source rank],0))="",INDEX(VendorGroups[Source name],MATCH(9,VendorGroups[Source rank],0)),HYPERLINK(INDEX(VendorGroups[Source URL],MATCH(9,VendorGroups[Source rank],0)),INDEX(VendorGroups[Source name],MATCH(9,VendorGroups[Source rank],0)))),"")) | C16: =IF(Trends!$B$6<>"","",IF(COUNTIFS(VendorGroups[Source rank],9)=1,IF(INDEX(VendorGroups[Source UEI],MATCH(9,VendorGroups[Source rank],0))="","Not supplied",INDEX(VendorGroups[Source UEI],MATCH(9,VendorGroups[Source rank],0))),"")) | D16: =IF(Trends!$B$6<>"","",IF(COUNTIFS(VendorGroups[Source rank],9)=1,INDEX(VendorGroups[Source net],MATCH(9,VendorGroups[Source rank],0)),"")) | E16: =IF(Trends!$B$6<>"","",IF(COUNTIFS(VendorGroups[Source rank],9)=1,INDEX(VendorGroups[Source deobligations],MATCH(9,VendorGroups[Source rank],0)),"")) | F16: =IF(Trends!$B$6<>"","",IF(COUNTIFS(VendorGroups[Source rank],9)=1,INDEX(VendorGroups[Source awards],MATCH(9,VendorGroups[Source rank],0)),"")) | G16: =IF(Trends!$B$6<>"","",IF(COUNTIFS(VendorGroups[Source rank],9)=1,INDEX(VendorGroups[Source actions],MATCH(9,VendorGroups[Source rank],0)),"")) | L16: =IF(H16="","",I16&IF(J16="",""," ["&J16&"]")) | M16: =IF(H16="","",SUMIFS(TransactionsData[Obligations],TransactionsData[Vendor ID],H16,TransactionsData[Selected],1)) | N16: =IF(H16="","",SUMIFS(TransactionsData[Deobligations],TransactionsData[Vendor ID],H16,TransactionsData[Selected],1)) | O16: =IF(H16="","",SUMIFS(TransactionsData[First vendor award],TransactionsData[Vendor ID],H16)) | P16: =IF(H16="","",COUNTIFS(TransactionsData[Vendor ID],H16,TransactionsData[Selected],1)) | Q16: =IF(OR(H16="",P16=0),"",COUNTIFS(VendorGroups[Source net],">"&M16,VendorGroups[Source actions],">0")+COUNTIFS(VendorGroups[Source net],M16,VendorGroups[Record ID],"<"&H16,VendorGroups[Source actions],">0")+1) | R16: =IF(H16="",IF(COUNTA(I16:K16)>0,"Missing record ID",""),IF(COUNTIFS(VendorGroups[Record ID],H16)<>1,"Duplicate record ID",IF(I16="","Add name","")))
A17: =IF(Trends!$B$6<>"","",IF(COUNTIFS(VendorGroups[Source rank],10)=1,10,"")) | B17: =IF(Trends!$B$6<>"","",IF(COUNTIFS(VendorGroups[Source rank],10)=1,IF(INDEX(VendorGroups[Source URL],MATCH(10,VendorGroups[Source rank],0))="",INDEX(VendorGroups[Source name],MATCH(10,VendorGroups[Source rank],0)),HYPERLINK(INDEX(VendorGroups[Source URL],MATCH(10,VendorGroups[Source rank],0)),INDEX(VendorGroups[Source name],MATCH(10,VendorGroups[Source rank],0)))),"")) | C17: =IF(Trends!$B$6<>"","",IF(COUNTIFS(VendorGroups[Source rank],10)=1,IF(INDEX(VendorGroups[Source UEI],MATCH(10,VendorGroups[Source rank],0))="","Not supplied",INDEX(VendorGroups[Source UEI],MATCH(10,VendorGroups[Source rank],0))),"")) | D17: =IF(Trends!$B$6<>"","",IF(COUNTIFS(VendorGroups[Source rank],10)=1,INDEX(VendorGroups[Source net],MATCH(10,VendorGroups[Source rank],0)),"")) | E17: =IF(Trends!$B$6<>"","",IF(COUNTIFS(VendorGroups[Source rank],10)=1,INDEX(VendorGroups[Source deobligations],MATCH(10,VendorGroups[Source rank],0)),"")) | F17: =IF(Trends!$B$6<>"","",IF(COUNTIFS(VendorGroups[Source rank],10)=1,INDEX(VendorGroups[Source awards],MATCH(10,VendorGroups[Source rank],0)),"")) | G17: =IF(Trends!$B$6<>"","",IF(COUNTIFS(VendorGroups[Source rank],10)=1,INDEX(VendorGroups[Source actions],MATCH(10,VendorGroups[Source rank],0)),"")) | L17: =IF(H17="","",I17&IF(J17="",""," ["&J17&"]")) | M17: =IF(H17="","",SUMIFS(TransactionsData[Obligations],TransactionsData[Vendor ID],H17,TransactionsData[Selected],1)) | N17: =IF(H17="","",SUMIFS(TransactionsData[Deobligations],TransactionsData[Vendor ID],H17,TransactionsData[Selected],1)) | O17: =IF(H17="","",SUMIFS(TransactionsData[First vendor award],TransactionsData[Vendor ID],H17)) | P17: =IF(H17="","",COUNTIFS(TransactionsData[Vendor ID],H17,TransactionsData[Selected],1)) | Q17: =IF(OR(H17="",P17=0),"",COUNTIFS(VendorGroups[Source net],">"&M17,VendorGroups[Source actions],">0")+COUNTIFS(VendorGroups[Source net],M17,VendorGroups[Record ID],"<"&H17,VendorGroups[Source actions],">0")+1) | R17: =IF(H17="",IF(COUNTA(I17:K17)>0,"Missing record ID",""),IF(COUNTIFS(VendorGroups[Record ID],H17)<>1,"Duplicate record ID",IF(I17="","Add name","")))
A18: =IF(Trends!$B$6<>"","",IF(COUNTIFS(VendorGroups[Source rank],11)=1,11,"")) | B18: =IF(Trends!$B$6<>"","",IF(COUNTIFS(VendorGroups[Source rank],11)=1,IF(INDEX(VendorGroups[Source URL],MATCH(11,VendorGroups[Source rank],0))="",INDEX(VendorGroups[Source name],MATCH(11,VendorGroups[Source rank],0)),HYPERLINK(INDEX(VendorGroups[Source URL],MATCH(11,VendorGroups[Source rank],0)),INDEX(VendorGroups[Source name],MATCH(11,VendorGroups[Source rank],0)))),"")) | C18: =IF(Trends!$B$6<>"","",IF(COUNTIFS(VendorGroups[Source rank],11)=1,IF(INDEX(VendorGroups[Source UEI],MATCH(11,VendorGroups[Source rank],0))="","Not supplied",INDEX(VendorGroups[Source UEI],MATCH(11,VendorGroups[Source rank],0))),"")) | D18: =IF(Trends!$B$6<>"","",IF(COUNTIFS(VendorGroups[Source rank],11)=1,INDEX(VendorGroups[Source net],MATCH(11,VendorGroups[Source rank],0)),"")) | E18: =IF(Trends!$B$6<>"","",IF(COUNTIFS(VendorGroups[Source rank],11)=1,INDEX(VendorGroups[Source deobligations],MATCH(11,VendorGroups[Source rank],0)),"")) | F18: =IF(Trends!$B$6<>"","",IF(COUNTIFS(VendorGroups[Source rank],11)=1,INDEX(VendorGroups[Source awards],MATCH(11,VendorGroups[Source rank],0)),"")) | G18: =IF(Trends!$B$6<>"","",IF(COUNTIFS(VendorGroups[Source rank],11)=1,INDEX(VendorGroups[Source actions],MATCH(11,VendorGroups[Source rank],0)),"")) | L18: =IF(H18="","",I18&IF(J18="",""," ["&J18&"]")) | M18: =IF(H18="","",SUMIFS(TransactionsData[Obligations],TransactionsData[Vendor ID],H18,TransactionsData[Selected],1)) | N18: =IF(H18="","",SUMIFS(TransactionsData[Deobligations],TransactionsData[Vendor ID],H18,TransactionsData[Selected],1)) | O18: =IF(H18="","",SUMIFS(TransactionsData[First vendor award],TransactionsData[Vendor ID],H18)) | P18: =IF(H18="","",COUNTIFS(TransactionsData[Vendor ID],H18,TransactionsData[Selected],1)) | Q18: =IF(OR(H18="",P18=0),"",COUNTIFS(VendorGroups[Source net],">"&M18,VendorGroups[Source actions],">0")+COUNTIFS(VendorGroups[Source net],M18,VendorGroups[Record ID],"<"&H18,VendorGroups[Source actions],">0")+1) | R18: =IF(H18="",IF(COUNTA(I18:K18)>0,"Missing record ID",""),IF(COUNTIFS(VendorGroups[Record ID],H18)<>1,"Duplicate record ID",IF(I18="","Add name","")))
A19: =IF(Trends!$B$6<>"","",IF(COUNTIFS(VendorGroups[Source rank],12)=1,12,"")) | B19: =IF(Trends!$B$6<>"","",IF(COUNTIFS(VendorGroups[Source rank],12)=1,IF(INDEX(VendorGroups[Source URL],MATCH(12,VendorGroups[Source rank],0))="",INDEX(VendorGroups[Source name],MATCH(12,VendorGroups[Source rank],0)),HYPERLINK(INDEX(VendorGroups[Source URL],MATCH(12,VendorGroups[Source rank],0)),INDEX(VendorGroups[Source name],MATCH(12,VendorGroups[Source rank],0)))),"")) | C19: =IF(Trends!$B$6<>"","",IF(COUNTIFS(VendorGroups[Source rank],12)=1,IF(INDEX(VendorGroups[Source UEI],MATCH(12,VendorGroups[Source rank],0))="","Not supplied",INDEX(VendorGroups[Source UEI],MATCH(12,VendorGroups[Source rank],0))),"")) | D19: =IF(Trends!$B$6<>"","",IF(COUNTIFS(VendorGroups[Source rank],12)=1,INDEX(VendorGroups[Source net],MATCH(12,VendorGroups[Source rank],0)),"")) | E19: =IF(Trends!$B$6<>"","",IF(COUNTIFS(VendorGroups[Source rank],12)=1,INDEX(VendorGroups[Source deobligations],MATCH(12,VendorGroups[Source rank],0)),"")) | F19: =IF(Trends!$B$6<>"","",IF(COUNTIFS(VendorGroups[Source rank],12)=1,INDEX(VendorGroups[Source awards],MATCH(12,VendorGroups[Source rank],0)),"")) | G19: =IF(Trends!$B$6<>"","",IF(COUNTIFS(VendorGroups[Source rank],12)=1,INDEX(VendorGroups[Source actions],MATCH(12,VendorGroups[Source rank],0)),"")) | L19: =IF(H19="","",I19&IF(J19="",""," ["&J19&"]")) | M19: =IF(H19="","",SUMIFS(TransactionsData[Obligations],TransactionsData[Vendor ID],H19,TransactionsData[Selected],1)) | N19: =IF(H19="","",SUMIFS(TransactionsData[Deobligations],TransactionsData[Vendor ID],H19,TransactionsData[Selected],1)) | O19: =IF(H19="","",SUMIFS(TransactionsData[First vendor award],TransactionsData[Vendor ID],H19)) | P19: =IF(H19="","",COUNTIFS(TransactionsData[Vendor ID],H19,TransactionsData[Selected],1)) | Q19: =IF(OR(H19="",P19=0),"",COUNTIFS(VendorGroups[Source net],">"&M19,VendorGroups[Source actions],">0")+COUNTIFS(VendorGroups[Source net],M19,VendorGroups[Record ID],"<"&H19,VendorGroups[Source actions],">0")+1) | R19: =IF(H19="",IF(COUNTA(I19:K19)>0,"Missing record ID",""),IF(COUNTIFS(VendorGroups[Record ID],H19)<>1,"Duplicate record ID",IF(I19="","Add name","")))
A24: Rank | B24: Funding office | C24: Office code | D24: Net obligations | E24: Deobligations | F24: Awards with obligations | G24: Transactions | H24: Record ID | I24: Source name | J24: Source UEI | K24: Source URL | L24: Filter label | M24: Source net | N24: Source deobligations | O24: Source awards | P24: Source actions | Q24: Source rank | R24: Input check
A25: =IF(Trends!$B$6<>"","",IF(COUNTIFS(OfficeGroups[Source rank],1)=1,1,"")) | B25: =IF(Trends!$B$6<>"","",IF(COUNTIFS(OfficeGroups[Source rank],1)=1,IF(INDEX(OfficeGroups[Source URL],MATCH(1,OfficeGroups[Source rank],0))="",INDEX(OfficeGroups[Source name],MATCH(1,OfficeGroups[Source rank],0)),HYPERLINK(INDEX(OfficeGroups[Source URL],MATCH(1,OfficeGroups[Source rank],0)),INDEX(OfficeGroups[Source name],MATCH(1,OfficeGroups[Source rank],0)))),"")) | C25: =IF(Trends!$B$6<>"","",IF(COUNTIFS(OfficeGroups[Source rank],1)=1,IF(INDEX(OfficeGroups[Source UEI],MATCH(1,OfficeGroups[Source rank],0))="","Not supplied",INDEX(OfficeGroups[Source UEI],MATCH(1,OfficeGroups[Source rank],0))),"")) | D25: =IF(Trends!$B$6<>"","",IF(COUNTIFS(OfficeGroups[Source rank],1)=1,INDEX(OfficeGroups[Source net],MATCH(1,OfficeGroups[Source rank],0)),"")) | E25: =IF(Trends!$B$6<>"","",IF(COUNTIFS(OfficeGroups[Source rank],1)=1,INDEX(OfficeGroups[Source deobligations],MATCH(1,OfficeGroups[Source rank],0)),"")) | F25: =IF(Trends!$B$6<>"","",IF(COUNTIFS(OfficeGroups[Source rank],1)=1,INDEX(OfficeGroups[Source awards],MATCH(1,OfficeGroups[Source rank],0)),"")) | G25: =IF(Trends!$B$6<>"","",IF(COUNTIFS(OfficeGroups[Source rank],1)=1,INDEX(OfficeGroups[Source actions],MATCH(1,OfficeGroups[Source rank],0)),"")) | L25: =IF(H25="","",I25&IF(J25="",""," ["&J25&"]")) | M25: =IF(H25="","",SUMIFS(TransactionsData[Obligations],TransactionsData[Funding office ID],H25,TransactionsData[Selected],1)) | N25: =IF(H25="","",SUMIFS(TransactionsData[Deobligations],TransactionsData[Funding office ID],H25,TransactionsData[Selected],1)) | O25: =IF(H25="","",SUMIFS(TransactionsData[First office award],TransactionsData[Funding office ID],H25)) | P25: =IF(H25="","",COUNTIFS(TransactionsData[Funding office ID],H25,TransactionsData[Selected],1)) | Q25: =IF(OR(H25="",P25=0),"",COUNTIFS(OfficeGroups[Source net],">"&M25,OfficeGroups[Source actions],">0")+COUNTIFS(OfficeGroups[Source net],M25,OfficeGroups[Record ID],"<"&H25,OfficeGroups[Source actions],">0")+1) | R25: =IF(H25="",IF(COUNTA(I25:K25)>0,"Missing record ID",""),IF(COUNTIFS(OfficeGroups[Record ID],H25)<>1,"Duplicate record ID",IF(I25="","Add name","")))
A26: =IF(Trends!$B$6<>"","",IF(COUNTIFS(OfficeGroups[Source rank],2)=1,2,"")) | B26: =IF(Trends!$B$6<>"","",IF(COUNTIFS(OfficeGroups[Source rank],2)=1,IF(INDEX(OfficeGroups[Source URL],MATCH(2,OfficeGroups[Source rank],0))="",INDEX(OfficeGroups[Source name],MATCH(2,OfficeGroups[Source rank],0)),HYPERLINK(INDEX(OfficeGroups[Source URL],MATCH(2,OfficeGroups[Source rank],0)),INDEX(OfficeGroups[Source name],MATCH(2,OfficeGroups[Source rank],0)))),"")) | C26: =IF(Trends!$B$6<>"","",IF(COUNTIFS(OfficeGroups[Source rank],2)=1,IF(INDEX(OfficeGroups[Source UEI],MATCH(2,OfficeGroups[Source rank],0))="","Not supplied",INDEX(OfficeGroups[Source UEI],MATCH(2,OfficeGroups[Source rank],0))),"")) | D26: =IF(Trends!$B$6<>"","",IF(COUNTIFS(OfficeGroups[Source rank],2)=1,INDEX(OfficeGroups[Source net],MATCH(2,OfficeGroups[Source rank],0)),"")) | E26: =IF(Trends!$B$6<>"","",IF(COUNTIFS(OfficeGroups[Source rank],2)=1,INDEX(OfficeGroups[Source deobligations],MATCH(2,OfficeGroups[Source rank],0)),"")) | F26: =IF(Trends!$B$6<>"","",IF(COUNTIFS(OfficeGroups[Source rank],2)=1,INDEX(OfficeGroups[Source awards],MATCH(2,OfficeGroups[Source rank],0)),"")) | G26: =IF(Trends!$B$6<>"","",IF(COUNTIFS(OfficeGroups[Source rank],2)=1,INDEX(OfficeGroups[Source actions],MATCH(2,OfficeGroups[Source rank],0)),"")) | L26: =IF(H26="","",I26&IF(J26="",""," ["&J26&"]")) | M26: =IF(H26="","",SUMIFS(TransactionsData[Obligations],TransactionsData[Funding office ID],H26,TransactionsData[Selected],1)) | N26: =IF(H26="","",SUMIFS(TransactionsData[Deobligations],TransactionsData[Funding office ID],H26,TransactionsData[Selected],1)) | O26: =IF(H26="","",SUMIFS(TransactionsData[First office award],TransactionsData[Funding office ID],H26)) | P26: =IF(H26="","",COUNTIFS(TransactionsData[Funding office ID],H26,TransactionsData[Selected],1)) | Q26: =IF(OR(H26="",P26=0),"",COUNTIFS(OfficeGroups[Source net],">"&M26,OfficeGroups[Source actions],">0")+COUNTIFS(OfficeGroups[Source net],M26,OfficeGroups[Record ID],"<"&H26,OfficeGroups[Source actions],">0")+1) | R26: =IF(H26="",IF(COUNTA(I26:K26)>0,"Missing record ID",""),IF(COUNTIFS(OfficeGroups[Record ID],H26)<>1,"Duplicate record ID",IF(I26="","Add name","")))
A27: =IF(Trends!$B$6<>"","",IF(COUNTIFS(OfficeGroups[Source rank],3)=1,3,"")) | B27: =IF(Trends!$B$6<>"","",IF(COUNTIFS(OfficeGroups[Source rank],3)=1,IF(INDEX(OfficeGroups[Source URL],MATCH(3,OfficeGroups[Source rank],0))="",INDEX(OfficeGroups[Source name],MATCH(3,OfficeGroups[Source rank],0)),HYPERLINK(INDEX(OfficeGroups[Source URL],MATCH(3,OfficeGroups[Source rank],0)),INDEX(OfficeGroups[Source name],MATCH(3,OfficeGroups[Source rank],0)))),"")) | C27: =IF(Trends!$B$6<>"","",IF(COUNTIFS(OfficeGroups[Source rank],3)=1,IF(INDEX(OfficeGroups[Source UEI],MATCH(3,OfficeGroups[Source rank],0))="","Not supplied",INDEX(OfficeGroups[Source UEI],MATCH(3,OfficeGroups[Source rank],0))),"")) | D27: =IF(Trends!$B$6<>"","",IF(COUNTIFS(OfficeGroups[Source rank],3)=1,INDEX(OfficeGroups[Source net],MATCH(3,OfficeGroups[Source rank],0)),"")) | E27: =IF(Trends!$B$6<>"","",IF(COUNTIFS(OfficeGroups[Source rank],3)=1,INDEX(OfficeGroups[Source deobligations],MATCH(3,OfficeGroups[Source rank],0)),"")) | F27: =IF(Trends!$B$6<>"","",IF(COUNTIFS(OfficeGroups[Source rank],3)=1,INDEX(OfficeGroups[Source awards],MATCH(3,OfficeGroups[Source rank],0)),"")) | G27: =IF(Trends!$B$6<>"","",IF(COUNTIFS(OfficeGroups[Source rank],3)=1,INDEX(OfficeGroups[Source actions],MATCH(3,OfficeGroups[Source rank],0)),"")) | L27: =IF(H27="","",I27&IF(J27="",""," ["&J27&"]")) | M27: =IF(H27="","",SUMIFS(TransactionsData[Obligations],TransactionsData[Funding office ID],H27,TransactionsData[Selected],1)) | N27: =IF(H27="","",SUMIFS(TransactionsData[Deobligations],TransactionsData[Funding office ID],H27,TransactionsData[Selected],1)) | O27: =IF(H27="","",SUMIFS(TransactionsData[First office award],TransactionsData[Funding office ID],H27)) | P27: =IF(H27="","",COUNTIFS(TransactionsData[Funding office ID],H27,TransactionsData[Selected],1)) | Q27: =IF(OR(H27="",P27=0),"",COUNTIFS(OfficeGroups[Source net],">"&M27,OfficeGroups[Source actions],">0")+COUNTIFS(OfficeGroups[Source net],M27,OfficeGroups[Record ID],"<"&H27,OfficeGroups[Source actions],">0")+1) | R27: =IF(H27="",IF(COUNTA(I27:K27)>0,"Missing record ID",""),IF(COUNTIFS(OfficeGroups[Record ID],H27)<>1,"Duplicate record ID",IF(I27="","Add name","")))
A28: =IF(Trends!$B$6<>"","",IF(COUNTIFS(OfficeGroups[Source rank],4)=1,4,"")) | B28: =IF(Trends!$B$6<>"","",IF(COUNTIFS(OfficeGroups[Source rank],4)=1,IF(INDEX(OfficeGroups[Source URL],MATCH(4,OfficeGroups[Source rank],0))="",INDEX(OfficeGroups[Source name],MATCH(4,OfficeGroups[Source rank],0)),HYPERLINK(INDEX(OfficeGroups[Source URL],MATCH(4,OfficeGroups[Source rank],0)),INDEX(OfficeGroups[Source name],MATCH(4,OfficeGroups[Source rank],0)))),"")) | C28: =IF(Trends!$B$6<>"","",IF(COUNTIFS(OfficeGroups[Source rank],4)=1,IF(INDEX(OfficeGroups[Source UEI],MATCH(4,OfficeGroups[Source rank],0))="","Not supplied",INDEX(OfficeGroups[Source UEI],MATCH(4,OfficeGroups[Source rank],0))),"")) | D28: =IF(Trends!$B$6<>"","",IF(COUNTIFS(OfficeGroups[Source rank],4)=1,INDEX(OfficeGroups[Source net],MATCH(4,OfficeGroups[Source rank],0)),"")) | E28: =IF(Trends!$B$6<>"","",IF(COUNTIFS(OfficeGroups[Source rank],4)=1,INDEX(OfficeGroups[Source deobligations],MATCH(4,OfficeGroups[Source rank],0)),"")) | F28: =IF(Trends!$B$6<>"","",IF(COUNTIFS(OfficeGroups[Source rank],4)=1,INDEX(OfficeGroups[Source awards],MATCH(4,OfficeGroups[Source rank],0)),"")) | G28: =IF(Trends!$B$6<>"","",IF(COUNTIFS(OfficeGroups[Source rank],4)=1,INDEX(OfficeGroups[Source actions],MATCH(4,OfficeGroups[Source rank],0)),"")) | L28: =IF(H28="","",I28&IF(J28="",""," ["&J28&"]")) | M28: =IF(H28="","",SUMIFS(TransactionsData[Obligations],TransactionsData[Funding office ID],H28,TransactionsData[Selected],1)) | N28: =IF(H28="","",SUMIFS(TransactionsData[Deobligations],TransactionsData[Funding office ID],H28,TransactionsData[Selected],1)) | O28: =IF(H28="","",SUMIFS(TransactionsData[First office award],TransactionsData[Funding office ID],H28)) | P28: =IF(H28="","",COUNTIFS(TransactionsData[Funding office ID],H28,TransactionsData[Selected],1)) | Q28: =IF(OR(H28="",P28=0),"",COUNTIFS(OfficeGroups[Source net],">"&M28,OfficeGroups[Source actions],">0")+COUNTIFS(OfficeGroups[Source net],M28,OfficeGroups[Record ID],"<"&H28,OfficeGroups[Source actions],">0")+1) | R28: =IF(H28="",IF(COUNTA(I28:K28)>0,"Missing record ID",""),IF(COUNTIFS(OfficeGroups[Record ID],H28)<>1,"Duplicate record ID",IF(I28="","Add name","")))
A29: =IF(Trends!$B$6<>"","",IF(COUNTIFS(OfficeGroups[Source rank],5)=1,5,"")) | B29: =IF(Trends!$B$6<>"","",IF(COUNTIFS(OfficeGroups[Source rank],5)=1,IF(INDEX(OfficeGroups[Source URL],MATCH(5,OfficeGroups[Source rank],0))="",INDEX(OfficeGroups[Source name],MATCH(5,OfficeGroups[Source rank],0)),HYPERLINK(INDEX(OfficeGroups[Source URL],MATCH(5,OfficeGroups[Source rank],0)),INDEX(OfficeGroups[Source name],MATCH(5,OfficeGroups[Source rank],0)))),"")) | C29: =IF(Trends!$B$6<>"","",IF(COUNTIFS(OfficeGroups[Source rank],5)=1,IF(INDEX(OfficeGroups[Source UEI],MATCH(5,OfficeGroups[Source rank],0))="","Not supplied",INDEX(OfficeGroups[Source UEI],MATCH(5,OfficeGroups[Source rank],0))),"")) | D29: =IF(Trends!$B$6<>"","",IF(COUNTIFS(OfficeGroups[Source rank],5)=1,INDEX(OfficeGroups[Source net],MATCH(5,OfficeGroups[Source rank],0)),"")) | E29: =IF(Trends!$B$6<>"","",IF(COUNTIFS(OfficeGroups[Source rank],5)=1,INDEX(OfficeGroups[Source deobligations],MATCH(5,OfficeGroups[Source rank],0)),"")) | F29: =IF(Trends!$B$6<>"","",IF(COUNTIFS(OfficeGroups[Source rank],5)=1,INDEX(OfficeGroups[Source awards],MATCH(5,OfficeGroups[Source rank],0)),"")) | G29: =IF(Trends!$B$6<>"","",IF(COUNTIFS(OfficeGroups[Source rank],5)=1,INDEX(OfficeGroups[Source actions],MATCH(5,OfficeGroups[Source rank],0)),"")) | L29: =IF(H29="","",I29&IF(J29="",""," ["&J29&"]")) | M29: =IF(H29="","",SUMIFS(TransactionsData[Obligations],TransactionsData[Funding office ID],H29,TransactionsData[Selected],1)) | N29: =IF(H29="","",SUMIFS(TransactionsData[Deobligations],TransactionsData[Funding office ID],H29,TransactionsData[Selected],1)) | O29: =IF(H29="","",SUMIFS(TransactionsData[First office award],TransactionsData[Funding office ID],H29)) | P29: =IF(H29="","",COUNTIFS(TransactionsData[Funding office ID],H29,TransactionsData[Selected],1)) | Q29: =IF(OR(H29="",P29=0),"",COUNTIFS(OfficeGroups[Source net],">"&M29,OfficeGroups[Source actions],">0")+COUNTIFS(OfficeGroups[Source net],M29,OfficeGroups[Record ID],"<"&H29,OfficeGroups[Source actions],">0")+1) | R29: =IF(H29="",IF(COUNTA(I29:K29)>0,"Missing record ID",""),IF(COUNTIFS(OfficeGroups[Record ID],H29)<>1,"Duplicate record ID",IF(I29="","Add name","")))
A30: =IF(Trends!$B$6<>"","",IF(COUNTIFS(OfficeGroups[Source rank],6)=1,6,"")) | B30: =IF(Trends!$B$6<>"","",IF(COUNTIFS(OfficeGroups[Source rank],6)=1,IF(INDEX(OfficeGroups[Source URL],MATCH(6,OfficeGroups[Source rank],0))="",INDEX(OfficeGroups[Source name],MATCH(6,OfficeGroups[Source rank],0)),HYPERLINK(INDEX(OfficeGroups[Source URL],MATCH(6,OfficeGroups[Source rank],0)),INDEX(OfficeGroups[Source name],MATCH(6,OfficeGroups[Source rank],0)))),"")) | C30: =IF(Trends!$B$6<>"","",IF(COUNTIFS(OfficeGroups[Source rank],6)=1,IF(INDEX(OfficeGroups[Source UEI],MATCH(6,OfficeGroups[Source rank],0))="","Not supplied",INDEX(OfficeGroups[Source UEI],MATCH(6,OfficeGroups[Source rank],0))),"")) | D30: =IF(Trends!$B$6<>"","",IF(COUNTIFS(OfficeGroups[Source rank],6)=1,INDEX(OfficeGroups[Source net],MATCH(6,OfficeGroups[Source rank],0)),"")) | E30: =IF(Trends!$B$6<>"","",IF(COUNTIFS(OfficeGroups[Source rank],6)=1,INDEX(OfficeGroups[Source deobligations],MATCH(6,OfficeGroups[Source rank],0)),"")) | F30: =IF(Trends!$B$6<>"","",IF(COUNTIFS(OfficeGroups[Source rank],6)=1,INDEX(OfficeGroups[Source awards],MATCH(6,OfficeGroups[Source rank],0)),"")) | G30: =IF(Trends!$B$6<>"","",IF(COUNTIFS(OfficeGroups[Source rank],6)=1,INDEX(OfficeGroups[Source actions],MATCH(6,OfficeGroups[Source rank],0)),"")) | L30: =IF(H30="","",I30&IF(J30="",""," ["&J30&"]")) | M30: =IF(H30="","",SUMIFS(TransactionsData[Obligations],TransactionsData[Funding office ID],H30,TransactionsData[Selected],1)) | N30: =IF(H30="","",SUMIFS(TransactionsData[Deobligations],TransactionsData[Funding office ID],H30,TransactionsData[Selected],1)) | O30: =IF(H30="","",SUMIFS(TransactionsData[First office award],TransactionsData[Funding office ID],H30)) | P30: =IF(H30="","",COUNTIFS(TransactionsData[Funding office ID],H30,TransactionsData[Selected],1)) | Q30: =IF(OR(H30="",P30=0),"",COUNTIFS(OfficeGroups[Source net],">"&M30,OfficeGroups[Source actions],">0")+COUNTIFS(OfficeGroups[Source net],M30,OfficeGroups[Record ID],"<"&H30,OfficeGroups[Source actions],">0")+1) | R30: =IF(H30="",IF(COUNTA(I30:K30)>0,"Missing record ID",""),IF(COUNTIFS(OfficeGroups[Record ID],H30)<>1,"Duplicate record ID",IF(I30="","Add name","")))
A31: =IF(Trends!$B$6<>"","",IF(COUNTIFS(OfficeGroups[Source rank],7)=1,7,"")) | B31: =IF(Trends!$B$6<>"","",IF(COUNTIFS(OfficeGroups[Source rank],7)=1,IF(INDEX(OfficeGroups[Source URL],MATCH(7,OfficeGroups[Source rank],0))="",INDEX(OfficeGroups[Source name],MATCH(7,OfficeGroups[Source rank],0)),HYPERLINK(INDEX(OfficeGroups[Source URL],MATCH(7,OfficeGroups[Source rank],0)),INDEX(OfficeGroups[Source name],MATCH(7,OfficeGroups[Source rank],0)))),"")) | C31: =IF(Trends!$B$6<>"","",IF(COUNTIFS(OfficeGroups[Source rank],7)=1,IF(INDEX(OfficeGroups[Source UEI],MATCH(7,OfficeGroups[Source rank],0))="","Not supplied",INDEX(OfficeGroups[Source UEI],MATCH(7,OfficeGroups[Source rank],0))),"")) | D31: =IF(Trends!$B$6<>"","",IF(COUNTIFS(OfficeGroups[Source rank],7)=1,INDEX(OfficeGroups[Source net],MATCH(7,OfficeGroups[Source rank],0)),"")) | E31: =IF(Trends!$B$6<>"","",IF(COUNTIFS(OfficeGroups[Source rank],7)=1,INDEX(OfficeGroups[Source deobligations],MATCH(7,OfficeGroups[Source rank],0)),"")) | F31: =IF(Trends!$B$6<>"","",IF(COUNTIFS(OfficeGroups[Source rank],7)=1,INDEX(OfficeGroups[Source awards],MATCH(7,OfficeGroups[Source rank],0)),"")) | G31: =IF(Trends!$B$6<>"","",IF(COUNTIFS(OfficeGroups[Source rank],7)=1,INDEX(OfficeGroups[Source actions],MATCH(7,OfficeGroups[Source rank],0)),"")) | L31: =IF(H31="","",I31&IF(J31="",""," ["&J31&"]")) | M31: =IF(H31="","",SUMIFS(TransactionsData[Obligations],TransactionsData[Funding office ID],H31,TransactionsData[Selected],1)) | N31: =IF(H31="","",SUMIFS(TransactionsData[Deobligations],TransactionsData[Funding office ID],H31,TransactionsData[Selected],1)) | O31: =IF(H31="","",SUMIFS(TransactionsData[First office award],TransactionsData[Funding office ID],H31)) | P31: =IF(H31="","",COUNTIFS(TransactionsData[Funding office ID],H31,TransactionsData[Selected],1)) | Q31: =IF(OR(H31="",P31=0),"",COUNTIFS(OfficeGroups[Source net],">"&M31,OfficeGroups[Source actions],">0")+COUNTIFS(OfficeGroups[Source net],M31,OfficeGroups[Record ID],"<"&H31,OfficeGroups[Source actions],">0")+1) | R31: =IF(H31="",IF(COUNTA(I31:K31)>0,"Missing record ID",""),IF(COUNTIFS(OfficeGroups[Record ID],H31)<>1,"Duplicate record ID",IF(I31="","Add name","")))
A32: =IF(Trends!$B$6<>"","",IF(COUNTIFS(OfficeGroups[Source rank],8)=1,8,"")) | B32: =IF(Trends!$B$6<>"","",IF(COUNTIFS(OfficeGroups[Source rank],8)=1,IF(INDEX(OfficeGroups[Source URL],MATCH(8,OfficeGroups[Source rank],0))="",INDEX(OfficeGroups[Source name],MATCH(8,OfficeGroups[Source rank],0)),HYPERLINK(INDEX(OfficeGroups[Source URL],MATCH(8,OfficeGroups[Source rank],0)),INDEX(OfficeGroups[Source name],MATCH(8,OfficeGroups[Source rank],0)))),"")) | C32: =IF(Trends!$B$6<>"","",IF(COUNTIFS(OfficeGroups[Source rank],8)=1,IF(INDEX(OfficeGroups[Source UEI],MATCH(8,OfficeGroups[Source rank],0))="","Not supplied",INDEX(OfficeGroups[Source UEI],MATCH(8,OfficeGroups[Source rank],0))),"")) | D32: =IF(Trends!$B$6<>"","",IF(COUNTIFS(OfficeGroups[Source rank],8)=1,INDEX(OfficeGroups[Source net],MATCH(8,OfficeGroups[Source rank],0)),"")) | E32: =IF(Trends!$B$6<>"","",IF(COUNTIFS(OfficeGroups[Source rank],8)=1,INDEX(OfficeGroups[Source deobligations],MATCH(8,OfficeGroups[Source rank],0)),"")) | F32: =IF(Trends!$B$6<>"","",IF(COUNTIFS(OfficeGroups[Source rank],8)=1,INDEX(OfficeGroups[Source awards],MATCH(8,OfficeGroups[Source rank],0)),"")) | G32: =IF(Trends!$B$6<>"","",IF(COUNTIFS(OfficeGroups[Source rank],8)=1,INDEX(OfficeGroups[Source actions],MATCH(8,OfficeGroups[Source rank],0)),"")) | L32: =IF(H32="","",I32&IF(J32="",""," ["&J32&"]")) | M32: =IF(H32="","",SUMIFS(TransactionsData[Obligations],TransactionsData[Funding office ID],H32,TransactionsData[Selected],1)) | N32: =IF(H32="","",SUMIFS(TransactionsData[Deobligations],TransactionsData[Funding office ID],H32,TransactionsData[Selected],1)) | O32: =IF(H32="","",SUMIFS(TransactionsData[First office award],TransactionsData[Funding office ID],H32)) | P32: =IF(H32="","",COUNTIFS(TransactionsData[Funding office ID],H32,TransactionsData[Selected],1)) | Q32: =IF(OR(H32="",P32=0),"",COUNTIFS(OfficeGroups[Source net],">"&M32,OfficeGroups[Source actions],">0")+COUNTIFS(OfficeGroups[Source net],M32,OfficeGroups[Record ID],"<"&H32,OfficeGroups[Source actions],">0")+1) | R32: =IF(H32="",IF(COUNTA(I32:K32)>0,"Missing record ID",""),IF(COUNTIFS(OfficeGroups[Record ID],H32)<>1,"Duplicate record ID",IF(I32="","Add name","")))
