Workbook
Name AwardTypeCategories: 'Dashboard'!$AD$42:$AD$45
Name SetAsideCategories: 'Dashboard'!$AG$42:$AG$45
Name PerformanceStateCategories: 'Dashboard'!$AJ$42:$AJ$47
Name VendorChoices: 'Dashboard'!$AM$1:$AM$21
Name OfficeChoices: 'Dashboard'!$AN$1:$AN$13
Name TypeChoices: 'Dashboard'!$AO$1:$AO$5

Sheet Dashboard
AM1: All | AN1: All | AO1: All
B2: Contract awards & spend | AA2: Vendor ID | AB2: =IF(H7="All","All",IF(COUNTIFS(VendorGroups[Filter label],H7)=1,INDEX(VendorGroups[Record ID],MATCH(H7,VendorGroups[Filter label],0)),"Invalid")) -> All | AM2: Agility Technologies Inc. [Z9M6NN4AQLF7] | AN2: Directorate for Engineering [490700-A] | AO2: BPA Call
B3: =IF(Transactions!B3="","Buyer / market",Transactions!B3) -> National Science Foundation | Q3: =IF(Transactions!G4="","Retrieved: not supplied","Retrieved "&TEXT(Transactions!G4,"mmm d, yyyy")) -> Retrieved Sep 14, 2026 | AA3: Office ID | AB3: =IF(B10="All","All",IF(COUNTIFS(OfficeGroups[Filter label],B10)=1,INDEX(OfficeGroups[Record ID],MATCH(B10,OfficeGroups[Filter label],0)),"Invalid")) -> All | AM3: Anika Systems Incorporated [Y9V7J5VN9F68] | AN3: Directorate of Geosciences [490600-A] | AO3: Definitive Contract
B4: =IF(Transactions!G3="","Add reviewed records and reporting dates to populate this workbook.",Transactions!G3) -> Application support (PSC DA01) | AM4: Booz Allen Hamilton Inc. [JCBMLGPE6Z71] | AN4: Division of Acquisition and Cooperative Support [491004-A] | AO4: Delivery Order
B5: Prepared by GovTribe, Inc. · UEI EDJBUPNLCCL5 | AM5: Civicactions, Inc. [XSZFHRS5QFL5] | AN5: Division of Industrial Innovation [490707-A] | AO5: Purchase Order
B6: Fiscal year | H6: Vendor | AA6: Net obligations | AB6: =IF(Trends!$B$6<>"","",SUMIFS(TransactionsData[Obligations],TransactionsData[Selected],1)) -> 1.2031667e+08 | AM6: Criterion Systems, L.L.C. [MPGNDNHHWM33] | AN6: Division of Information Systems [490209-A]
B7: 2025 | H7: All | AA7: Awards with obligations | AB7: =IF(Trends!$B$6<>"","",SUM(TransactionsData[First selected award])) -> 34 | AM7: Directviz Solutions, LLC [YXH4AGD2LGF5] | AN7: Division of Social and Economic Science [490405-A]
AA8: Vendors with obligations | AB8: =IF(Trends!$B$6<>"","",SUM(TransactionsData[First selected vendor])) -> 18 | AM8: Expediteinfotech, Inc. [KX6EDEAPTKH5] | AN8: National Center for Science and Engineering Statistics [490403-A]
B9: Funding office | N9: Current award type | AA9: Transactions | AB9: =IF(Trends!$B$6<>"","",SUM(TransactionsData[Selected])) -> 106 | AM9: Gartner, Inc. [CFALLJBGZ697] | AN9: National Science Board [490001-A]
B10: All | N10: All | AM10: GBS Dakota IT, LLC [G9E9BR9MG9N7] | AN10: NSF — office not specified [4900-A]
AB11: =IF(OR(Dashboard!$B$7="All",NOT(ISNUMBER(Dashboard!$B$7))),0,IF(AND(COUNTIFS(Trends!$I$26:$I$28,Dashboard!$B$7)=1,COUNTIFS(Trends!$I$26:$I$28,Dashboard!$B$7-1)=1),IF(AND(INDEX(Trends!$J$26:$J$28,MATCH(Dashboard!$B$7,Trends!$I$26:$I$28,0))=1,INDEX(Trends!$J$26:$J$28,MATCH(Dashboard!$B$7-1,Trends!$I$26:$I$28,0))=1),1,0),0)) -> 1 | AM11: GBS Solutions Corp [NKNSTJBPABX9] | AN11: Office of Budget Finance and Award Management [491000-A]
B12: =Trends!$B$6 | AM12: Ibex It Business Experts LLC [XPA8X2BWTD49] | AN12: Office of Information Resource Management [490200-A]
AB13: =IF(AB11=1,INDEX(Trends!$D$26:$D$28,MATCH(Dashboard!$B$7-1,Trends!$I$26:$I$28,0)),"") -> 97611271 | AM13: Lynker Corporation [MCLPKDBCDKY7] | AN13: Office of the Inspector General [490002-A]
B14: Net obligations | H14: Awards with obligations | N14: Vendors with obligations | T14: Transactions | AB14: =IF(AB11=1,INDEX(Trends!$E$26:$E$28,MATCH(Dashboard!$B$7-1,Trends!$I$26:$I$28,0)),"") -> 34 | AM14: Montage + Magnum, LLC [XLJSS2NNHU27]
B15: =IF(Trends!$B$6<>"","—",TEXT(AB6/1000000,"$0.00")&"M") -> $120.32M | H15: =IF(Trends!$B$6<>"","—",AB7) -> 34 | N15: =IF(Trends!$B$6<>"","—",AB8) -> 18 | T15: =IF(Trends!$B$6<>"","—",AB9) -> 106 | AB15: =IF(AB11=1,INDEX(Trends!$F$26:$F$28,MATCH(Dashboard!$B$7-1,Trends!$I$26:$I$28,0)),"") -> 18 | AM15: Professional Management Consulting Services LLC [CD2QDS1EFHP3]
AB16: =IF(AB11=1,INDEX(Trends!$G$26:$G$28,MATCH(Dashboard!$B$7-1,Trends!$I$26:$I$28,0)),"") -> 74 | AM16: Rei Systems, Inc. [YRNMVN96JC17]
B17: =IF(OR(Trends!$B$6<>"",AB11<>1),"",IF(AB13>0,TEXT((AB6-AB13)/AB13,"+0.0%;-0.0%;+0.0%")&" vs FY"&(Dashboard!$B$7-1),"")) -> +23.3% vs FY2024 | H17: =IF(OR(Trends!$B$6<>"",AB11<>1),"",IF(AB7=AB14,"No change vs FY"&(Dashboard!$B$7-1),TEXT(AB7-AB14,"+#,##0;-#,##0;0")&" vs FY"&(Dashboard!$B$7-1))) -> No change vs FY2024 | N17: =IF(OR(Trends!$B$6<>"",AB11<>1),"",IF(AB8=AB15,"No change vs FY"&(Dashboard!$B$7-1),TEXT(AB8-AB15,"+#,##0;-#,##0;0")&" vs FY"&(Dashboard!$B$7-1))) -> No change vs FY2024 | T17: =IF(OR(Trends!$B$6<>"",AB11<>1),"",IF(AB9=AB16,"No change vs FY"&(Dashboard!$B$7-1),TEXT(AB9-AB16,"+#,##0;-#,##0;0")&" vs FY"&(Dashboard!$B$7-1))) -> +32 vs FY2024 | AM17: Scope It Consulting, LLC [KN99UT9W5N77]
AM18: Spatial Front Inc. [J1ADW6BL8MN5]
B19: =IF(Dashboard!$B$7="All","All covered years",IF(Dashboard!$B$7="","No reporting period","FY"&Dashboard!$B$7)) -> FY2025 | H19: =IF(Dashboard!$B$7="All","All covered years",IF(Dashboard!$B$7="","No reporting period","FY"&Dashboard!$B$7)) -> FY2025 | N19: =IF(Dashboard!$B$7="All","All covered years",IF(Dashboard!$B$7="","No reporting period","FY"&Dashboard!$B$7)) -> FY2025 | T19: =IF(Dashboard!$B$7="All","All covered years",IF(Dashboard!$B$7="","No reporting period","FY"&Dashboard!$B$7)) -> FY2025 | AM19: Strategic Communications LLC [LJZRP7SE5LN4]
B20: Charts in USD millions | AM20: Thundercat Technology, LLC [UER4AJLUB8D5]
B21: Annual net obligations | N21: Leading vendors | AA21: Category | AB21: Net obligations | AD21: Category | AE21: Net obligations | AM21: University Corporation For Advanced Internet Development [DZEBKFRD1ZN6]
AA22: =IF(Trends!A26="","",Trends!A26) -> FY2023 | AB22: =IF((IF(Trends!$B$6<>"","",Trends!D26))="","",(IF(Trends!$B$6<>"","",Trends!D26))/1000000) -> 24.025004 | AD22: =IF(Trends!$B$6<>"","",IF(COUNTIFS(VendorGroups[Source actions],">0")>5,"Other vendors","")) -> Other vendors | AE22: =IF((IF(Trends!$B$6<>"","",IF(AD22="","",SUMIFS(VendorGroups[Source net],VendorGroups[Source rank],">5"))))="","",(IF(Trends!$B$6<>"","",IF(AD22="","",SUMIFS(VendorGroups[Source net],VendorGroups[Source rank],">5"))))/1000000) -> 17.767082
AA23: =IF(Trends!A27="","",Trends!A27) -> FY2024 | AB23: =IF((IF(Trends!$B$6<>"","",Trends!D27))="","",(IF(Trends!$B$6<>"","",Trends!D27))/1000000) -> 97.611271 | AD23: =IF('Vendors & Buyers'!B12="","",'Vendors & Buyers'!B12) -> Strategic Communications LLC | AE23: =IF((IF(AD23="","",'Vendors & Buyers'!D12))="","",(IF(AD23="","",'Vendors & Buyers'!D12))/1000000) -> 7.2373027
AA24: =IF(Trends!A28="","",Trends!A28) -> FY2025 | AB24: =IF((IF(Trends!$B$6<>"","",Trends!D28))="","",(IF(Trends!$B$6<>"","",Trends!D28))/1000000) -> 120.31667 | AD24: =IF('Vendors & Buyers'!B11="","",'Vendors & Buyers'!B11) -> Spatial Front Inc. | AE24: =IF((IF(AD24="","",'Vendors & Buyers'!D11))="","",(IF(AD24="","",'Vendors & Buyers'!D11))/1000000) -> 8.845386
AD25: =IF('Vendors & Buyers'!B10="","",'Vendors & Buyers'!B10) -> Civicactions, Inc. | AE25: =IF((IF(AD25="","",'Vendors & Buyers'!D10))="","",(IF(AD25="","",'Vendors & Buyers'!D10))/1000000) -> 10.76911
AD26: =IF('Vendors & Buyers'!B9="","",'Vendors & Buyers'!B9) -> Directviz Solutions, LLC | AE26: =IF((IF(AD26="","",'Vendors & Buyers'!D9))="","",(IF(AD26="","",'Vendors & Buyers'!D9))/1000000) -> 22.532734
AD27: =IF('Vendors & Buyers'!B8="","",'Vendors & Buyers'!B8) -> Booz Allen Hamilton Inc. | AE27: =IF((IF(AD27="","",'Vendors & Buyers'!D8))="","",(IF(AD27="","",'Vendors & Buyers'!D8))/1000000) -> 53.165051
B36: Annual and quarterly history use all covered years. Rankings and breakdowns use the selected fiscal year.
B38: Contract awards & spend — breakdowns
B39: ="USD millions | Period: "&IF(B7="All","All covered years",IF(B7="","Not supplied","FY"&B7))&" | Award type: "&N10&CHAR(10)&"Vendor: "&H7&" | Funding office: "&B10 -> USD millions | Period: FY2025 | Award type: All Vendor: All | Funding office: All | AB39: =MAX(1,COUNTIFS(Trends!$K$34:$K$45,">0")) -> 4
B40: Quarterly history · all covered years | N40: Current award types
AA41: Category | AB41: Net obligations | AD41: Category | AE41: Net obligations | AG41: Category | AH41: Net obligations | AJ41: Category | AK41: Net obligations
AA42: =IF(Trends!A34="","",Trends!A34) -> FY2023 Q1 | AB42: =IF((IF(OR(Trends!$B$6<>"",AA42=""),"",Trends!D34))="","",(IF(OR(Trends!$B$6<>"",AA42=""),"",Trends!D34))/1000000) -> 6.1156203 | AD42: Purchase Order | AE42: =IF((IF(AD42="","",IF(Trends!$B$6<>"","",SUMIFS(TransactionsData[Obligations],TransactionsData[Current award type],AD42,TransactionsData[Selected],1))))="","",(IF(AD42="","",IF(Trends!$B$6<>"","",SUMIFS(TransactionsData[Obligations],TransactionsData[Current award type],AD42,TransactionsData[Selected],1))))/1000000) -> 0.039079 | AG42: Total Small Business | AH42: =IF((IF(AG42="","",IF(Trends!$B$6<>"","",SUMIFS(TransactionsData[Obligations],TransactionsData[Current set-aside],AG42,TransactionsData[Selected],1))))="","",(IF(AG42="","",IF(Trends!$B$6<>"","",SUMIFS(TransactionsData[Obligations],TransactionsData[Current set-aside],AG42,TransactionsData[Selected],1))))/1000000) -> 42.644429 | AJ42: Virginia | AK42: =IF((IF(AJ42="","",IF(Trends!$B$6<>"","",SUMIFS(TransactionsData[Obligations],TransactionsData[Performance state],AJ42,TransactionsData[Selected],1))))="","",(IF(AJ42="","",IF(Trends!$B$6<>"","",SUMIFS(TransactionsData[Obligations],TransactionsData[Performance state],AJ42,TransactionsData[Selected],1))))/1000000) -> 103.48523
AA43: =IF(Trends!A35="","",Trends!A35) -> FY2023 Q2 | AB43: =IF((IF(OR(Trends!$B$6<>"",AA43=""),"",Trends!D35))="","",(IF(OR(Trends!$B$6<>"",AA43=""),"",Trends!D35))/1000000) -> 9.2182711 | AD43: Delivery Order | AE43: =IF((IF(AD43="","",IF(Trends!$B$6<>"","",SUMIFS(TransactionsData[Obligations],TransactionsData[Current award type],AD43,TransactionsData[Selected],1))))="","",(IF(AD43="","",IF(Trends!$B$6<>"","",SUMIFS(TransactionsData[Obligations],TransactionsData[Current award type],AD43,TransactionsData[Selected],1))))/1000000) -> 80.714699 | AG43: No Set-Aside Used | AH43: =IF((IF(AG43="","",IF(Trends!$B$6<>"","",SUMIFS(TransactionsData[Obligations],TransactionsData[Current set-aside],AG43,TransactionsData[Selected],1))))="","",(IF(AG43="","",IF(Trends!$B$6<>"","",SUMIFS(TransactionsData[Obligations],TransactionsData[Current set-aside],AG43,TransactionsData[Selected],1))))/1000000) -> 70.815302 | AJ43: Utah | AK43: =IF((IF(AJ43="","",IF(Trends!$B$6<>"","",SUMIFS(TransactionsData[Obligations],TransactionsData[Performance state],AJ43,TransactionsData[Selected],1))))="","",(IF(AJ43="","",IF(Trends!$B$6<>"","",SUMIFS(TransactionsData[Obligations],TransactionsData[Performance state],AJ43,TransactionsData[Selected],1))))/1000000) -> 0.06175948
AA44: =IF(Trends!A36="","",Trends!A36) -> FY2023 Q3 | AB44: =IF((IF(OR(Trends!$B$6<>"",AA44=""),"",Trends!D36))="","",(IF(OR(Trends!$B$6<>"",AA44=""),"",Trends!D36))/1000000) -> 3.4499029 | AD44: Definitive Contract | AE44: =IF((IF(AD44="","",IF(Trends!$B$6<>"","",SUMIFS(TransactionsData[Obligations],TransactionsData[Current award type],AD44,TransactionsData[Selected],1))))="","",(IF(AD44="","",IF(Trends!$B$6<>"","",SUMIFS(TransactionsData[Obligations],TransactionsData[Current award type],AD44,TransactionsData[Selected],1))))/1000000) -> 3.2298286 | AG44: Competitive 8(a) | AH44: =IF((IF(AG44="","",IF(Trends!$B$6<>"","",SUMIFS(TransactionsData[Obligations],TransactionsData[Current set-aside],AG44,TransactionsData[Selected],1))))="","",(IF(AG44="","",IF(Trends!$B$6<>"","",SUMIFS(TransactionsData[Obligations],TransactionsData[Current set-aside],AG44,TransactionsData[Selected],1))))/1000000) -> 5.2792241 | AJ44: Maryland | AK44: =IF((IF(AJ44="","",IF(Trends!$B$6<>"","",SUMIFS(TransactionsData[Obligations],TransactionsData[Performance state],AJ44,TransactionsData[Selected],1))))="","",(IF(AJ44="","",IF(Trends!$B$6<>"","",SUMIFS(TransactionsData[Obligations],TransactionsData[Performance state],AJ44,TransactionsData[Selected],1))))/1000000) -> 5.0153911
AA45: =IF(Trends!A37="","",Trends!A37) -> FY2023 Q4 | AB45: =IF((IF(OR(Trends!$B$6<>"",AA45=""),"",Trends!D37))="","",(IF(OR(Trends!$B$6<>"",AA45=""),"",Trends!D37))/1000000) -> 5.2412096 | AD45: BPA Call | AE45: =IF((IF(AD45="","",IF(Trends!$B$6<>"","",SUMIFS(TransactionsData[Obligations],TransactionsData[Current award type],AD45,TransactionsData[Selected],1))))="","",(IF(AD45="","",IF(Trends!$B$6<>"","",SUMIFS(TransactionsData[Obligations],TransactionsData[Current award type],AD45,TransactionsData[Selected],1))))/1000000) -> 36.33306 | AG45: 8(a) Sole Source | AH45: =IF((IF(AG45="","",IF(Trends!$B$6<>"","",SUMIFS(TransactionsData[Obligations],TransactionsData[Current set-aside],AG45,TransactionsData[Selected],1))))="","",(IF(AG45="","",IF(Trends!$B$6<>"","",SUMIFS(TransactionsData[Obligations],TransactionsData[Current set-aside],AG45,TransactionsData[Selected],1))))/1000000) -> 1.5777104 | AJ45: Georgia | AK45: =IF((IF(AJ45="","",IF(Trends!$B$6<>"","",SUMIFS(TransactionsData[Obligations],TransactionsData[Performance state],AJ45,TransactionsData[Selected],1))))="","",(IF(AJ45="","",IF(Trends!$B$6<>"","",SUMIFS(TransactionsData[Obligations],TransactionsData[Performance state],AJ45,TransactionsData[Selected],1))))/1000000) -> 0.48979172
AA46: =IF(Trends!A38="","",Trends!A38) -> FY2024 Q1 | AB46: =IF((IF(OR(Trends!$B$6<>"",AA46=""),"",Trends!D38))="","",(IF(OR(Trends!$B$6<>"",AA46=""),"",Trends!D38))/1000000) -> 25.40001 | AJ46: District of Columbia | AK46: =IF((IF(AJ46="","",IF(Trends!$B$6<>"","",SUMIFS(TransactionsData[Obligations],TransactionsData[Performance state],AJ46,TransactionsData[Selected],1))))="","",(IF(AJ46="","",IF(Trends!$B$6<>"","",SUMIFS(TransactionsData[Obligations],TransactionsData[Performance state],AJ46,TransactionsData[Selected],1))))/1000000) -> 0.49538297
AA47: =IF(Trends!A39="","",Trends!A39) -> FY2024 Q2 | AB47: =IF((IF(OR(Trends!$B$6<>"",AA47=""),"",Trends!D39))="","",(IF(OR(Trends!$B$6<>"",AA47=""),"",Trends!D39))/1000000) -> 7.4993187 | AJ47: California | AK47: =IF((IF(AJ47="","",IF(Trends!$B$6<>"","",SUMIFS(TransactionsData[Obligations],TransactionsData[Performance state],AJ47,TransactionsData[Selected],1))))="","",(IF(AJ47="","",IF(Trends!$B$6<>"","",SUMIFS(TransactionsData[Obligations],TransactionsData[Performance state],AJ47,TransactionsData[Selected],1))))/1000000) -> 10.76911
AA48: =IF(Trends!A40="","",Trends!A40) -> FY2024 Q3 | AB48: =IF((IF(OR(Trends!$B$6<>"",AA48=""),"",Trends!D40))="","",(IF(OR(Trends!$B$6<>"",AA48=""),"",Trends!D40))/1000000) -> 23.742006
AA49: =IF(Trends!A41="","",Trends!A41) -> FY2024 Q4 | AB49: =IF((IF(OR(Trends!$B$6<>"",AA49=""),"",Trends!D41))="","",(IF(OR(Trends!$B$6<>"",AA49=""),"",Trends!D41))/1000000) -> 40.969937
...

Sheet Trends
A2: Trends
A3: ="Buyer: "&IF(Transactions!B3="","Not supplied",Transactions!B3)&" | History: "&IF(Transactions!B4="","Not supplied",TEXT(Transactions!B4,"mmm d, yyyy"))&" through "&IF(Transactions!D4="","Not supplied",TEXT(Transactions!D4,"mmm d, yyyy"))&" | Award type: "&Dashboard!$N$10 -> Buyer: National Science Foundation | History: Oct 1, 2022 through Sep 30, 2025 | Award type: All
A4: ="Vendor: "&Dashboard!H7&CHAR(10)&"Funding office: "&Dashboard!B10 -> Vendor: All Funding office: All
A5: Chart in USD millions; supporting tables in USD.
A6: Report status | B6: =IF(COUNTIF(AwardsData[Input check],"New category: refresh report")>0,"Refresh report for new classifications",IF(COUNTA(TransactionsData[Transaction ID])=0,"Awaiting source data",IF(OR(NOT(ISNUMBER(Transactions!B4)),NOT(ISNUMBER(Transactions!D4)),Transactions!B4>Transactions!D4,NOT(ISNUMBER(Transactions!G4))),"Enter valid coverage and retrieval dates",IF(COUNTIFS(TransactionsData[Input check],"?*")+COUNTIFS(AwardsData[Input check],"?*")+COUNTIFS(VendorGroups[Input check],"?*")+COUNTIFS(OfficeGroups[Input check],"?*")>0,"Review source input checks",IF(OR(Dashboard!$AB$2="Invalid",Dashboard!$AB$3="Invalid",AND(Dashboard!$N$10<>"All",COUNTIFS(TypeChoices,Dashboard!$N$10)<>1)),"Choose valid Dashboard filters",IF(NOT(OR(Dashboard!$B$7="All",COUNTIFS($I$26:$I$28,Dashboard!$B$7)=1)),"Choose a reporting year",IF(SUMPRODUCT((TransactionsData[Eligible]=1)*(COUNTIFS(VendorGroups[Record ID],TransactionsData[Vendor ID])<>1))+SUMPRODUCT((TransactionsData[Eligible]=1)*(COUNTIFS(OfficeGroups[Record ID],TransactionsData[Funding office ID])<>1))>0,"Add missing vendor or office registry IDs","")))))))
A23: Four-quarter average begins after four complete consecutive quarters. Negative values retain their sign.
A25: Fiscal year | B25: Positive obligations | C25: Deobligations | D25: Net obligations | E25: Awards with obligations | F25: Vendors with obligations | G25: Transactions | H25: YoY change | I25: Year key | J25: Complete year
A26: =IF(I26="","","FY"&I26) -> FY2023 | B26: =IF(I26="","",IF(Trends!$B$6<>"","",SUMIFS(TransactionsData[Positive],TransactionsData[FY],I26,TransactionsData[Dimension match],1))) -> 24025004 | C26: =IF(I26="","",IF(Trends!$B$6<>"","",SUMIFS(TransactionsData[Deobligations],TransactionsData[FY],I26,TransactionsData[Dimension match],1))) -> 0 | D26: =IF(I26="","",IF(Trends!$B$6<>"","",SUMIFS(TransactionsData[Obligations],TransactionsData[FY],I26,TransactionsData[Dimension match],1))) -> 24025004 | E26: =IF(I26="","",IF(Trends!$B$6<>"","",SUMIFS(TransactionsData[First annual award],TransactionsData[FY],I26,TransactionsData[Dimension match],1))) -> 16 | F26: =IF(I26="","",IF(Trends!$B$6<>"","",SUMIFS(TransactionsData[First annual vendor],TransactionsData[FY],I26,TransactionsData[Dimension match],1))) -> 10 | G26: =IF(I26="","",IF(Trends!$B$6<>"","",COUNTIFS(TransactionsData[FY],I26,TransactionsData[Dimension match],1))) -> 34 | H26: ="" | I26: 2023 | J26: =IF(I26="","",IF(AND(Transactions!$B$4<=DATE(I26-1,10,1),Transactions!$D$4>=DATE(I26,9,30)),1,0)) -> 1
A27: =IF(I27="","","FY"&I27) -> FY2024 | B27: =IF(I27="","",IF(Trends!$B$6<>"","",SUMIFS(TransactionsData[Positive],TransactionsData[FY],I27,TransactionsData[Dimension match],1))) -> 97611271 | C27: =IF(I27="","",IF(Trends!$B$6<>"","",SUMIFS(TransactionsData[Deobligations],TransactionsData[FY],I27,TransactionsData[Dimension match],1))) -> 0 | D27: =IF(I27="","",IF(Trends!$B$6<>"","",SUMIFS(TransactionsData[Obligations],TransactionsData[FY],I27,TransactionsData[Dimension match],1))) -> 97611271 | E27: =IF(I27="","",IF(Trends!$B$6<>"","",SUMIFS(TransactionsData[First annual award],TransactionsData[FY],I27,TransactionsData[Dimension match],1))) -> 34 | F27: =IF(I27="","",IF(Trends!$B$6<>"","",SUMIFS(TransactionsData[First annual vendor],TransactionsData[FY],I27,TransactionsData[Dimension match],1))) -> 18 | G27: =IF(I27="","",IF(Trends!$B$6<>"","",COUNTIFS(TransactionsData[FY],I27,TransactionsData[Dimension match],1))) -> 74 | H27: =IF(AND(Trends!$B$6="",J27=1,J26=1,D26>0),(D27-D26)/D26,"") -> 3.0629035 | I27: 2024 | J27: =IF(I27="","",IF(AND(Transactions!$B$4<=DATE(I27-1,10,1),Transactions!$D$4>=DATE(I27,9,30)),1,0)) -> 1
A28: =IF(I28="","","FY"&I28) -> FY2025 | B28: =IF(I28="","",IF(Trends!$B$6<>"","",SUMIFS(TransactionsData[Positive],TransactionsData[FY],I28,TransactionsData[Dimension match],1))) -> 1.2161709e+08 | C28: =IF(I28="","",IF(Trends!$B$6<>"","",SUMIFS(TransactionsData[Deobligations],TransactionsData[FY],I28,TransactionsData[Dimension match],1))) -> -1300426.3 | D28: =IF(I28="","",IF(Trends!$B$6<>"","",SUMIFS(TransactionsData[Obligations],TransactionsData[FY],I28,TransactionsData[Dimension match],1))) -> 1.2031667e+08 | E28: =IF(I28="","",IF(Trends!$B$6<>"","",SUMIFS(TransactionsData[First annual award],TransactionsData[FY],I28,TransactionsData[Dimension match],1))) -> 34 | F28: =IF(I28="","",IF(Trends!$B$6<>"","",SUMIFS(TransactionsData[First annual vendor],TransactionsData[FY],I28,TransactionsData[Dimension match],1))) -> 18 | G28: =IF(I28="","",IF(Trends!$B$6<>"","",COUNTIFS(TransactionsData[FY],I28,TransactionsData[Dimension match],1))) -> 106 | H28: =IF(AND(Trends!$B$6="",J28=1,J27=1,D27>0),(D28-D27)/D27,"") -> 0.23261038 | I28: 2025 | J28: =IF(I28="","",IF(AND(Transactions!$B$4<=DATE(I28-1,10,1),Transactions!$D$4>=DATE(I28,9,30)),1,0)) -> 1
A33: Quarter | B33: From | C33: Through | D33: Net obligations | E33: Deobligations | F33: Transactions | G33: 4-quarter average | H33: Coverage | I33: Year key | J33: Quarter key | K33: Selected order | L33: Net obligations | M33: 4-quarter average
A34: =IF(I34="","","FY"&I34&" Q"&J34) -> FY2023 Q1 | B34: =IF(I34="","",DATE(I34-IF(J34=1,1,0),CHOOSE(J34,10,1,4,7),1)) -> 44835 | C34: =IF(B34="","",EDATE(B34,3)-1) -> 44926 | D34: =IF(I34="","",IF(Trends!$B$6<>"","",SUMIFS(TransactionsData[Obligations],TransactionsData[FY],I34,TransactionsData[Quarter],J34,TransactionsData[Dimension match],1))) -> 6115620.3 | E34: =IF(I34="","",IF(Trends!$B$6<>"","",SUMIFS(TransactionsData[Deobligations],TransactionsData[FY],I34,TransactionsData[Quarter],J34,TransactionsData[Dimension match],1))) -> 0 | F34: =IF(I34="","",IF(Trends!$B$6<>"","",COUNTIFS(TransactionsData[FY],I34,TransactionsData[Quarter],J34,TransactionsData[Dimension match],1))) -> 6 | H34: =IF(I34="","",IF(AND(B34>=Transactions!$B$4,C34<=Transactions!$D$4),"Complete","Partial")) -> Complete | I34: 2023 | J34: 1 | K34: =IF(OR(I34="",AND(Dashboard!$B$7<>"All",I34<>Dashboard!$B$7)),0,IF(Dashboard!$B$7="All",ROW()-33,J34)) -> 0 | L34: =IF(OR(Trends!$B$6<>"",I34=""),"",D34/1000000) -> 6.1156203
A35: =IF(I35="","","FY"&I35&" Q"&J35) -> FY2023 Q2 | B35: =IF(I35="","",DATE(I35-IF(J35=1,1,0),CHOOSE(J35,10,1,4,7),1)) -> 44927 | C35: =IF(B35="","",EDATE(B35,3)-1) -> 45016 | D35: =IF(I35="","",IF(Trends!$B$6<>"","",SUMIFS(TransactionsData[Obligations],TransactionsData[FY],I35,TransactionsData[Quarter],J35,TransactionsData[Dimension match],1))) -> 9218271.1 | E35: =IF(I35="","",IF(Trends!$B$6<>"","",SUMIFS(TransactionsData[Deobligations],TransactionsData[FY],I35,TransactionsData[Quarter],J35,TransactionsData[Dimension match],1))) -> 0 | F35: =IF(I35="","",IF(Trends!$B$6<>"","",COUNTIFS(TransactionsData[FY],I35,TransactionsData[Quarter],J35,TransactionsData[Dimension match],1))) -> 6 | H35: =IF(I35="","",IF(AND(B35>=Transactions!$B$4,C35<=Transactions!$D$4),"Complete","Partial")) -> Complete | I35: 2023 | J35: 2 | K35: =IF(OR(I35="",AND(Dashboard!$B$7<>"All",I35<>Dashboard!$B$7)),0,IF(Dashboard!$B$7="All",ROW()-33,J35)) -> 0 | L35: =IF(OR(Trends!$B$6<>"",I35=""),"",D35/1000000) -> 9.2182711
A36: =IF(I36="","","FY"&I36&" Q"&J36) -> FY2023 Q3 | B36: =IF(I36="","",DATE(I36-IF(J36=1,1,0),CHOOSE(J36,10,1,4,7),1)) -> 45017 | C36: =IF(B36="","",EDATE(B36,3)-1) -> 45107 | D36: =IF(I36="","",IF(Trends!$B$6<>"","",SUMIFS(TransactionsData[Obligations],TransactionsData[FY],I36,TransactionsData[Quarter],J36,TransactionsData[Dimension match],1))) -> 3449902.9 | E36: =IF(I36="","",IF(Trends!$B$6<>"","",SUMIFS(TransactionsData[Deobligations],TransactionsData[FY],I36,TransactionsData[Quarter],J36,TransactionsData[Dimension match],1))) -> 0 | F36: =IF(I36="","",IF(Trends!$B$6<>"","",COUNTIFS(TransactionsData[FY],I36,TransactionsData[Quarter],J36,TransactionsData[Dimension match],1))) -> 7 | H36: =IF(I36="","",IF(AND(B36>=Transactions!$B$4,C36<=Transactions!$D$4),"Complete","Partial")) -> Complete | I36: 2023 | J36: 3 | K36: =IF(OR(I36="",AND(Dashboard!$B$7<>"All",I36<>Dashboard!$B$7)),0,IF(Dashboard!$B$7="All",ROW()-33,J36)) -> 0 | L36: =IF(OR(Trends!$B$6<>"",I36=""),"",D36/1000000) -> 3.4499029
A37: =IF(I37="","","FY"&I37&" Q"&J37) -> FY2023 Q4 | B37: =IF(I37="","",DATE(I37-IF(J37=1,1,0),CHOOSE(J37,10,1,4,7),1)) -> 45108 | C37: =IF(B37="","",EDATE(B37,3)-1) -> 45199 | D37: =IF(I37="","",IF(Trends!$B$6<>"","",SUMIFS(TransactionsData[Obligations],TransactionsData[FY],I37,TransactionsData[Quarter],J37,TransactionsData[Dimension match],1))) -> 5241209.6 | E37: =IF(I37="","",IF(Trends!$B$6<>"","",SUMIFS(TransactionsData[Deobligations],TransactionsData[FY],I37,TransactionsData[Quarter],J37,TransactionsData[Dimension match],1))) -> 0 | F37: =IF(I37="","",IF(Trends!$B$6<>"","",COUNTIFS(TransactionsData[FY],I37,TransactionsData[Quarter],J37,TransactionsData[Dimension match],1))) -> 15 | G37: =IF(AND(Trends!$B$6="",COUNTIFS(H34:H37,"Complete")=4),SUM(D34:D37)/4,"") -> 6006251 | H37: =IF(I37="","",IF(AND(B37>=Transactions!$B$4,C37<=Transactions!$D$4),"Complete","Partial")) -> Complete | I37: 2023 | J37: 4 | K37: =IF(OR(I37="",AND(Dashboard!$B$7<>"All",I37<>Dashboard!$B$7)),0,IF(Dashboard!$B$7="All",ROW()-33,J37)) -> 0 | L37: =IF(OR(Trends!$B$6<>"",I37=""),"",D37/1000000) -> 5.2412096 | M37: =IF(G37="","",G37/1000000) -> 6.006251
A38: =IF(I38="","","FY"&I38&" Q"&J38) -> FY2024 Q1 | B38: =IF(I38="","",DATE(I38-IF(J38=1,1,0),CHOOSE(J38,10,1,4,7),1)) -> 45200 | C38: =IF(B38="","",EDATE(B38,3)-1) -> 45291 | D38: =IF(I38="","",IF(Trends!$B$6<>"","",SUMIFS(TransactionsData[Obligations],TransactionsData[FY],I38,TransactionsData[Quarter],J38,TransactionsData[Dimension match],1))) -> 25400010 | E38: =IF(I38="","",IF(Trends!$B$6<>"","",SUMIFS(TransactionsData[Deobligations],TransactionsData[FY],I38,TransactionsData[Quarter],J38,TransactionsData[Dimension match],1))) -> 0 | F38: =IF(I38="","",IF(Trends!$B$6<>"","",COUNTIFS(TransactionsData[FY],I38,TransactionsData[Quarter],J38,TransactionsData[Dimension match],1))) -> 13 | G38: =IF(AND(Trends!$B$6="",COUNTIFS(H35:H38,"Complete")=4),SUM(D35:D38)/4,"") -> 10827348 | H38: =IF(I38="","",IF(AND(B38>=Transactions!$B$4,C38<=Transactions!$D$4),"Complete","Partial")) -> Complete | I38: 2024 | J38: 1 | K38: =IF(OR(I38="",AND(Dashboard!$B$7<>"All",I38<>Dashboard!$B$7)),0,IF(Dashboard!$B$7="All",ROW()-33,J38)) -> 0 | L38: =IF(OR(Trends!$B$6<>"",I38=""),"",D38/1000000) -> 25.40001 | M38: =IF(G38="","",G38/1000000) -> 10.827348
A39: =IF(I39="","","FY"&I39&" Q"&J39) -> FY2024 Q2 | B39: =IF(I39="","",DATE(I39-IF(J39=1,1,0),CHOOSE(J39,10,1,4,7),1)) -> 45292 | C39: =IF(B39="","",EDATE(B39,3)-1) -> 45382 | D39: =IF(I39="","",IF(Trends!$B$6<>"","",SUMIFS(TransactionsData[Obligations],TransactionsData[FY],I39,TransactionsData[Quarter],J39,TransactionsData[Dimension match],1))) -> 7499318.7 | E39: =IF(I39="","",IF(Trends!$B$6<>"","",SUMIFS(TransactionsData[Deobligations],TransactionsData[FY],I39,TransactionsData[Quarter],J39,TransactionsData[Dimension match],1))) -> 0 | F39: =IF(I39="","",IF(Trends!$B$6<>"","",COUNTIFS(TransactionsData[FY],I39,TransactionsData[Quarter],J39,TransactionsData[Dimension match],1))) -> 16 | G39: =IF(AND(Trends!$B$6="",COUNTIFS(H36:H39,"Complete")=4),SUM(D36:D39)/4,"") -> 10397610 | H39: =IF(I39="","",IF(AND(B39>=Transactions!$B$4,C39<=Transactions!$D$4),"Complete","Partial")) -> Complete | I39: 2024 | J39: 2 | K39: =IF(OR(I39="",AND(Dashboard!$B$7<>"All",I39<>Dashboard!$B$7)),0,IF(Dashboard!$B$7="All",ROW()-33,J39)) -> 0 | L39: =IF(OR(Trends!$B$6<>"",I39=""),"",D39/1000000) -> 7.4993187 | M39: =IF(G39="","",G39/1000000) -> 10.39761
A40: =IF(I40="","","FY"&I40&" Q"&J40) -> FY2024 Q3 | B40: =IF(I40="","",DATE(I40-IF(J40=1,1,0),CHOOSE(J40,10,1,4,7),1)) -> 45383 | C40: =IF(B40="","",EDATE(B40,3)-1) -> 45473 | D40: =IF(I40="","",IF(Trends!$B$6<>"","",SUMIFS(TransactionsData[Obligations],TransactionsData[FY],I40,TransactionsData[Quarter],J40,TransactionsData[Dimension match],1))) -> 23742006 | E40: =IF(I40="","",IF(Trends!$B$6<>"","",SUMIFS(TransactionsData[Deobligations],TransactionsData[FY],I40,TransactionsData[Quarter],J40,TransactionsData[Dimension match],1))) -> 0 | F40: =IF(I40="","",IF(Trends!$B$6<>"","",COUNTIFS(TransactionsData[FY],I40,TransactionsData[Quarter],J40,TransactionsData[Dimension match],1))) -> 21 | G40: =IF(AND(Trends!$B$6="",COUNTIFS(H37:H40,"Complete")=4),SUM(D37:D40)/4,"") -> 15470636 | H40: =IF(I40="","",IF(AND(B40>=Transactions!$B$4,C40<=Transactions!$D$4),"Complete","Partial")) -> Complete | I40: 2024 | J40: 3 | K40: =IF(OR(I40="",AND(Dashboard!$B$7<>"All",I40<>Dashboard!$B$7)),0,IF(Dashboard!$B$7="All",ROW()-33,J40)) -> 0 | L40: =IF(OR(Trends!$B$6<>"",I40=""),"",D40/1000000) -> 23.742006 | M40: =IF(G40="","",G40/1000000) -> 15.470636
A41: =IF(I41="","","FY"&I41&" Q"&J41) -> FY2024 Q4 | B41: =IF(I41="","",DATE(I41-IF(J41=1,1,0),CHOOSE(J41,10,1,4,7),1)) -> 45474 | C41: =IF(B41="","",EDATE(B41,3)-1) -> 45565 | D41: =IF(I41="","",IF(Trends!$B$6<>"","",SUMIFS(TransactionsData[Obligations],TransactionsData[FY],I41,TransactionsData[Quarter],J41,TransactionsData[Dimension match],1))) -> 40969937 | E41: =IF(I41="","",IF(Trends!$B$6<>"","",SUMIFS(TransactionsData[Deobligations],TransactionsData[FY],I41,TransactionsData[Quarter],J41,TransactionsData[Dimension match],1))) -> 0 | F41: =IF(I41="","",IF(Trends!$B$6<>"","",COUNTIFS(TransactionsData[FY],I41,TransactionsData[Quarter],J41,TransactionsData[Dimension match],1))) -> 24 | G41: =IF(AND(Trends!$B$6="",COUNTIFS(H38:H41,"Complete")=4),SUM(D38:D41)/4,"") -> 24402818 | H41: =IF(I41="","",IF(AND(B41>=Transactions!$B$4,C41<=Transactions!$D$4),"Complete","Partial")) -> Complete | I41: 2024 | J41: 4 | K41: =IF(OR(I41="",AND(Dashboard!$B$7<>"All",I41<>Dashboard!$B$7)),0,IF(Dashboard!$B$7="All",ROW()-33,J41)) -> 0 | L41: =IF(OR(Trends!$B$6<>"",I41=""),"",D41/1000000) -> 40.969937 | M41: =IF(G41="","",G41/1000000) -> 24.402818
A42: =IF(I42="","","FY"&I42&" Q"&J42) -> FY2025 Q1 | B42: =IF(I42="","",DATE(I42-IF(J42=1,1,0),CHOOSE(J42,10,1,4,7),1)) -> 45566 | C42: =IF(B42="","",EDATE(B42,3)-1) -> 45657 | D42: =IF(I42="","",IF(Trends!$B$6<>"","",SUMIFS(TransactionsData[Obligations],TransactionsData[FY],I42,TransactionsData[Quarter],J42,TransactionsData[Dimension match],1))) -> 15412439 | E42: =IF(I42="","",IF(Trends!$B$6<>"","",SUMIFS(TransactionsData[Deobligations],TransactionsData[FY],I42,TransactionsData[Quarter],J42,TransactionsData[Dimension match],1))) -> 0 | F42: =IF(I42="","",IF(Trends!$B$6<>"","",COUNTIFS(TransactionsData[FY],I42,TransactionsData[Quarter],J42,TransactionsData[Dimension match],1))) -> 21 | G42: =IF(AND(Trends!$B$6="",COUNTIFS(H39:H42,"Complete")=4),SUM(D39:D42)/4,"") -> 21905925 | H42: =IF(I42="","",IF(AND(B42>=Transactions!$B$4,C42<=Transactions!$D$4),"Complete","Partial")) -> Complete | I42: 2025 | J42: 1 | K42: =IF(OR(I42="",AND(Dashboard!$B$7<>"All",I42<>Dashboard!$B$7)),0,IF(Dashboard!$B$7="All",ROW()-33,J42)) -> 1 | L42: =IF(OR(Trends!$B$6<>"",I42=""),"",D42/1000000) -> 15.412439 | M42: =IF(G42="","",G42/1000000) -> 21.905925
A43: =IF(I43="","","FY"&I43&" Q"&J43) -> FY2025 Q2 | B43: =IF(I43="","",DATE(I43-IF(J43=1,1,0),CHOOSE(J43,10,1,4,7),1)) -> 45658 | C43: =IF(B43="","",EDATE(B43,3)-1) -> 45747 | D43: =IF(I43="","",IF(Trends!$B$6<>"","",SUMIFS(TransactionsData[Obligations],TransactionsData[FY],I43,TransactionsData[Quarter],J43,TransactionsData[Dimension match],1))) -> 39930780 | E43: =IF(I43="","",IF(Trends!$B$6<>"","",SUMIFS(TransactionsData[Deobligations],TransactionsData[FY],I43,TransactionsData[Quarter],J43,TransactionsData[Dimension match],1))) -> -90.35 | F43: =IF(I43="","",IF(Trends!$B$6<>"","",COUNTIFS(TransactionsData[FY],I43,TransactionsData[Quarter],J43,TransactionsData[Dimension match],1))) -> 26 | G43: =IF(AND(Trends!$B$6="",COUNTIFS(H40:H43,"Complete")=4),SUM(D40:D43)/4,"") -> 30013791 | H43: =IF(I43="","",IF(AND(B43>=Transactions!$B$4,C43<=Transactions!$D$4),"Complete","Partial")) -> Complete | I43: 2025 | J43: 2 | K43: =IF(OR(I43="",AND(Dashboard!$B$7<>"All",I43<>Dashboard!$B$7)),0,IF(Dashboard!$B$7="All",ROW()-33,J43)) -> 2 | L43: =IF(OR(Trends!$B$6<>"",I43=""),"",D43/1000000) -> 39.93078 | M43: =IF(G43="","",G43/1000000) -> 30.013791
A44: =IF(I44="","","FY"&I44&" Q"&J44) -> FY2025 Q3 | B44: =IF(I44="","",DATE(I44-IF(J44=1,1,0),CHOOSE(J44,10,1,4,7),1)) -> 45748 | C44: =IF(B44="","",EDATE(B44,3)-1) -> 45838 | D44: =IF(I44="","",IF(Trends!$B$6<>"","",SUMIFS(TransactionsData[Obligations],TransactionsData[FY],I44,TransactionsData[Quarter],J44,TransactionsData[Dimension match],1))) -> 14093815 | E44: =IF(I44="","",IF(Trends!$B$6<>"","",SUMIFS(TransactionsData[Deobligations],TransactionsData[FY],I44,TransactionsData[Quarter],J44,TransactionsData[Dimension match],1))) -> -960102.33 | F44: =IF(I44="","",IF(Trends!$B$6<>"","",COUNTIFS(TransactionsData[FY],I44,TransactionsData[Quarter],J44,TransactionsData[Dimension match],1))) -> 15 | G44: =IF(AND(Trends!$B$6="",COUNTIFS(H41:H44,"Complete")=4),SUM(D41:D44)/4,"") -> 27601743 | H44: =IF(I44="","",IF(AND(B44>=Transactions!$B$4,C44<=Transactions!$D$4),"Complete","Partial")) -> Complete | I44: 2025 | J44: 3 | K44: =IF(OR(I44="",AND(Dashboard!$B$7<>"All",I44<>Dashboard!$B$7)),0,IF(Dashboard!$B$7="All",ROW()-33,J44)) -> 3 | L44: =IF(OR(Trends!$B$6<>"",I44=""),"",D44/1000000) -> 14.093815 | M44: =IF(G44="","",G44/1000000) -> 27.601743
A45: =IF(I45="","","FY"&I45&" Q"&J45) -> FY2025 Q4 | B45: =IF(I45="","",DATE(I45-IF(J45=1,1,0),CHOOSE(J45,10,1,4,7),1)) -> 45839 | C45: =IF(B45="","",EDATE(B45,3)-1) -> 45930 | D45: =IF(I45="","",IF(Trends!$B$6<>"","",SUMIFS(TransactionsData[Obligations],TransactionsData[FY],I45,TransactionsData[Quarter],J45,TransactionsData[Dimension match],1))) -> 50879631 | E45: =IF(I45="","",IF(Trends!$B$6<>"","",SUMIFS(TransactionsData[Deobligations],TransactionsData[FY],I45,TransactionsData[Quarter],J45,TransactionsData[Dimension match],1))) -> -340233.63 | F45: =IF(I45="","",IF(Trends!$B$6<>"","",COUNTIFS(TransactionsData[FY],I45,TransactionsData[Quarter],J45,TransactionsData[Dimension match],1))) -> 44 | G45: =IF(AND(Trends!$B$6="",COUNTIFS(H42:H45,"Complete")=4),SUM(D42:D45)/4,"") -> 30079166 | H45: =IF(I45="","",IF(AND(B45>=Transactions!$B$4,C45<=Transactions!$D$4),"Complete","Partial")) -> Complete | I45: 2025 | J45: 4 | K45: =IF(OR(I45="",AND(Dashboard!$B$7<>"All",I45<>Dashboard!$B$7)),0,IF(Dashboard!$B$7="All",ROW()-33,J45)) -> 4 | L45: =IF(OR(Trends!$B$6<>"",I45=""),"",D45/1000000) -> 50.879631 | M45: =IF(G45="","",G45/1000000) -> 30.079166

Sheet Vendors & Buyers
A2: Vendors & Buyers
A3: ="Buyer: "&IF(Transactions!B3="","Not supplied",Transactions!B3)&" | Period: "&IF(Dashboard!$B$7="All","All covered years",IF(Dashboard!$B$7="","Not supplied","FY"&Dashboard!$B$7))&" | Award type: "&Dashboard!$N$10 -> Buyer: National Science Foundation | Period: FY2025 | Award type: All
A4: ="Vendor: "&Dashboard!H7 -> Vendor: All
A5: ="Funding office: "&Dashboard!B10 -> Funding office: All
A6: Rankings follow the filters above. Award counts include nonzero obligation or deobligation actions.
A7: Rank | B7: Vendor | C7: UEI | D7: Net obligations | E7: Deobligations | F7: Awards with obligations | G7: Transactions | H7: Record ID | I7: Source name | J7: Source UEI | K7: Source URL | L7: Filter label | M7: Source net | N7: Source deobligations | O7: Source awards | P7: Source actions | Q7: Source rank | R7: Input check
A8: =IF(Trends!$B$6<>"","",IF(COUNTIFS(VendorGroups[Source rank],1)=1,1,"")) -> 1 | B8: =IF(Trends!$B$6<>"","",IF(COUNTIFS(VendorGroups[Source rank],1)=1,IF(INDEX(VendorGroups[Source URL],MATCH(1,VendorGroups[Source rank],0))="",INDEX(VendorGroups[Source name],MATCH(1,VendorGroups[Source rank],0)),HYPERLINK(INDEX(VendorGroups[Source URL],MATCH(1,VendorGroups[Source rank],0)),INDEX(VendorGroups[Source name],MATCH(1,VendorGroups[Source rank],0)))),"")) -> Booz Allen Hamilton Inc. | C8: =IF(Trends!$B$6<>"","",IF(COUNTIFS(VendorGroups[Source rank],1)=1,IF(INDEX(VendorGroups[Source UEI],MATCH(1,VendorGroups[Source rank],0))="","Not supplied",INDEX(VendorGroups[Source UEI],MATCH(1,VendorGroups[Source rank],0))),"")) -> JCBMLGPE6Z71 | D8: =IF(Trends!$B$6<>"","",IF(COUNTIFS(VendorGroups[Source rank],1)=1,INDEX(VendorGroups[Source net],MATCH(1,VendorGroups[Source rank],0)),"")) -> 53165051 | E8: =IF(Trends!$B$6<>"","",IF(COUNTIFS(VendorGroups[Source rank],1)=1,INDEX(VendorGroups[Source deobligations],MATCH(1,VendorGroups[Source rank],0)),"")) -> 0 | F8: =IF(Trends!$B$6<>"","",IF(COUNTIFS(VendorGroups[Source rank],1)=1,INDEX(VendorGroups[Source awards],MATCH(1,VendorGroups[Source rank],0)),"")) -> 1 | G8: =IF(Trends!$B$6<>"","",IF(COUNTIFS(VendorGroups[Source rank],1)=1,INDEX(VendorGroups[Source actions],MATCH(1,VendorGroups[Source rank],0)),"")) -> 15 | H8: OHd3bTBwbEZXcHJrNFVtbnphbjRJdz09 | I8: Agility Technologies Inc. | J8: Z9M6NN4AQLF7 | K8: https://govtribe.com/vendors/agility-technologies-inc-dot-5b8b7 | L8: =IF(H8="","",I8&IF(J8="",""," ["&J8&"]")) -> Agility Technologies Inc. [Z9M6NN4AQLF7] | M8: =IF(H8="","",SUMIFS(TransactionsData[Obligations],TransactionsData[Vendor ID],H8,TransactionsData[Selected],1)) -> 592445.36 | N8: =IF(H8="","",SUMIFS(TransactionsData[Deobligations],TransactionsData[Vendor ID],H8,TransactionsData[Selected],1)) -> -90.35 | O8: =IF(H8="","",SUMIFS(TransactionsData[First vendor award],TransactionsData[Vendor ID],H8)) -> 2 | P8: =IF(H8="","",COUNTIFS(TransactionsData[Vendor ID],H8,TransactionsData[Selected],1)) -> 2 | Q8: =IF(OR(H8="",P8=0),"",COUNTIFS(VendorGroups[Source net],">"&M8,VendorGroups[Source actions],">0")+COUNTIFS(VendorGroups[Source net],M8,VendorGroups[Record ID],"<"&H8,VendorGroups[Source actions],">0")+1) -> 11 | R8: =IF(H8="",IF(COUNTA(I8:K8)>0,"Missing record ID",""),IF(COUNTIFS(VendorGroups[Record ID],H8)<>1,"Duplicate record ID",IF(I8="","Add name","")))
A9: =IF(Trends!$B$6<>"","",IF(COUNTIFS(VendorGroups[Source rank],2)=1,2,"")) -> 2 | B9: =IF(Trends!$B$6<>"","",IF(COUNTIFS(VendorGroups[Source rank],2)=1,IF(INDEX(VendorGroups[Source URL],MATCH(2,VendorGroups[Source rank],0))="",INDEX(VendorGroups[Source name],MATCH(2,VendorGroups[Source rank],0)),HYPERLINK(INDEX(VendorGroups[Source URL],MATCH(2,VendorGroups[Source rank],0)),INDEX(VendorGroups[Source name],MATCH(2,VendorGroups[Source rank],0)))),"")) -> Directviz Solutions, LLC | C9: =IF(Trends!$B$6<>"","",IF(COUNTIFS(VendorGroups[Source rank],2)=1,IF(INDEX(VendorGroups[Source UEI],MATCH(2,VendorGroups[Source rank],0))="","Not supplied",INDEX(VendorGroups[Source UEI],MATCH(2,VendorGroups[Source rank],0))),"")) -> YXH4AGD2LGF5 | D9: =IF(Trends!$B$6<>"","",IF(COUNTIFS(VendorGroups[Source rank],2)=1,INDEX(VendorGroups[Source net],MATCH(2,VendorGroups[Source rank],0)),"")) -> 22532734 | E9: =IF(Trends!$B$6<>"","",IF(COUNTIFS(VendorGroups[Source rank],2)=1,INDEX(VendorGroups[Source deobligations],MATCH(2,VendorGroups[Source rank],0)),"")) -> 0 | F9: =IF(Trends!$B$6<>"","",IF(COUNTIFS(VendorGroups[Source rank],2)=1,INDEX(VendorGroups[Source awards],MATCH(2,VendorGroups[Source rank],0)),"")) -> 5 | G9: =IF(Trends!$B$6<>"","",IF(COUNTIFS(VendorGroups[Source rank],2)=1,INDEX(VendorGroups[Source actions],MATCH(2,VendorGroups[Source rank],0)),"")) -> 11 | H9: L0R0d3dCdlZtWHRzZklTY0R1ZStPdz09 | I9: Anika Systems Incorporated | J9: Y9V7J5VN9F68 | K9: https://govtribe.com/vendors/anika-systems-incorporated-61up0 | L9: =IF(H9="","",I9&IF(J9="",""," ["&J9&"]")) -> Anika Systems Incorporated [Y9V7J5VN9F68] | M9: =IF(H9="","",SUMIFS(TransactionsData[Obligations],TransactionsData[Vendor ID],H9,TransactionsData[Selected],1)) -> 4954939.8 | N9: =IF(H9="","",SUMIFS(TransactionsData[Deobligations],TransactionsData[Vendor ID],H9,TransactionsData[Selected],1)) -> 0 | O9: =IF(H9="","",SUMIFS(TransactionsData[First vendor award],TransactionsData[Vendor ID],H9)) -> 1 | P9: =IF(H9="","",COUNTIFS(TransactionsData[Vendor ID],H9,TransactionsData[Selected],1)) -> 4 | Q9: =IF(OR(H9="",P9=0),"",COUNTIFS(VendorGroups[Source net],">"&M9,VendorGroups[Source actions],">0")+COUNTIFS(VendorGroups[Source net],M9,VendorGroups[Record ID],"<"&H9,VendorGroups[Source actions],">0")+1) -> 7 | R9: =IF(H9="",IF(COUNTA(I9:K9)>0,"Missing record ID",""),IF(COUNTIFS(VendorGroups[Record ID],H9)<>1,"Duplicate record ID",IF(I9="","Add name","")))
A10: =IF(Trends!$B$6<>"","",IF(COUNTIFS(VendorGroups[Source rank],3)=1,3,"")) -> 3 | B10: =IF(Trends!$B$6<>"","",IF(COUNTIFS(VendorGroups[Source rank],3)=1,IF(INDEX(VendorGroups[Source URL],MATCH(3,VendorGroups[Source rank],0))="",INDEX(VendorGroups[Source name],MATCH(3,VendorGroups[Source rank],0)),HYPERLINK(INDEX(VendorGroups[Source URL],MATCH(3,VendorGroups[Source rank],0)),INDEX(VendorGroups[Source name],MATCH(3,VendorGroups[Source rank],0)))),"")) -> Civicactions, Inc. | C10: =IF(Trends!$B$6<>"","",IF(COUNTIFS(VendorGroups[Source rank],3)=1,IF(INDEX(VendorGroups[Source UEI],MATCH(3,VendorGroups[Source rank],0))="","Not supplied",INDEX(VendorGroups[Source UEI],MATCH(3,VendorGroups[Source rank],0))),"")) -> XSZFHRS5QFL5 | D10: =IF(Trends!$B$6<>"","",IF(COUNTIFS(VendorGroups[Source rank],3)=1,INDEX(VendorGroups[Source net],MATCH(3,VendorGroups[Source rank],0)),"")) -> 10769110 | E10: =IF(Trends!$B$6<>"","",IF(COUNTIFS(VendorGroups[Source rank],3)=1,INDEX(VendorGroups[Source deobligations],MATCH(3,VendorGroups[Source rank],0)),"")) -> -561.71 | F10: =IF(Trends!$B$6<>"","",IF(COUNTIFS(VendorGroups[Source rank],3)=1,INDEX(VendorGroups[Source awards],MATCH(3,VendorGroups[Source rank],0)),"")) -> 1 | G10: =IF(Trends!$B$6<>"","",IF(COUNTIFS(VendorGroups[Source rank],3)=1,INDEX(VendorGroups[Source actions],MATCH(3,VendorGroups[Source rank],0)),"")) -> 10 | H10: K1ZVMVVzSS81SWIveXlWTi93b2V0UT09 | I10: Booz Allen Hamilton Inc. | J10: JCBMLGPE6Z71 | K10: https://govtribe.com/vendors/booz-allen-hamilton-inc-dot-17038 | L10: =IF(H10="","",I10&IF(J10="",""," ["&J10&"]")) -> Booz Allen Hamilton Inc. [JCBMLGPE6Z71] | M10: =IF(H10="","",SUMIFS(TransactionsData[Obligations],TransactionsData[Vendor ID],H10,TransactionsData[Selected],1)) -> 53165051 | N10: =IF(H10="","",SUMIFS(TransactionsData[Deobligations],TransactionsData[Vendor ID],H10,TransactionsData[Selected],1)) -> 0 | O10: =IF(H10="","",SUMIFS(TransactionsData[First vendor award],TransactionsData[Vendor ID],H10)) -> 1 | P10: =IF(H10="","",COUNTIFS(TransactionsData[Vendor ID],H10,TransactionsData[Selected],1)) -> 15 | Q10: =IF(OR(H10="",P10=0),"",COUNTIFS(VendorGroups[Source net],">"&M10,VendorGroups[Source actions],">0")+COUNTIFS(VendorGroups[Source net],M10,VendorGroups[Record ID],"<"&H10,VendorGroups[Source actions],">0")+1) -> 1 | R10: =IF(H10="",IF(COUNTA(I10:K10)>0,"Missing record ID",""),IF(COUNTIFS(VendorGroups[Record ID],H10)<>1,"Duplicate record ID",IF(I10="","Add name","")))
A11: =IF(Trends!$B$6<>"","",IF(COUNTIFS(VendorGroups[Source rank],4)=1,4,"")) -> 4 | B11: =IF(Trends!$B$6<>"","",IF(COUNTIFS(VendorGroups[Source rank],4)=1,IF(INDEX(VendorGroups[Source URL],MATCH(4,VendorGroups[Source rank],0))="",INDEX(VendorGroups[Source name],MATCH(4,VendorGroups[Source rank],0)),HYPERLINK(INDEX(VendorGroups[Source URL],MATCH(4,VendorGroups[Source rank],0)),INDEX(VendorGroups[Source name],MATCH(4,VendorGroups[Source rank],0)))),"")) -> Spatial Front Inc. | C11: =IF(Trends!$B$6<>"","",IF(COUNTIFS(VendorGroups[Source rank],4)=1,IF(INDEX(VendorGroups[Source UEI],MATCH(4,VendorGroups[Source rank],0))="","Not supplied",INDEX(VendorGroups[Source UEI],MATCH(4,VendorGroups[Source rank],0))),"")) -> J1ADW6BL8MN5 | D11: =IF(Trends!$B$6<>"","",IF(COUNTIFS(VendorGroups[Source rank],4)=1,INDEX(VendorGroups[Source net],MATCH(4,VendorGroups[Source rank],0)),"")) -> 8845386 | E11: =IF(Trends!$B$6<>"","",IF(COUNTIFS(VendorGroups[Source rank],4)=1,INDEX(VendorGroups[Source deobligations],MATCH(4,VendorGroups[Source rank],0)),"")) -> -1096141.6 | F11: =IF(Trends!$B$6<>"","",IF(COUNTIFS(VendorGroups[Source rank],4)=1,INDEX(VendorGroups[Source awards],MATCH(4,VendorGroups[Source rank],0)),"")) -> 9 | G11: =IF(Trends!$B$6<>"","",IF(COUNTIFS(VendorGroups[Source rank],4)=1,INDEX(VendorGroups[Source actions],MATCH(4,VendorGroups[Source rank],0)),"")) -> 29 | H11: eU9TbVJvdFJnc1dJL2U5YUVPc2JCZz09 | I11: Civicactions, Inc. | J11: XSZFHRS5QFL5 | K11: https://govtribe.com/vendors/civicactions-inc-dot-65fk1 | L11: =IF(H11="","",I11&IF(J11="",""," ["&J11&"]")) -> Civicactions, Inc. [XSZFHRS5QFL5] | M11: =IF(H11="","",SUMIFS(TransactionsData[Obligations],TransactionsData[Vendor ID],H11,TransactionsData[Selected],1)) -> 10769110 | N11: =IF(H11="","",SUMIFS(TransactionsData[Deobligations],TransactionsData[Vendor ID],H11,TransactionsData[Selected],1)) -> -561.71 | O11: =IF(H11="","",SUMIFS(TransactionsData[First vendor award],TransactionsData[Vendor ID],H11)) -> 1 | P11: =IF(H11="","",COUNTIFS(TransactionsData[Vendor ID],H11,TransactionsData[Selected],1)) -> 10 | Q11: =IF(OR(H11="",P11=0),"",COUNTIFS(VendorGroups[Source net],">"&M11,VendorGroups[Source actions],">0")+COUNTIFS(VendorGroups[Source net],M11,VendorGroups[Record ID],"<"&H11,VendorGroups[Source actions],">0")+1) -> 3 | R11: =IF(H11="",IF(COUNTA(I11:K11)>0,"Missing record ID",""),IF(COUNTIFS(VendorGroups[Record ID],H11)<>1,"Duplicate record ID",IF(I11="","Add name","")))
A12: =IF(Trends!$B$6<>"","",IF(COUNTIFS(VendorGroups[Source rank],5)=1,5,"")) -> 5 | B12: =IF(Trends!$B$6<>"","",IF(COUNTIFS(VendorGroups[Source rank],5)=1,IF(INDEX(VendorGroups[Source URL],MATCH(5,VendorGroups[Source rank],0))="",INDEX(VendorGroups[Source name],MATCH(5,VendorGroups[Source rank],0)),HYPERLINK(INDEX(VendorGroups[Source URL],MATCH(5,VendorGroups[Source rank],0)),INDEX(VendorGroups[Source name],MATCH(5,VendorGroups[Source rank],0)))),"")) -> Strategic Communications LLC | C12: =IF(Trends!$B$6<>"","",IF(COUNTIFS(VendorGroups[Source rank],5)=1,IF(INDEX(VendorGroups[Source UEI],MATCH(5,VendorGroups[Source rank],0))="","Not supplied",INDEX(VendorGroups[Source UEI],MATCH(5,VendorGroups[Source rank],0))),"")) -> LJZRP7SE5LN4 | D12: =IF(Trends!$B$6<>"","",IF(COUNTIFS(VendorGroups[Source rank],5)=1,INDEX(VendorGroups[Source net],MATCH(5,VendorGroups[Source rank],0)),"")) -> 7237302.7 | E12: =IF(Trends!$B$6<>"","",IF(COUNTIFS(VendorGroups[Source rank],5)=1,INDEX(VendorGroups[Source deobligations],MATCH(5,VendorGroups[Source rank],0)),"")) -> 0 | F12: =IF(Trends!$B$6<>"","",IF(COUNTIFS(VendorGroups[Source rank],5)=1,INDEX(VendorGroups[Source awards],MATCH(5,VendorGroups[Source rank],0)),"")) -> 1 | G12: =IF(Trends!$B$6<>"","",IF(COUNTIFS(VendorGroups[Source rank],5)=1,INDEX(VendorGroups[Source actions],MATCH(5,VendorGroups[Source rank],0)),"")) -> 4 | H12: OWJtcjhIZU41SjlrOFJKOTI3MHE5QT09 | I12: Criterion Systems, L.L.C. | J12: MPGNDNHHWM33 | K12: https://govtribe.com/vendors/criterion-systems-inc-dot-8aep0 | L12: =IF(H12="","",I12&IF(J12="",""," ["&J12&"]")) -> Criterion Systems, L.L.C. [MPGNDNHHWM33] | M12: =IF(H12="","",SUMIFS(TransactionsData[Obligations],TransactionsData[Vendor ID],H12,TransactionsData[Selected],1)) -> 5033264 | N12: =IF(H12="","",SUMIFS(TransactionsData[Deobligations],TransactionsData[Vendor ID],H12,TransactionsData[Selected],1)) -> 0 | O12: =IF(H12="","",SUMIFS(TransactionsData[First vendor award],TransactionsData[Vendor ID],H12)) -> 2 | P12: =IF(H12="","",COUNTIFS(TransactionsData[Vendor ID],H12,TransactionsData[Selected],1)) -> 6 | Q12: =IF(OR(H12="",P12=0),"",COUNTIFS(VendorGroups[Source net],">"&M12,VendorGroups[Source actions],">0")+COUNTIFS(VendorGroups[Source net],M12,VendorGroups[Record ID],"<"&H12,VendorGroups[Source actions],">0")+1) -> 6 | R12: =IF(H12="",IF(COUNTA(I12:K12)>0,"Missing record ID",""),IF(COUNTIFS(VendorGroups[Record ID],H12)<>1,"Duplicate record ID",IF(I12="","Add name","")))
A13: =IF(Trends!$B$6<>"","",IF(COUNTIFS(VendorGroups[Source rank],6)=1,6,"")) -> 6 | B13: =IF(Trends!$B$6<>"","",IF(COUNTIFS(VendorGroups[Source rank],6)=1,IF(INDEX(VendorGroups[Source URL],MATCH(6,VendorGroups[Source rank],0))="",INDEX(VendorGroups[Source name],MATCH(6,VendorGroups[Source rank],0)),HYPERLINK(INDEX(VendorGroups[Source URL],MATCH(6,VendorGroups[Source rank],0)),INDEX(VendorGroups[Source name],MATCH(6,VendorGroups[Source rank],0)))),"")) -> Criterion Systems, L.L.C. | C13: =IF(Trends!$B$6<>"","",IF(COUNTIFS(VendorGroups[Source rank],6)=1,IF(INDEX(VendorGroups[Source UEI],MATCH(6,VendorGroups[Source rank],0))="","Not supplied",INDEX(VendorGroups[Source UEI],MATCH(6,VendorGroups[Source rank],0))),"")) -> MPGNDNHHWM33 | D13: =IF(Trends!$B$6<>"","",IF(COUNTIFS(VendorGroups[Source rank],6)=1,INDEX(VendorGroups[Source net],MATCH(6,VendorGroups[Source rank],0)),"")) -> 5033264 | E13: =IF(Trends!$B$6<>"","",IF(COUNTIFS(VendorGroups[Source rank],6)=1,INDEX(VendorGroups[Source deobligations],MATCH(6,VendorGroups[Source rank],0)),"")) -> 0 | F13: =IF(Trends!$B$6<>"","",IF(COUNTIFS(VendorGroups[Source rank],6)=1,INDEX(VendorGroups[Source awards],MATCH(6,VendorGroups[Source rank],0)),"")) -> 2 | G13: =IF(Trends!$B$6<>"","",IF(COUNTIFS(VendorGroups[Source rank],6)=1,INDEX(VendorGroups[Source actions],MATCH(6,VendorGroups[Source rank],0)),"")) -> 6 | H13: V0s3QTJhcWZOS0lyMkJLVzE4Y2tTdz09 | I13: Directviz Solutions, LLC | J13: YXH4AGD2LGF5 | K13: https://govtribe.com/vendors/directviz-solutions-llc-6evd4 | L13: =IF(H13="","",I13&IF(J13="",""," ["&J13&"]")) -> Directviz Solutions, LLC [YXH4AGD2LGF5] | M13: =IF(H13="","",SUMIFS(TransactionsData[Obligations],TransactionsData[Vendor ID],H13,TransactionsData[Selected],1)) -> 22532734 | N13: =IF(H13="","",SUMIFS(TransactionsData[Deobligations],TransactionsData[Vendor ID],H13,TransactionsData[Selected],1)) -> 0 | O13: =IF(H13="","",SUMIFS(TransactionsData[First vendor award],TransactionsData[Vendor ID],H13)) -> 5 | P13: =IF(H13="","",COUNTIFS(TransactionsData[Vendor ID],H13,TransactionsData[Selected],1)) -> 11 | Q13: =IF(OR(H13="",P13=0),"",COUNTIFS(VendorGroups[Source net],">"&M13,VendorGroups[Source actions],">0")+COUNTIFS(VendorGroups[Source net],M13,VendorGroups[Record ID],"<"&H13,VendorGroups[Source actions],">0")+1) -> 2 | R13: =IF(H13="",IF(COUNTA(I13:K13)>0,"Missing record ID",""),IF(COUNTIFS(VendorGroups[Record ID],H13)<>1,"Duplicate record ID",IF(I13="","Add name","")))
A14: =IF(Trends!$B$6<>"","",IF(COUNTIFS(VendorGroups[Source rank],7)=1,7,"")) -> 7 | B14: =IF(Trends!$B$6<>"","",IF(COUNTIFS(VendorGroups[Source rank],7)=1,IF(INDEX(VendorGroups[Source URL],MATCH(7,VendorGroups[Source rank],0))="",INDEX(VendorGroups[Source name],MATCH(7,VendorGroups[Source rank],0)),HYPERLINK(INDEX(VendorGroups[Source URL],MATCH(7,VendorGroups[Source rank],0)),INDEX(VendorGroups[Source name],MATCH(7,VendorGroups[Source rank],0)))),"")) -> Anika Systems Incorporated | C14: =IF(Trends!$B$6<>"","",IF(COUNTIFS(VendorGroups[Source rank],7)=1,IF(INDEX(VendorGroups[Source UEI],MATCH(7,VendorGroups[Source rank],0))="","Not supplied",INDEX(VendorGroups[Source UEI],MATCH(7,VendorGroups[Source rank],0))),"")) -> Y9V7J5VN9F68 | D14: =IF(Trends!$B$6<>"","",IF(COUNTIFS(VendorGroups[Source rank],7)=1,INDEX(VendorGroups[Source net],MATCH(7,VendorGroups[Source rank],0)),"")) -> 4954939.8 | E14: =IF(Trends!$B$6<>"","",IF(COUNTIFS(VendorGroups[Source rank],7)=1,INDEX(VendorGroups[Source deobligations],MATCH(7,VendorGroups[Source rank],0)),"")) -> 0 | F14: =IF(Trends!$B$6<>"","",IF(COUNTIFS(VendorGroups[Source rank],7)=1,INDEX(VendorGroups[Source awards],MATCH(7,VendorGroups[Source rank],0)),"")) -> 1 | G14: =IF(Trends!$B$6<>"","",IF(COUNTIFS(VendorGroups[Source rank],7)=1,INDEX(VendorGroups[Source actions],MATCH(7,VendorGroups[Source rank],0)),"")) -> 4 | H14: cFNFdDdxT05JcUJjUW92YlRySEh2dz09 | I14: Expediteinfotech, Inc. | J14: KX6EDEAPTKH5 | K14: https://govtribe.com/vendors/expediteinfotech-inc-dot-78dz9 | L14: =IF(H14="","",I14&IF(J14="",""," ["&J14&"]")) -> Expediteinfotech, Inc. [KX6EDEAPTKH5] | M14: =IF(H14="","",SUMIFS(TransactionsData[Obligations],TransactionsData[Vendor ID],H14,TransactionsData[Selected],1)) -> 150188.63 | N14: =IF(H14="","",SUMIFS(TransactionsData[Deobligations],TransactionsData[Vendor ID],H14,TransactionsData[Selected],1)) -> -77859 | O14: =IF(H14="","",SUMIFS(TransactionsData[First vendor award],TransactionsData[Vendor ID],H14)) -> 1 | P14: =IF(H14="","",COUNTIFS(TransactionsData[Vendor ID],H14,TransactionsData[Selected],1)) -> 3 | Q14: =IF(OR(H14="",P14=0),"",COUNTIFS(VendorGroups[Source net],">"&M14,VendorGroups[Source actions],">0")+COUNTIFS(VendorGroups[Source net],M14,VendorGroups[Record ID],"<"&H14,VendorGroups[Source actions],">0")+1) -> 15 | R14: =IF(H14="",IF(COUNTA(I14:K14)>0,"Missing record ID",""),IF(COUNTIFS(VendorGroups[Record ID],H14)<>1,"Duplicate record ID",IF(I14="","Add name","")))
A15: =IF(Trends!$B$6<>"","",IF(COUNTIFS(VendorGroups[Source rank],8)=1,8,"")) -> 8 | B15: =IF(Trends!$B$6<>"","",IF(COUNTIFS(VendorGroups[Source rank],8)=1,IF(INDEX(VendorGroups[Source URL],MATCH(8,VendorGroups[Source rank],0))="",INDEX(VendorGroups[Source name],MATCH(8,VendorGroups[Source rank],0)),HYPERLINK(INDEX(VendorGroups[Source URL],MATCH(8,VendorGroups[Source rank],0)),INDEX(VendorGroups[Source name],MATCH(8,VendorGroups[Source rank],0)))),"")) -> Lynker Corporation | C15: =IF(Trends!$B$6<>"","",IF(COUNTIFS(VendorGroups[Source rank],8)=1,IF(INDEX(VendorGroups[Source UEI],MATCH(8,VendorGroups[Source rank],0))="","Not supplied",INDEX(VendorGroups[Source UEI],MATCH(8,VendorGroups[Source rank],0))),"")) -> MCLPKDBCDKY7 | D15: =IF(Trends!$B$6<>"","",IF(COUNTIFS(VendorGroups[Source rank],8)=1,INDEX(VendorGroups[Source net],MATCH(8,VendorGroups[Source rank],0)),"")) -> 2603796 | E15: =IF(Trends!$B$6<>"","",IF(COUNTIFS(VendorGroups[Source rank],8)=1,INDEX(VendorGroups[Source deobligations],MATCH(8,VendorGroups[Source rank],0)),"")) -> 0 | F15: =IF(Trends!$B$6<>"","",IF(COUNTIFS(VendorGroups[Source rank],8)=1,INDEX(VendorGroups[Source awards],MATCH(8,VendorGroups[Source rank],0)),"")) -> 1 | G15: =IF(Trends!$B$6<>"","",IF(COUNTIFS(VendorGroups[Source rank],8)=1,INDEX(VendorGroups[Source actions],MATCH(8,VendorGroups[Source rank],0)),"")) -> 2 | H15: VlgvSWowSTJ2WlBTdlBXd2pxTFhBdz09 | I15: Gartner, Inc. | J15: CFALLJBGZ697 | K15: https://govtribe.com/vendors/gartner-inc-dot-0efu3 | L15: =IF(H15="","",I15&IF(J15="",""," ["&J15&"]")) -> Gartner, Inc. [CFALLJBGZ697] | M15: =IF(H15="","",SUMIFS(TransactionsData[Obligations],TransactionsData[Vendor ID],H15,TransactionsData[Selected],1)) -> 589968 | N15: =IF(H15="","",SUMIFS(TransactionsData[Deobligations],TransactionsData[Vendor ID],H15,TransactionsData[Selected],1)) -> 0 | O15: =IF(H15="","",SUMIFS(TransactionsData[First vendor award],TransactionsData[Vendor ID],H15)) -> 1 | P15: =IF(H15="","",COUNTIFS(TransactionsData[Vendor ID],H15,TransactionsData[Selected],1)) -> 3 | Q15: =IF(OR(H15="",P15=0),"",COUNTIFS(VendorGroups[Source net],">"&M15,VendorGroups[Source actions],">0")+COUNTIFS(VendorGroups[Source net],M15,VendorGroups[Record ID],"<"&H15,VendorGroups[Source actions],">0")+1) -> 12 | R15: =IF(H15="",IF(COUNTA(I15:K15)>0,"Missing record ID",""),IF(COUNTIFS(VendorGroups[Record ID],H15)<>1,"Duplicate record ID",IF(I15="","Add name","")))
A16: =IF(Trends!$B$6<>"","",IF(COUNTIFS(VendorGroups[Source rank],9)=1,9,"")) -> 9 | B16: =IF(Trends!$B$6<>"","",IF(COUNTIFS(VendorGroups[Source rank],9)=1,IF(INDEX(VendorGroups[Source URL],MATCH(9,VendorGroups[Source rank],0))="",INDEX(VendorGroups[Source name],MATCH(9,VendorGroups[Source rank],0)),HYPERLINK(INDEX(VendorGroups[Source URL],MATCH(9,VendorGroups[Source rank],0)),INDEX(VendorGroups[Source name],MATCH(9,VendorGroups[Source rank],0)))),"")) -> Rei Systems, Inc. | C16: =IF(Trends!$B$6<>"","",IF(COUNTIFS(VendorGroups[Source rank],9)=1,IF(INDEX(VendorGroups[Source UEI],MATCH(9,VendorGroups[Source rank],0))="","Not supplied",INDEX(VendorGroups[Source UEI],MATCH(9,VendorGroups[Source rank],0))),"")) -> YRNMVN96JC17 | D16: =IF(Trends!$B$6<>"","",IF(COUNTIFS(VendorGroups[Source rank],9)=1,INDEX(VendorGroups[Source net],MATCH(9,VendorGroups[Source rank],0)),"")) -> 1899378.1 | E16: =IF(Trends!$B$6<>"","",IF(COUNTIFS(VendorGroups[Source rank],9)=1,INDEX(VendorGroups[Source deobligations],MATCH(9,VendorGroups[Source rank],0)),"")) -> 0 | F16: =IF(Trends!$B$6<>"","",IF(COUNTIFS(VendorGroups[Source rank],9)=1,INDEX(VendorGroups[Source awards],MATCH(9,VendorGroups[Source rank],0)),"")) -> 2 | G16: =IF(Trends!$B$6<>"","",IF(COUNTIFS(VendorGroups[Source rank],9)=1,INDEX(VendorGroups[Source actions],MATCH(9,VendorGroups[Source rank],0)),"")) -> 5 | H16: c1krbWRVbVB4cEpvMEV4WEt5b05wdz09 | I16: GBS Dakota IT, LLC | J16: G9E9BR9MG9N7 | K16: https://govtribe.com/vendors/gbs-dakota-it-llc-8ph94 | L16: =IF(H16="","",I16&IF(J16="",""," ["&J16&"]")) -> GBS Dakota IT, LLC [G9E9BR9MG9N7] | M16: =IF(H16="","",SUMIFS(TransactionsData[Obligations],TransactionsData[Vendor ID],H16,TransactionsData[Selected],1)) -> 16430.4 | N16: =IF(H16="","",SUMIFS(TransactionsData[Deobligations],TransactionsData[Vendor ID],H16,TransactionsData[Selected],1)) -> 0 | O16: =IF(H16="","",SUMIFS(TransactionsData[First vendor award],TransactionsData[Vendor ID],H16)) -> 1 | P16: =IF(H16="","",COUNTIFS(TransactionsData[Vendor ID],H16,TransactionsData[Selected],1)) -> 1 | Q16: =IF(OR(H16="",P16=0),"",COUNTIFS(VendorGroups[Source net],">"&M16,VendorGroups[Source actions],">0")+COUNTIFS(VendorGroups[Source net],M16,VendorGroups[Record ID],"<"&H16,VendorGroups[Source actions],">0")+1) -> 18 | R16: =IF(H16="",IF(COUNTA(I16:K16)>0,"Missing record ID",""),IF(COUNTIFS(VendorGroups[Record ID],H16)<>1,"Duplicate record ID",IF(I16="","Add name","")))
A17: =IF(Trends!$B$6<>"","",IF(COUNTIFS(VendorGroups[Source rank],10)=1,10,"")) -> 10 | B17: =IF(Trends!$B$6<>"","",IF(COUNTIFS(VendorGroups[Source rank],10)=1,IF(INDEX(VendorGroups[Source URL],MATCH(10,VendorGroups[Source rank],0))="",INDEX(VendorGroups[Source name],MATCH(10,VendorGroups[Source rank],0)),HYPERLINK(INDEX(VendorGroups[Source URL],MATCH(10,VendorGroups[Source rank],0)),INDEX(VendorGroups[Source name],MATCH(10,VendorGroups[Source rank],0)))),"")) -> Montage + Magnum, LLC | C17: =IF(Trends!$B$6<>"","",IF(COUNTIFS(VendorGroups[Source rank],10)=1,IF(INDEX(VendorGroups[Source UEI],MATCH(10,VendorGroups[Source rank],0))="","Not supplied",INDEX(VendorGroups[Source UEI],MATCH(10,VendorGroups[Source rank],0))),"")) -> XLJSS2NNHU27 | D17: =IF(Trends!$B$6<>"","",IF(COUNTIFS(VendorGroups[Source rank],10)=1,INDEX(VendorGroups[Source net],MATCH(10,VendorGroups[Source rank],0)),"")) -> 840658.87 | E17: =IF(Trends!$B$6<>"","",IF(COUNTIFS(VendorGroups[Source rank],10)=1,INDEX(VendorGroups[Source deobligations],MATCH(10,VendorGroups[Source rank],0)),"")) -> 0 | F17: =IF(Trends!$B$6<>"","",IF(COUNTIFS(VendorGroups[Source rank],10)=1,INDEX(VendorGroups[Source awards],MATCH(10,VendorGroups[Source rank],0)),"")) -> 1 | G17: =IF(Trends!$B$6<>"","",IF(COUNTIFS(VendorGroups[Source rank],10)=1,INDEX(VendorGroups[Source actions],MATCH(10,VendorGroups[Source rank],0)),"")) -> 3 | H17: ejJEYUJ0cDdrQzV5VHVFMGc5bG9oQT09 | I17: GBS Solutions Corp | J17: NKNSTJBPABX9 | K17: https://govtribe.com/vendors/gbs-solutions-corporation-gbs-79pq1 | L17: =IF(H17="","",I17&IF(J17="",""," ["&J17&"]")) -> GBS Solutions Corp [NKNSTJBPABX9] | M17: =IF(H17="","",SUMIFS(TransactionsData[Obligations],TransactionsData[Vendor ID],H17,TransactionsData[Selected],1)) -> 61759.48 | N17: =IF(H17="","",SUMIFS(TransactionsData[Deobligations],TransactionsData[Vendor ID],H17,TransactionsData[Selected],1)) -> -112336.2 | O17: =IF(H17="","",SUMIFS(TransactionsData[First vendor award],TransactionsData[Vendor ID],H17)) -> 2 | P17: =IF(H17="","",COUNTIFS(TransactionsData[Vendor ID],H17,TransactionsData[Selected],1)) -> 4 | Q17: =IF(OR(H17="",P17=0),"",COUNTIFS(VendorGroups[Source net],">"&M17,VendorGroups[Source actions],">0")+COUNTIFS(VendorGroups[Source net],M17,VendorGroups[Record ID],"<"&H17,VendorGroups[Source actions],">0")+1) -> 16 | R17: =IF(H17="",IF(COUNTA(I17:K17)>0,"Missing record ID",""),IF(COUNTIFS(VendorGroups[Record ID],H17)<>1,"Duplicate record ID",IF(I17="","Add name","")))
