Workbook

Sheet Summary
C2: Labor pricing & staffing
C4: Scenario | D4: =Assumptions!$D$4 -> Base | E4: GovTribe, Inc. · UEI EDJBUPNLCCL5
C7: Buyer | D7: =IF('Source Data'!D6="","",'Source Data'!D6) -> Federal Enterprise Finance Office
C8: Project | D8: =IF('Source Data'!D7="","",'Source Data'!D7) -> Financial Oversight and Program Support
C9: Solicitation | D9: =IF('Source Data'!D8="","",'Source Data'!D8) -> DEMO-LABOR-001
C10: Location | D10: =IF('Source Data'!D9="","",'Source Data'!D9) -> Washington, DC
C11: As of | D11: =IF('Source Data'!D10="","",'Source Data'!D10) -> 46276
C13: GovTribe’s identity is real; scenario assumptions and past performance are illustrative. Fictional buyer.
C16: Period | D16: Pricing hours | E16: Est. positions | F16: Paid FTE | G16: Price | H16: Modeled cost | I16: Profit
C17: Base | D17: =IF(Pricing!E16="","",Pricing!E16) -> 16640 | E17: =IF(COUNT('Source Data'!E21:E26)<6,"",SUM('Source Data'!E21:E26)) -> 8 | F17: =IF(COUNT(Staffing!D13,Staffing!D25,Staffing!D37,Staffing!D49,Staffing!D61,Staffing!D73)<6,"",SUM(Staffing!D13,Staffing!D25,Staffing!D37,Staffing!D49,Staffing!D61,Staffing!D73)) -> 9.0434783 | G17: =IF(Pricing!G16="","",Pricing!G16) -> 1771701.8 | H17: =IF(Pricing!H16="","",Pricing!H16) -> 1610637.9 | I17: =IF(Pricing!I16="","",Pricing!I16) -> 161063.85
C18: Option 1 | D18: =IF(Pricing!E27="","",Pricing!E27) -> 16640 | E18: =IF(COUNT('Source Data'!E21:E26)<6,"",SUM('Source Data'!E21:E26)) -> 8 | F18: =IF(COUNT(Staffing!E13,Staffing!E25,Staffing!E37,Staffing!E49,Staffing!E61,Staffing!E73)<6,"",SUM(Staffing!E13,Staffing!E25,Staffing!E37,Staffing!E49,Staffing!E61,Staffing!E73)) -> 9.0434783 | G18: =IF(Pricing!G27="","",Pricing!G27) -> 1824852.6 | H18: =IF(Pricing!H27="","",Pricing!H27) -> 1658957.1 | I18: =IF(Pricing!I27="","",Pricing!I27) -> 165895.58
C19: Option 2 | D19: =IF(Pricing!E38="","",Pricing!E38) -> 16640 | E19: =IF(COUNT('Source Data'!E21:E26)<6,"",SUM('Source Data'!E21:E26)) -> 8 | F19: =IF(COUNT(Staffing!F13,Staffing!F25,Staffing!F37,Staffing!F49,Staffing!F61,Staffing!F73)<6,"",SUM(Staffing!F13,Staffing!F25,Staffing!F37,Staffing!F49,Staffing!F61,Staffing!F73)) -> 9.0434783 | G19: =IF(Pricing!G38="","",Pricing!G38) -> 1879598.4 | H19: =IF(Pricing!H38="","",Pricing!H38) -> 1708725.8 | I19: =IF(Pricing!I38="","",Pricing!I38) -> 170872.67
C20: Option 3 | D20: =IF(Pricing!E49="","",Pricing!E49) -> 16640 | E20: =IF(COUNT('Source Data'!E21:E26)<6,"",SUM('Source Data'!E21:E26)) -> 8 | F20: =IF(COUNT(Staffing!G13,Staffing!G25,Staffing!G37,Staffing!G49,Staffing!G61,Staffing!G73)<6,"",SUM(Staffing!G13,Staffing!G25,Staffing!G37,Staffing!G49,Staffing!G61,Staffing!G73)) -> 9.0434783 | G20: =IF(Pricing!G49="","",Pricing!G49) -> 1935986.4 | H20: =IF(Pricing!H49="","",Pricing!H49) -> 1759987.5 | I20: =IF(Pricing!I49="","",Pricing!I49) -> 175998.88
C21: Option 4 | D21: =IF(Pricing!E60="","",Pricing!E60) -> 16640 | E21: =IF(COUNT('Source Data'!E21:E26)<6,"",SUM('Source Data'!E21:E26)) -> 8 | F21: =IF(COUNT(Staffing!H13,Staffing!H25,Staffing!H37,Staffing!H49,Staffing!H61,Staffing!H73)<6,"",SUM(Staffing!H13,Staffing!H25,Staffing!H37,Staffing!H49,Staffing!H61,Staffing!H73)) -> 9.0434783 | G21: =IF(Pricing!G60="","",Pricing!G60) -> 1994065.8 | H21: =IF(Pricing!H60="","",Pricing!H60) -> 1812787.2 | I21: =IF(Pricing!I60="","",Pricing!I60) -> 181278.67
C22: Extension | D22: =IF(Pricing!E71="","",Pricing!E71) -> 8320 | E22: =IF(COUNT('Source Data'!E21:E26)<6,"",SUM('Source Data'!E21:E26)) -> 8 | F22: =IF(COUNT(Staffing!I13,Staffing!I25,Staffing!I37,Staffing!I49,Staffing!I61,Staffing!I73)<6,"",SUM(Staffing!I13,Staffing!I25,Staffing!I37,Staffing!I49,Staffing!I61,Staffing!I73)) -> 9.0434783 | G22: =IF(Pricing!G71="","",Pricing!G71) -> 997032.92 | H22: =IF(Pricing!H71="","",Pricing!H71) -> 906393.59 | I22: =IF(Pricing!I71="","",Pricing!I71) -> 90639.33
C24: Five-year total | D24: =IF(COUNT(D17:D21)<5,"",SUM(D17:D21)) -> 83200 | G24: =IF(COUNT(G17:G21)<5,"",SUM(G17:G21)) -> 9406205.1 | H24: =IF(COUNT(H17:H21)<5,"n.a.",SUM(H17:H21)) -> 8551095.5 | I24: =IF(COUNT(I17:I21)<5,"n.a.",SUM(I17:I21)) -> 855109.65
C25: Extension — separate | D25: =IF(D22="","",D22) -> 8320 | G25: =IF(G22="","",G22) -> 997032.92 | H25: =IF(H22="","",H22) -> 906393.59 | I25: =IF(I22="","",I22) -> 90639.33
C28: Model status | D28: =IF(OR('Source Data'!D6="",'Source Data'!D7="",'Source Data'!D8="",'Source Data'!D9="",NOT(ISNUMBER('Source Data'!D10))),"Complete the project inputs",IF(COUNT(Assumptions!D19:I19)<6,"Check period dates in Source Data",IF(SUM(IF('Labor Rates'!D27="Staffing shortfall",1,0),IF('Labor Rates'!E27="Staffing shortfall",1,0),IF('Labor Rates'!F27="Staffing shortfall",1,0),IF('Labor Rates'!G27="Staffing shortfall",1,0),IF('Labor Rates'!H27="Staffing shortfall",1,0),IF('Labor Rates'!I27="Staffing shortfall",1,0),IF('Labor Rates'!D50="Staffing shortfall",1,0),IF('Labor Rates'!E50="Staffing shortfall",1,0),IF('Labor Rates'!F50="Staffing shortfall",1,0),IF('Labor Rates'!G50="Staffing shortfall",1,0),IF('Labor Rates'!H50="Staffing shortfall",1,0),IF('Labor Rates'!I50="Staffing shortfall",1,0),IF('Labor Rates'!D73="Staffing shortfall",1,0),IF('Labor Rates'!E73="Staffing shortfall",1,0),IF('Labor Rates'!F73="Staffing shortfall",1,0),IF('Labor Rates'!G73="Staffing shortfall",1,0),IF('Labor Rates'!H73="Staffing shortfall",1,0),IF('Labor Rates'!I73="Staffing shortfall",1,0),IF('Labor Rates'!D96="Staffing shortfall",1,0),IF('Labor Rates'!E96="Staffing shortfall",1,0),IF('Labor Rates'!F96="Staffing shortfall",1,0),IF('Labor Rates'!G96="Staffing shortfall",1,0),IF('Labor Rates'!H96="Staffing shortfall",1,0),IF('Labor Rates'!I96="Staffing shortfall",1,0),IF('Labor Rates'!D119="Staffing shortfall",1,0),IF('Labor Rates'!E119="Staffing shortfall",1,0),IF('Labor Rates'!F119="Staffing shortfall",1,0),IF('Labor Rates'!G119="Staffing shortfall",1,0),IF('Labor Rates'!H119="Staffing shortfall",1,0),IF('Labor Rates'!I119="Staffing shortfall",1,0),IF('Labor Rates'!D142="Staffing shortfall",1,0),IF('Labor Rates'!E142="Staffing shortfall",1,0),IF('Labor Rates'!F142="Staffing shortfall",1,0),IF('Labor Rates'!G142="Staffing shortfall",1,0),IF('Labor Rates'!H142="Staffing shortfall",1,0),IF('Labor Rates'!I142="Staffing shortfall",1,0))>0,"Staffing shortfall — review Staffing",IF(SUM(IF(OR('Labor Rates'!D27="Complete",'Labor Rates'!D27="Zero hours"),0,1),IF(OR('Labor Rates'!E27="Complete",'Labor Rates'!E27="Zero hours"),0,1),IF(OR('Labor Rates'!F27="Complete",'Labor Rates'!F27="Zero hours"),0,1),IF(OR('Labor Rates'!G27="Complete",'Labor Rates'!G27="Zero hours"),0,1),IF(OR('Labor Rates'!H27="Complete",'Labor Rates'!H27="Zero hours"),0,1),IF(OR('Labor Rates'!I27="Complete",'Labor Rates'!I27="Zero hours"),0,1),IF(OR('Labor Rates'!D50="Complete",'Labor Rates'!D50="Zero hours"),0,1),IF(OR('Labor Rates'!E50="Complete",'Labor Rates'!E50="Zero hours"),0,1),IF(OR('Labor Rates'!F50="Complete",'Labor Rates'!F50="Zero hours"),0,1),IF(OR('Labor Rates'!G50="Complete",'Labor Rates'!G50="Zero hours"),0,1),IF(OR('Labor Rates'!H50="Complete",'Labor Rates'!H50="Zero hours"),0,1),IF(OR('Labor Rates'!I50="Complete",'Labor Rates'!I50="Zero hours"),0,1),IF(OR('Labor Rates'!D73="Complete",'Labor Rates'!D73="Zero hours"),0,1),IF(OR('Labor Rates'!E73="Complete",'Labor Rates'!E73="Zero hours"),0,1),IF(OR('Labor Rates'!F73="Complete",'Labor Rates'!F73="Zero hours"),0,1),IF(OR('Labor Rates'!G73="Complete",'Labor Rates'!G73="Zero hours"),0,1),IF(OR('Labor Rates'!H73="Complete",'Labor Rates'!H73="Zero hours"),0,1),IF(OR('Labor Rates'!I73="Complete",'Labor Rates'!I73="Zero hours"),0,1),IF(OR('Labor Rates'!D96="Complete",'Labor Rates'!D96="Zero hours"),0,1),IF(OR('Labor Rates'!E96="Complete",'Labor Rates'!E96="Zero hours"),0,1),IF(OR('Labor Rates'!F96="Complete",'Labor Rates'!F96="Zero hours"),0,1),IF(OR('Labor Rates'!G96="Complete",'Labor Rates'!G96="Zero hours"),0,1),IF(OR('Labor Rates'!H96="Complete",'Labor Rates'!H96="Zero hours"),0,1),IF(OR('Labor Rates'!I96="Complete",'Labor Rates'!I96="Zero hours"),0,1),IF(OR('Labor Rates'!D119="Complete",'Labor Rates'!D119="Zero hours"),0,1),IF(OR('Labor Rates'!E119="Complete",'Labor Rates'!E119="Zero hours"),0,1),IF(OR('Labor Rates'!F119="Complete",'Labor Rates'!F119="Zero hours"),0,1),IF(OR('Labor Rates'!G119="Complete",'Labor Rates'!G119="Zero hours"),0,1),IF(OR('Labor Rates'!H119="Complete",'Labor Rates'!H119="Zero hours"),0,1),IF(OR('Labor Rates'!I119="Complete",'Labor Rates'!I119="Zero hours"),0,1),IF(OR('Labor Rates'!D142="Complete",'Labor Rates'!D142="Zero hours"),0,1),IF(OR('Labor Rates'!E142="Complete",'Labor Rates'!E142="Zero hours"),0,1),IF(OR('Labor Rates'!F142="Complete",'Labor Rates'!F142="Zero hours"),0,1),IF(OR('Labor Rates'!G142="Complete",'Labor Rates'!G142="Zero hours"),0,1),IF(OR('Labor Rates'!H142="Complete",'Labor Rates'!H142="Zero hours"),0,1),IF(OR('Labor Rates'!I142="Complete",'Labor Rates'!I142="Zero hours"),0,1))>0,"Missing or invalid inputs — review detail","Calculated")))) -> Calculated
C30: Paid FTE includes capacity for nonbillable time; it is not a count of named people. Prices use requested hours and do not represent guaranteed orders.
C32: Edit amber inputs in Source Data and Assumptions. Use Staffing for FTE overrides and Labor Rates for period-rate overrides.
C34: Input key: blue = editable input; black = calculation; green = linked input. Missing values remain incomplete; n.a. means cost or profit is unavailable.

Sheet Assumptions
C2: Assumptions
C4: Scenario | D4: Base
C7: Annual paid hours | D7: 2080
C8: Annual nonbillable hours | D8: 240
C9: Additional benefit / paid hour | D9: 0
C10: Profit or margin | D10: 0.1
C11: Profit calculation | D11: Profit on cost
C12: Nonbillable time includes paid leave; fringe excludes it. Management is included in indirect costs. Duration uses complete months plus actual-day fractions of the final month, with inclusive end dates.
D16: Base | E16: Option 1 | F16: Option 2 | G16: Option 3 | H16: Option 4 | I16: Extension
C17: Period starts | D17: =IF('Source Data'!D15="","",'Source Data'!D15) -> 46296 | E17: =IF('Source Data'!E15="","",'Source Data'!E15) -> 46661 | F17: =IF('Source Data'!F15="","",'Source Data'!F15) -> 47027 | G17: =IF('Source Data'!G15="","",'Source Data'!G15) -> 47392 | H17: =IF('Source Data'!H15="","",'Source Data'!H15) -> 47757 | I17: =IF('Source Data'!I15="","",'Source Data'!I15) -> 48122
C18: Period ends | D18: =IF('Source Data'!D16="","",'Source Data'!D16) -> 46660 | E18: =IF('Source Data'!E16="","",'Source Data'!E16) -> 47026 | F18: =IF('Source Data'!F16="","",'Source Data'!F16) -> 47391 | G18: =IF('Source Data'!G16="","",'Source Data'!G16) -> 47756 | H18: =IF('Source Data'!H16="","",'Source Data'!H16) -> 48121 | I18: =IF('Source Data'!I16="","",'Source Data'!I16) -> 48304
C19: Years of staffing | D19: =IF(COUNT(D20:D21)<2,"",SUM(D20:D21)/12) -> 1 | E19: =IF(COUNT(E20:E21)<2,"",SUM(E20:E21)/12) -> 1 | F19: =IF(COUNT(F20:F21)<2,"",SUM(F20:F21)/12) -> 1 | G19: =IF(COUNT(G20:G21)<2,"",SUM(G20:G21)/12) -> 1 | H19: =IF(COUNT(H20:H21)<2,"",SUM(H20:H21)/12) -> 1 | I19: =IF(COUNT(I20:I21)<2,"",SUM(I20:I21)/12) -> 0.5
C20: Complete months | D20: =IF(COUNT(D17:D18)<2,"",IF(NOT(AND(D17>0,D18>=D17,D17=INT(D17),D18=INT(D18),D18<2958465)),"",(12*(YEAR(D18+1)-YEAR(D17))+MONTH(D18+1)-MONTH(D17))-IF(EDATE(D17,(12*(YEAR(D18+1)-YEAR(D17))+MONTH(D18+1)-MONTH(D17)))>D18+1,1,0))) -> 12 | E20: =IF(COUNT(E17:E18,D18)<3,"",IF(NOT(AND(E17>0,E18>=E17,E17=INT(E17),E18=INT(E18),E18<2958465,ISNUMBER(D18),E17=D18+1)),"",(12*(YEAR(E18+1)-YEAR(E17))+MONTH(E18+1)-MONTH(E17))-IF(EDATE(E17,(12*(YEAR(E18+1)-YEAR(E17))+MONTH(E18+1)-MONTH(E17)))>E18+1,1,0))) -> 12 | F20: =IF(COUNT(F17:F18,E18)<3,"",IF(NOT(AND(F17>0,F18>=F17,F17=INT(F17),F18=INT(F18),F18<2958465,ISNUMBER(E18),F17=E18+1)),"",(12*(YEAR(F18+1)-YEAR(F17))+MONTH(F18+1)-MONTH(F17))-IF(EDATE(F17,(12*(YEAR(F18+1)-YEAR(F17))+MONTH(F18+1)-MONTH(F17)))>F18+1,1,0))) -> 12 | G20: =IF(COUNT(G17:G18,F18)<3,"",IF(NOT(AND(G17>0,G18>=G17,G17=INT(G17),G18=INT(G18),G18<2958465,ISNUMBER(F18),G17=F18+1)),"",(12*(YEAR(G18+1)-YEAR(G17))+MONTH(G18+1)-MONTH(G17))-IF(EDATE(G17,(12*(YEAR(G18+1)-YEAR(G17))+MONTH(G18+1)-MONTH(G17)))>G18+1,1,0))) -> 12 | H20: =IF(COUNT(H17:H18,G18)<3,"",IF(NOT(AND(H17>0,H18>=H17,H17=INT(H17),H18=INT(H18),H18<2958465,ISNUMBER(G18),H17=G18+1)),"",(12*(YEAR(H18+1)-YEAR(H17))+MONTH(H18+1)-MONTH(H17))-IF(EDATE(H17,(12*(YEAR(H18+1)-YEAR(H17))+MONTH(H18+1)-MONTH(H17)))>H18+1,1,0))) -> 12 | I20: =IF(COUNT(I17:I18,H18)<3,"",IF(NOT(AND(I17>0,I18>=I17,I17=INT(I17),I18=INT(I18),I18<2958465,ISNUMBER(H18),I17=H18+1)),"",(12*(YEAR(I18+1)-YEAR(I17))+MONTH(I18+1)-MONTH(I17))-IF(EDATE(I17,(12*(YEAR(I18+1)-YEAR(I17))+MONTH(I18+1)-MONTH(I17)))>I18+1,1,0))) -> 6
C21: Partial month | D21: =IF(NOT(ISNUMBER(D20)),"",(D18+1-EDATE(D17,D20))/(EDATE(D17,D20+1)-EDATE(D17,D20))) -> 0 | E21: =IF(NOT(ISNUMBER(E20)),"",(E18+1-EDATE(E17,E20))/(EDATE(E17,E20+1)-EDATE(E17,E20))) -> 0 | F21: =IF(NOT(ISNUMBER(F20)),"",(F18+1-EDATE(F17,F20))/(EDATE(F17,F20+1)-EDATE(F17,F20))) -> 0 | G21: =IF(NOT(ISNUMBER(G20)),"",(G18+1-EDATE(G17,G20))/(EDATE(G17,G20+1)-EDATE(G17,G20))) -> 0 | H21: =IF(NOT(ISNUMBER(H20)),"",(H18+1-EDATE(H17,H20))/(EDATE(H17,H20+1)-EDATE(H17,H20))) -> 0 | I21: =IF(NOT(ISNUMBER(I20)),"",(I18+1-EDATE(I17,I20))/(EDATE(I17,I20+1)-EDATE(I17,I20))) -> 0
C22: Annual wage escalation — active | D22: =IF(ISNA(MATCH($D$4,$C$23:$C$25,0)),"",IF(INDEX(D23:D25,MATCH($D$4,$C$23:$C$25,0))="","",INDEX(D23:D25,MATCH($D$4,$C$23:$C$25,0)))) -> 0.03 | E22: =IF(ISNA(MATCH($D$4,$C$23:$C$25,0)),"",IF(INDEX(E23:E25,MATCH($D$4,$C$23:$C$25,0))="","",INDEX(E23:E25,MATCH($D$4,$C$23:$C$25,0)))) -> 0.03 | F22: =IF(ISNA(MATCH($D$4,$C$23:$C$25,0)),"",IF(INDEX(F23:F25,MATCH($D$4,$C$23:$C$25,0))="","",INDEX(F23:F25,MATCH($D$4,$C$23:$C$25,0)))) -> 0.03 | G22: =IF(ISNA(MATCH($D$4,$C$23:$C$25,0)),"",IF(INDEX(G23:G25,MATCH($D$4,$C$23:$C$25,0))="","",INDEX(G23:G25,MATCH($D$4,$C$23:$C$25,0)))) -> 0.03 | H22: =IF(ISNA(MATCH($D$4,$C$23:$C$25,0)),"",IF(INDEX(H23:H25,MATCH($D$4,$C$23:$C$25,0))="","",INDEX(H23:H25,MATCH($D$4,$C$23:$C$25,0)))) -> 0.03 | I22: =IF(H22="","",H22) -> 0.03
C23: Low | D23: 0.02 | E23: 0.02 | F23: 0.02 | G23: 0.02 | H23: 0.02 | I23: =IF(H23="","",H23) -> 0.02
C24: Base | D24: 0.03 | E24: 0.03 | F24: 0.03 | G24: 0.03 | H24: 0.03 | I24: =IF(H24="","",H24) -> 0.03
C25: High | D25: 0.04 | E25: 0.04 | F25: 0.04 | G25: 0.04 | H25: 0.04 | I25: =IF(H25="","",H25) -> 0.04
C28: Fringe, excluding paid leave — active | D28: =IF(ISNA(MATCH($D$4,$C$29:$C$31,0)),"",IF(INDEX(D29:D31,MATCH($D$4,$C$29:$C$31,0))="","",INDEX(D29:D31,MATCH($D$4,$C$29:$C$31,0)))) -> 0.25 | E28: =IF(ISNA(MATCH($D$4,$C$29:$C$31,0)),"",IF(INDEX(E29:E31,MATCH($D$4,$C$29:$C$31,0))="","",INDEX(E29:E31,MATCH($D$4,$C$29:$C$31,0)))) -> 0.25 | F28: =IF(ISNA(MATCH($D$4,$C$29:$C$31,0)),"",IF(INDEX(F29:F31,MATCH($D$4,$C$29:$C$31,0))="","",INDEX(F29:F31,MATCH($D$4,$C$29:$C$31,0)))) -> 0.25 | G28: =IF(ISNA(MATCH($D$4,$C$29:$C$31,0)),"",IF(INDEX(G29:G31,MATCH($D$4,$C$29:$C$31,0))="","",INDEX(G29:G31,MATCH($D$4,$C$29:$C$31,0)))) -> 0.25 | H28: =IF(ISNA(MATCH($D$4,$C$29:$C$31,0)),"",IF(INDEX(H29:H31,MATCH($D$4,$C$29:$C$31,0))="","",INDEX(H29:H31,MATCH($D$4,$C$29:$C$31,0)))) -> 0.25 | I28: =IF(H28="","",H28) -> 0.25
C29: Low | D29: 0.2 | E29: 0.2 | F29: 0.2 | G29: 0.2 | H29: 0.2 | I29: =IF(H29="","",H29) -> 0.2
C30: Base | D30: 0.25 | E30: 0.25 | F30: 0.25 | G30: 0.25 | H30: 0.25 | I30: =IF(H30="","",H30) -> 0.25
C31: High | D31: 0.3 | E31: 0.3 | F31: 0.3 | G31: 0.3 | H31: 0.3 | I31: =IF(H31="","",H31) -> 0.3
D33: Base | E33: Option 1 | F33: Option 2 | G33: Option 3 | H33: Option 4 | I33: Extension
C34: Overhead — active | D34: =IF(ISNA(MATCH($D$4,$C$35:$C$37,0)),"",IF(INDEX(D35:D37,MATCH($D$4,$C$35:$C$37,0))="","",INDEX(D35:D37,MATCH($D$4,$C$35:$C$37,0)))) -> 0.1 | E34: =IF(ISNA(MATCH($D$4,$C$35:$C$37,0)),"",IF(INDEX(E35:E37,MATCH($D$4,$C$35:$C$37,0))="","",INDEX(E35:E37,MATCH($D$4,$C$35:$C$37,0)))) -> 0.1 | F34: =IF(ISNA(MATCH($D$4,$C$35:$C$37,0)),"",IF(INDEX(F35:F37,MATCH($D$4,$C$35:$C$37,0))="","",INDEX(F35:F37,MATCH($D$4,$C$35:$C$37,0)))) -> 0.1 | G34: =IF(ISNA(MATCH($D$4,$C$35:$C$37,0)),"",IF(INDEX(G35:G37,MATCH($D$4,$C$35:$C$37,0))="","",INDEX(G35:G37,MATCH($D$4,$C$35:$C$37,0)))) -> 0.1 | H34: =IF(ISNA(MATCH($D$4,$C$35:$C$37,0)),"",IF(INDEX(H35:H37,MATCH($D$4,$C$35:$C$37,0))="","",INDEX(H35:H37,MATCH($D$4,$C$35:$C$37,0)))) -> 0.1 | I34: =IF(H34="","",H34) -> 0.1
C35: Low | D35: 0.08 | E35: 0.08 | F35: 0.08 | G35: 0.08 | H35: 0.08 | I35: =IF(H35="","",H35) -> 0.08
C36: Base | D36: 0.1 | E36: 0.1 | F36: 0.1 | G36: 0.1 | H36: 0.1 | I36: =IF(H36="","",H36) -> 0.1
C37: High | D37: 0.12 | E37: 0.12 | F37: 0.12 | G37: 0.12 | H37: 0.12 | I37: =IF(H37="","",H37) -> 0.12
C40: G&A — active | D40: =IF(ISNA(MATCH($D$4,$C$41:$C$43,0)),"",IF(INDEX(D41:D43,MATCH($D$4,$C$41:$C$43,0))="","",INDEX(D41:D43,MATCH($D$4,$C$41:$C$43,0)))) -> 0.1 | E40: =IF(ISNA(MATCH($D$4,$C$41:$C$43,0)),"",IF(INDEX(E41:E43,MATCH($D$4,$C$41:$C$43,0))="","",INDEX(E41:E43,MATCH($D$4,$C$41:$C$43,0)))) -> 0.1 | F40: =IF(ISNA(MATCH($D$4,$C$41:$C$43,0)),"",IF(INDEX(F41:F43,MATCH($D$4,$C$41:$C$43,0))="","",INDEX(F41:F43,MATCH($D$4,$C$41:$C$43,0)))) -> 0.1 | G40: =IF(ISNA(MATCH($D$4,$C$41:$C$43,0)),"",IF(INDEX(G41:G43,MATCH($D$4,$C$41:$C$43,0))="","",INDEX(G41:G43,MATCH($D$4,$C$41:$C$43,0)))) -> 0.1 | H40: =IF(ISNA(MATCH($D$4,$C$41:$C$43,0)),"",IF(INDEX(H41:H43,MATCH($D$4,$C$41:$C$43,0))="","",INDEX(H41:H43,MATCH($D$4,$C$41:$C$43,0)))) -> 0.1 | I40: =IF(H40="","",H40) -> 0.1
C41: Low | D41: 0.08 | E41: 0.08 | F41: 0.08 | G41: 0.08 | H41: 0.08 | I41: =IF(H41="","",H41) -> 0.08
C42: Base | D42: 0.1 | E42: 0.1 | F42: 0.1 | G42: 0.1 | H42: 0.1 | I42: =IF(H42="","",H42) -> 0.1
C43: High | D43: 0.12 | E43: 0.12 | F43: 0.12 | G43: 0.12 | H43: 0.12 | I43: =IF(H43="","",H43) -> 0.12
C46: Supplied-rate escalation — active | D46: =IF(ISNA(MATCH($D$4,$C$47:$C$49,0)),"",IF(INDEX(D47:D49,MATCH($D$4,$C$47:$C$49,0))="","",INDEX(D47:D49,MATCH($D$4,$C$47:$C$49,0)))) -> 0 | E46: =IF(ISNA(MATCH($D$4,$C$47:$C$49,0)),"",IF(INDEX(E47:E49,MATCH($D$4,$C$47:$C$49,0))="","",INDEX(E47:E49,MATCH($D$4,$C$47:$C$49,0)))) -> 0 | F46: =IF(ISNA(MATCH($D$4,$C$47:$C$49,0)),"",IF(INDEX(F47:F49,MATCH($D$4,$C$47:$C$49,0))="","",INDEX(F47:F49,MATCH($D$4,$C$47:$C$49,0)))) -> 0 | G46: =IF(ISNA(MATCH($D$4,$C$47:$C$49,0)),"",IF(INDEX(G47:G49,MATCH($D$4,$C$47:$C$49,0))="","",INDEX(G47:G49,MATCH($D$4,$C$47:$C$49,0)))) -> 0 | H46: =IF(ISNA(MATCH($D$4,$C$47:$C$49,0)),"",IF(INDEX(H47:H49,MATCH($D$4,$C$47:$C$49,0))="","",INDEX(H47:H49,MATCH($D$4,$C$47:$C$49,0)))) -> 0 | I46: =IF(H46="","",H46) -> 0
C47: Low | D47: 0 | E47: 0 | F47: 0 | G47: 0 | H47: 0 | I47: =IF(H47="","",H47) -> 0
C48: Base | D48: 0 | E48: 0 | F48: 0 | G48: 0 | H48: 0 | I48: =IF(H48="","",H48) -> 0
C49: High | D49: 0 | E49: 0 | F49: 0 | G49: 0 | H49: 0 | I49: =IF(H49="","",H49) -> 0
C52: Wage escalation: fixed annual assumption. The base wage is adjusted from its benchmark year to the first pricing year; each later option uses that period’s active rate.
C54: Supplied-rate escalation: applies only to a supplied loaded base rate. Zero holds it flat. A period override replaces only that period; the extension defaults to Option 4’s final rate.
C56: Low/Base/High company-cost assumptions are illustrative. Dates must be consecutive. The extension inherits Option 4 cost assumptions; its quantities and duration remain separate.

Sheet Staffing
C2: Staffing
C4: Scenario | D4: =Assumptions!$D$4 -> Base
D5: Base | E5: Option 1 | F5: Option 2 | G5: Option 3 | H5: Option 4 | I5: Extension
C8: R01 | D8: =IF(COUNTIFS('Source Data'!$C$21:$C$26,$C8)<>1,"",IF(INDEX('Source Data'!$D$21:$D$26,MATCH($C8,'Source Data'!$C$21:$C$26,0))="","",INDEX('Source Data'!$D$21:$D$26,MATCH($C8,'Source Data'!$C$21:$C$26,0)))) -> On-Site Supervisor
C9: Requested hours | D9: =IF(COUNTIFS('Source Data'!$C$30:$C$35,$C8)<>1,"",IF(INDEX('Source Data'!$D$30:$D$35,MATCH($C8,'Source Data'!$C$30:$C$35,0))="","",INDEX('Source Data'!$D$30:$D$35,MATCH($C8,'Source Data'!$C$30:$C$35,0)))) -> 2080 | E9: =IF(COUNTIFS('Source Data'!$C$30:$C$35,$C8)<>1,"",IF(INDEX('Source Data'!$E$30:$E$35,MATCH($C8,'Source Data'!$C$30:$C$35,0))="","",INDEX('Source Data'!$E$30:$E$35,MATCH($C8,'Source Data'!$C$30:$C$35,0)))) -> 2080 | F9: =IF(COUNTIFS('Source Data'!$C$30:$C$35,$C8)<>1,"",IF(INDEX('Source Data'!$F$30:$F$35,MATCH($C8,'Source Data'!$C$30:$C$35,0))="","",INDEX('Source Data'!$F$30:$F$35,MATCH($C8,'Source Data'!$C$30:$C$35,0)))) -> 2080 | G9: =IF(COUNTIFS('Source Data'!$C$30:$C$35,$C8)<>1,"",IF(INDEX('Source Data'!$G$30:$G$35,MATCH($C8,'Source Data'!$C$30:$C$35,0))="","",INDEX('Source Data'!$G$30:$G$35,MATCH($C8,'Source Data'!$C$30:$C$35,0)))) -> 2080 | H9: =IF(COUNTIFS('Source Data'!$C$30:$C$35,$C8)<>1,"",IF(INDEX('Source Data'!$H$30:$H$35,MATCH($C8,'Source Data'!$C$30:$C$35,0))="","",INDEX('Source Data'!$H$30:$H$35,MATCH($C8,'Source Data'!$C$30:$C$35,0)))) -> 2080 | I9: =IF(COUNTIFS('Source Data'!$C$30:$C$35,$C8)<>1,"",IF(INDEX('Source Data'!$I$30:$I$35,MATCH($C8,'Source Data'!$C$30:$C$35,0))="","",INDEX('Source Data'!$I$30:$I$35,MATCH($C8,'Source Data'!$C$30:$C$35,0)))) -> 1040
C10: Estimated positions | D10: =IF(COUNTIFS('Source Data'!$C$21:$C$26,$C8)<>1,"",IF(INDEX('Source Data'!$E$21:$E$26,MATCH($C8,'Source Data'!$C$21:$C$26,0))="","",INDEX('Source Data'!$E$21:$E$26,MATCH($C8,'Source Data'!$C$21:$C$26,0)))) -> 1 | E10: =IF(COUNTIFS('Source Data'!$C$21:$C$26,$C8)<>1,"",IF(INDEX('Source Data'!$E$21:$E$26,MATCH($C8,'Source Data'!$C$21:$C$26,0))="","",INDEX('Source Data'!$E$21:$E$26,MATCH($C8,'Source Data'!$C$21:$C$26,0)))) -> 1 | F10: =IF(COUNTIFS('Source Data'!$C$21:$C$26,$C8)<>1,"",IF(INDEX('Source Data'!$E$21:$E$26,MATCH($C8,'Source Data'!$C$21:$C$26,0))="","",INDEX('Source Data'!$E$21:$E$26,MATCH($C8,'Source Data'!$C$21:$C$26,0)))) -> 1 | G10: =IF(COUNTIFS('Source Data'!$C$21:$C$26,$C8)<>1,"",IF(INDEX('Source Data'!$E$21:$E$26,MATCH($C8,'Source Data'!$C$21:$C$26,0))="","",INDEX('Source Data'!$E$21:$E$26,MATCH($C8,'Source Data'!$C$21:$C$26,0)))) -> 1 | H10: =IF(COUNTIFS('Source Data'!$C$21:$C$26,$C8)<>1,"",IF(INDEX('Source Data'!$E$21:$E$26,MATCH($C8,'Source Data'!$C$21:$C$26,0))="","",INDEX('Source Data'!$E$21:$E$26,MATCH($C8,'Source Data'!$C$21:$C$26,0)))) -> 1 | I10: =IF(COUNTIFS('Source Data'!$C$21:$C$26,$C8)<>1,"",IF(INDEX('Source Data'!$E$21:$E$26,MATCH($C8,'Source Data'!$C$21:$C$26,0))="","",INDEX('Source Data'!$E$21:$E$26,MATCH($C8,'Source Data'!$C$21:$C$26,0)))) -> 1
C11: Required paid FTE | D11: =IF(COUNT(D9,Assumptions!$D$7,Assumptions!$D$8,Assumptions!D$19)<4,"",IF(OR(D9<0,Assumptions!$D$7<=Assumptions!$D$8,Assumptions!$D$8<0,Assumptions!D$19<=0),"",D9/((Assumptions!$D$7-Assumptions!$D$8)*Assumptions!D$19))) -> 1.1304348 | E11: =IF(COUNT(E9,Assumptions!$D$7,Assumptions!$D$8,Assumptions!E$19)<4,"",IF(OR(E9<0,Assumptions!$D$7<=Assumptions!$D$8,Assumptions!$D$8<0,Assumptions!E$19<=0),"",E9/((Assumptions!$D$7-Assumptions!$D$8)*Assumptions!E$19))) -> 1.1304348 | F11: =IF(COUNT(F9,Assumptions!$D$7,Assumptions!$D$8,Assumptions!F$19)<4,"",IF(OR(F9<0,Assumptions!$D$7<=Assumptions!$D$8,Assumptions!$D$8<0,Assumptions!F$19<=0),"",F9/((Assumptions!$D$7-Assumptions!$D$8)*Assumptions!F$19))) -> 1.1304348 | G11: =IF(COUNT(G9,Assumptions!$D$7,Assumptions!$D$8,Assumptions!G$19)<4,"",IF(OR(G9<0,Assumptions!$D$7<=Assumptions!$D$8,Assumptions!$D$8<0,Assumptions!G$19<=0),"",G9/((Assumptions!$D$7-Assumptions!$D$8)*Assumptions!G$19))) -> 1.1304348 | H11: =IF(COUNT(H9,Assumptions!$D$7,Assumptions!$D$8,Assumptions!H$19)<4,"",IF(OR(H9<0,Assumptions!$D$7<=Assumptions!$D$8,Assumptions!$D$8<0,Assumptions!H$19<=0),"",H9/((Assumptions!$D$7-Assumptions!$D$8)*Assumptions!H$19))) -> 1.1304348 | I11: =IF(COUNT(I9,Assumptions!$D$7,Assumptions!$D$8,Assumptions!I$19)<4,"",IF(OR(I9<0,Assumptions!$D$7<=Assumptions!$D$8,Assumptions!$D$8<0,Assumptions!I$19<=0),"",I9/((Assumptions!$D$7-Assumptions!$D$8)*Assumptions!I$19))) -> 1.1304348
C12: Proposed FTE override
C13: Paid FTE used | D13: =IF(D12="",IF(D11="","",D11),IF(AND(ISNUMBER(D12),D12>=0),D12,"")) -> 1.1304348 | E13: =IF(E12="",IF(E11="","",E11),IF(AND(ISNUMBER(E12),E12>=0),E12,"")) -> 1.1304348 | F13: =IF(F12="",IF(F11="","",F11),IF(AND(ISNUMBER(F12),F12>=0),F12,"")) -> 1.1304348 | G13: =IF(G12="",IF(G11="","",G11),IF(AND(ISNUMBER(G12),G12>=0),G12,"")) -> 1.1304348 | H13: =IF(H12="",IF(H11="","",H11),IF(AND(ISNUMBER(H12),H12>=0),H12,"")) -> 1.1304348 | I13: =IF(I12="",IF(I11="","",I11),IF(AND(ISNUMBER(I12),I12>=0),I12,"")) -> 1.1304348
C14: Available billable hours | D14: =IF(OR(COUNT(D13,Assumptions!$D$7,Assumptions!$D$8,Assumptions!D$19)<4,Assumptions!$D$7<=Assumptions!$D$8,Assumptions!$D$8<0,Assumptions!D$19<=0),"",D13*(Assumptions!$D$7-Assumptions!$D$8)*Assumptions!D$19) -> 2080 | E14: =IF(OR(COUNT(E13,Assumptions!$D$7,Assumptions!$D$8,Assumptions!E$19)<4,Assumptions!$D$7<=Assumptions!$D$8,Assumptions!$D$8<0,Assumptions!E$19<=0),"",E13*(Assumptions!$D$7-Assumptions!$D$8)*Assumptions!E$19) -> 2080 | F14: =IF(OR(COUNT(F13,Assumptions!$D$7,Assumptions!$D$8,Assumptions!F$19)<4,Assumptions!$D$7<=Assumptions!$D$8,Assumptions!$D$8<0,Assumptions!F$19<=0),"",F13*(Assumptions!$D$7-Assumptions!$D$8)*Assumptions!F$19) -> 2080 | G14: =IF(OR(COUNT(G13,Assumptions!$D$7,Assumptions!$D$8,Assumptions!G$19)<4,Assumptions!$D$7<=Assumptions!$D$8,Assumptions!$D$8<0,Assumptions!G$19<=0),"",G13*(Assumptions!$D$7-Assumptions!$D$8)*Assumptions!G$19) -> 2080 | H14: =IF(OR(COUNT(H13,Assumptions!$D$7,Assumptions!$D$8,Assumptions!H$19)<4,Assumptions!$D$7<=Assumptions!$D$8,Assumptions!$D$8<0,Assumptions!H$19<=0),"",H13*(Assumptions!$D$7-Assumptions!$D$8)*Assumptions!H$19) -> 2080 | I14: =IF(OR(COUNT(I13,Assumptions!$D$7,Assumptions!$D$8,Assumptions!I$19)<4,Assumptions!$D$7<=Assumptions!$D$8,Assumptions!$D$8<0,Assumptions!I$19<=0),"",I13*(Assumptions!$D$7-Assumptions!$D$8)*Assumptions!I$19) -> 1040
C15: Hours above / (below) need | D15: =IF(COUNT(D14,D9)<2,"",D14-D9) -> 0 | E15: =IF(COUNT(E14,E9)<2,"",E14-E9) -> 0 | F15: =IF(COUNT(F14,F9)<2,"",F14-F9) -> 0 | G15: =IF(COUNT(G14,G9)<2,"",G14-G9) -> 0 | H15: =IF(COUNT(H14,H9)<2,"",H14-H9) -> 0 | I15: =IF(COUNT(I14,I9)<2,"",I14-I9) -> 0
C16: Paid hours for cost | D16: =IF(OR(COUNT(D13,Assumptions!$D$7,Assumptions!D$19)<3,Assumptions!$D$7<=0,Assumptions!D$19<=0),"",D13*Assumptions!$D$7*Assumptions!D$19) -> 2351.3043 | E16: =IF(OR(COUNT(E13,Assumptions!$D$7,Assumptions!E$19)<3,Assumptions!$D$7<=0,Assumptions!E$19<=0),"",E13*Assumptions!$D$7*Assumptions!E$19) -> 2351.3043 | F16: =IF(OR(COUNT(F13,Assumptions!$D$7,Assumptions!F$19)<3,Assumptions!$D$7<=0,Assumptions!F$19<=0),"",F13*Assumptions!$D$7*Assumptions!F$19) -> 2351.3043 | G16: =IF(OR(COUNT(G13,Assumptions!$D$7,Assumptions!G$19)<3,Assumptions!$D$7<=0,Assumptions!G$19<=0),"",G13*Assumptions!$D$7*Assumptions!G$19) -> 2351.3043 | H16: =IF(OR(COUNT(H13,Assumptions!$D$7,Assumptions!H$19)<3,Assumptions!$D$7<=0,Assumptions!H$19<=0),"",H13*Assumptions!$D$7*Assumptions!H$19) -> 2351.3043 | I16: =IF(OR(COUNT(I13,Assumptions!$D$7,Assumptions!I$19)<3,Assumptions!$D$7<=0,Assumptions!I$19<=0),"",I13*Assumptions!$D$7*Assumptions!I$19) -> 1175.6522
C17: Input status | D17: =IF(COUNTIFS('Source Data'!$C$21:$C$26,$C8)<>1,"Duplicate / missing role",IF(OR($D8="",COUNT(D9:D10)<2,COUNT(D11,D13,D15)<3),"Missing / invalid",IF(OR(D9<0,D10<0),"Invalid input",IF(D15<-0.01,"Staffing shortfall","Complete")))) -> Complete | E17: =IF(COUNTIFS('Source Data'!$C$21:$C$26,$C8)<>1,"Duplicate / missing role",IF(OR($D8="",COUNT(E9:E10)<2,COUNT(E11,E13,E15)<3),"Missing / invalid",IF(OR(E9<0,E10<0),"Invalid input",IF(E15<-0.01,"Staffing shortfall","Complete")))) -> Complete | F17: =IF(COUNTIFS('Source Data'!$C$21:$C$26,$C8)<>1,"Duplicate / missing role",IF(OR($D8="",COUNT(F9:F10)<2,COUNT(F11,F13,F15)<3),"Missing / invalid",IF(OR(F9<0,F10<0),"Invalid input",IF(F15<-0.01,"Staffing shortfall","Complete")))) -> Complete | G17: =IF(COUNTIFS('Source Data'!$C$21:$C$26,$C8)<>1,"Duplicate / missing role",IF(OR($D8="",COUNT(G9:G10)<2,COUNT(G11,G13,G15)<3),"Missing / invalid",IF(OR(G9<0,G10<0),"Invalid input",IF(G15<-0.01,"Staffing shortfall","Complete")))) -> Complete | H17: =IF(COUNTIFS('Source Data'!$C$21:$C$26,$C8)<>1,"Duplicate / missing role",IF(OR($D8="",COUNT(H9:H10)<2,COUNT(H11,H13,H15)<3),"Missing / invalid",IF(OR(H9<0,H10<0),"Invalid input",IF(H15<-0.01,"Staffing shortfall","Complete")))) -> Complete | I17: =IF(COUNTIFS('Source Data'!$C$21:$C$26,$C8)<>1,"Duplicate / missing role",IF(OR($D8="",COUNT(I9:I10)<2,COUNT(I11,I13,I15)<3),"Missing / invalid",IF(OR(I9<0,I10<0),"Invalid input",IF(I15<-0.01,"Staffing shortfall","Complete")))) -> Complete
C20: R02 | D20: =IF(COUNTIFS('Source Data'!$C$21:$C$26,$C20)<>1,"",IF(INDEX('Source Data'!$D$21:$D$26,MATCH($C20,'Source Data'!$C$21:$C$26,0))="","",INDEX('Source Data'!$D$21:$D$26,MATCH($C20,'Source Data'!$C$21:$C$26,0)))) -> Financial Analyst
C21: Requested hours | D21: =IF(COUNTIFS('Source Data'!$C$30:$C$35,$C20)<>1,"",IF(INDEX('Source Data'!$D$30:$D$35,MATCH($C20,'Source Data'!$C$30:$C$35,0))="","",INDEX('Source Data'!$D$30:$D$35,MATCH($C20,'Source Data'!$C$30:$C$35,0)))) -> 4160 | E21: =IF(COUNTIFS('Source Data'!$C$30:$C$35,$C20)<>1,"",IF(INDEX('Source Data'!$E$30:$E$35,MATCH($C20,'Source Data'!$C$30:$C$35,0))="","",INDEX('Source Data'!$E$30:$E$35,MATCH($C20,'Source Data'!$C$30:$C$35,0)))) -> 4160 | F21: =IF(COUNTIFS('Source Data'!$C$30:$C$35,$C20)<>1,"",IF(INDEX('Source Data'!$F$30:$F$35,MATCH($C20,'Source Data'!$C$30:$C$35,0))="","",INDEX('Source Data'!$F$30:$F$35,MATCH($C20,'Source Data'!$C$30:$C$35,0)))) -> 4160 | G21: =IF(COUNTIFS('Source Data'!$C$30:$C$35,$C20)<>1,"",IF(INDEX('Source Data'!$G$30:$G$35,MATCH($C20,'Source Data'!$C$30:$C$35,0))="","",INDEX('Source Data'!$G$30:$G$35,MATCH($C20,'Source Data'!$C$30:$C$35,0)))) -> 4160 | H21: =IF(COUNTIFS('Source Data'!$C$30:$C$35,$C20)<>1,"",IF(INDEX('Source Data'!$H$30:$H$35,MATCH($C20,'Source Data'!$C$30:$C$35,0))="","",INDEX('Source Data'!$H$30:$H$35,MATCH($C20,'Source Data'!$C$30:$C$35,0)))) -> 4160 | I21: =IF(COUNTIFS('Source Data'!$C$30:$C$35,$C20)<>1,"",IF(INDEX('Source Data'!$I$30:$I$35,MATCH($C20,'Source Data'!$C$30:$C$35,0))="","",INDEX('Source Data'!$I$30:$I$35,MATCH($C20,'Source Data'!$C$30:$C$35,0)))) -> 2080
C22: Estimated positions | D22: =IF(COUNTIFS('Source Data'!$C$21:$C$26,$C20)<>1,"",IF(INDEX('Source Data'!$E$21:$E$26,MATCH($C20,'Source Data'!$C$21:$C$26,0))="","",INDEX('Source Data'!$E$21:$E$26,MATCH($C20,'Source Data'!$C$21:$C$26,0)))) -> 2 | E22: =IF(COUNTIFS('Source Data'!$C$21:$C$26,$C20)<>1,"",IF(INDEX('Source Data'!$E$21:$E$26,MATCH($C20,'Source Data'!$C$21:$C$26,0))="","",INDEX('Source Data'!$E$21:$E$26,MATCH($C20,'Source Data'!$C$21:$C$26,0)))) -> 2 | F22: =IF(COUNTIFS('Source Data'!$C$21:$C$26,$C20)<>1,"",IF(INDEX('Source Data'!$E$21:$E$26,MATCH($C20,'Source Data'!$C$21:$C$26,0))="","",INDEX('Source Data'!$E$21:$E$26,MATCH($C20,'Source Data'!$C$21:$C$26,0)))) -> 2 | G22: =IF(COUNTIFS('Source Data'!$C$21:$C$26,$C20)<>1,"",IF(INDEX('Source Data'!$E$21:$E$26,MATCH($C20,'Source Data'!$C$21:$C$26,0))="","",INDEX('Source Data'!$E$21:$E$26,MATCH($C20,'Source Data'!$C$21:$C$26,0)))) -> 2 | H22: =IF(COUNTIFS('Source Data'!$C$21:$C$26,$C20)<>1,"",IF(INDEX('Source Data'!$E$21:$E$26,MATCH($C20,'Source Data'!$C$21:$C$26,0))="","",INDEX('Source Data'!$E$21:$E$26,MATCH($C20,'Source Data'!$C$21:$C$26,0)))) -> 2 | I22: =IF(COUNTIFS('Source Data'!$C$21:$C$26,$C20)<>1,"",IF(INDEX('Source Data'!$E$21:$E$26,MATCH($C20,'Source Data'!$C$21:$C$26,0))="","",INDEX('Source Data'!$E$21:$E$26,MATCH($C20,'Source Data'!$C$21:$C$26,0)))) -> 2
C23: Required paid FTE | D23: =IF(COUNT(D21,Assumptions!$D$7,Assumptions!$D$8,Assumptions!D$19)<4,"",IF(OR(D21<0,Assumptions!$D$7<=Assumptions!$D$8,Assumptions!$D$8<0,Assumptions!D$19<=0),"",D21/((Assumptions!$D$7-Assumptions!$D$8)*Assumptions!D$19))) -> 2.2608696 | E23: =IF(COUNT(E21,Assumptions!$D$7,Assumptions!$D$8,Assumptions!E$19)<4,"",IF(OR(E21<0,Assumptions!$D$7<=Assumptions!$D$8,Assumptions!$D$8<0,Assumptions!E$19<=0),"",E21/((Assumptions!$D$7-Assumptions!$D$8)*Assumptions!E$19))) -> 2.2608696 | F23: =IF(COUNT(F21,Assumptions!$D$7,Assumptions!$D$8,Assumptions!F$19)<4,"",IF(OR(F21<0,Assumptions!$D$7<=Assumptions!$D$8,Assumptions!$D$8<0,Assumptions!F$19<=0),"",F21/((Assumptions!$D$7-Assumptions!$D$8)*Assumptions!F$19))) -> 2.2608696 | G23: =IF(COUNT(G21,Assumptions!$D$7,Assumptions!$D$8,Assumptions!G$19)<4,"",IF(OR(G21<0,Assumptions!$D$7<=Assumptions!$D$8,Assumptions!$D$8<0,Assumptions!G$19<=0),"",G21/((Assumptions!$D$7-Assumptions!$D$8)*Assumptions!G$19))) -> 2.2608696 | H23: =IF(COUNT(H21,Assumptions!$D$7,Assumptions!$D$8,Assumptions!H$19)<4,"",IF(OR(H21<0,Assumptions!$D$7<=Assumptions!$D$8,Assumptions!$D$8<0,Assumptions!H$19<=0),"",H21/((Assumptions!$D$7-Assumptions!$D$8)*Assumptions!H$19))) -> 2.2608696 | I23: =IF(COUNT(I21,Assumptions!$D$7,Assumptions!$D$8,Assumptions!I$19)<4,"",IF(OR(I21<0,Assumptions!$D$7<=Assumptions!$D$8,Assumptions!$D$8<0,Assumptions!I$19<=0),"",I21/((Assumptions!$D$7-Assumptions!$D$8)*Assumptions!I$19))) -> 2.2608696
C24: Proposed FTE override
C25: Paid FTE used | D25: =IF(D24="",IF(D23="","",D23),IF(AND(ISNUMBER(D24),D24>=0),D24,"")) -> 2.2608696 | E25: =IF(E24="",IF(E23="","",E23),IF(AND(ISNUMBER(E24),E24>=0),E24,"")) -> 2.2608696 | F25: =IF(F24="",IF(F23="","",F23),IF(AND(ISNUMBER(F24),F24>=0),F24,"")) -> 2.2608696 | G25: =IF(G24="",IF(G23="","",G23),IF(AND(ISNUMBER(G24),G24>=0),G24,"")) -> 2.2608696 | H25: =IF(H24="",IF(H23="","",H23),IF(AND(ISNUMBER(H24),H24>=0),H24,"")) -> 2.2608696 | I25: =IF(I24="",IF(I23="","",I23),IF(AND(ISNUMBER(I24),I24>=0),I24,"")) -> 2.2608696
C26: Available billable hours | D26: =IF(OR(COUNT(D25,Assumptions!$D$7,Assumptions!$D$8,Assumptions!D$19)<4,Assumptions!$D$7<=Assumptions!$D$8,Assumptions!$D$8<0,Assumptions!D$19<=0),"",D25*(Assumptions!$D$7-Assumptions!$D$8)*Assumptions!D$19) -> 4160 | E26: =IF(OR(COUNT(E25,Assumptions!$D$7,Assumptions!$D$8,Assumptions!E$19)<4,Assumptions!$D$7<=Assumptions!$D$8,Assumptions!$D$8<0,Assumptions!E$19<=0),"",E25*(Assumptions!$D$7-Assumptions!$D$8)*Assumptions!E$19) -> 4160 | F26: =IF(OR(COUNT(F25,Assumptions!$D$7,Assumptions!$D$8,Assumptions!F$19)<4,Assumptions!$D$7<=Assumptions!$D$8,Assumptions!$D$8<0,Assumptions!F$19<=0),"",F25*(Assumptions!$D$7-Assumptions!$D$8)*Assumptions!F$19) -> 4160 | G26: =IF(OR(COUNT(G25,Assumptions!$D$7,Assumptions!$D$8,Assumptions!G$19)<4,Assumptions!$D$7<=Assumptions!$D$8,Assumptions!$D$8<0,Assumptions!G$19<=0),"",G25*(Assumptions!$D$7-Assumptions!$D$8)*Assumptions!G$19) -> 4160 | H26: =IF(OR(COUNT(H25,Assumptions!$D$7,Assumptions!$D$8,Assumptions!H$19)<4,Assumptions!$D$7<=Assumptions!$D$8,Assumptions!$D$8<0,Assumptions!H$19<=0),"",H25*(Assumptions!$D$7-Assumptions!$D$8)*Assumptions!H$19) -> 4160 | I26: =IF(OR(COUNT(I25,Assumptions!$D$7,Assumptions!$D$8,Assumptions!I$19)<4,Assumptions!$D$7<=Assumptions!$D$8,Assumptions!$D$8<0,Assumptions!I$19<=0),"",I25*(Assumptions!$D$7-Assumptions!$D$8)*Assumptions!I$19) -> 2080
C27: Hours above / (below) need | D27: =IF(COUNT(D26,D21)<2,"",D26-D21) -> 0 | E27: =IF(COUNT(E26,E21)<2,"",E26-E21) -> 0 | F27: =IF(COUNT(F26,F21)<2,"",F26-F21) -> 0 | G27: =IF(COUNT(G26,G21)<2,"",G26-G21) -> 0 | H27: =IF(COUNT(H26,H21)<2,"",H26-H21) -> 0 | I27: =IF(COUNT(I26,I21)<2,"",I26-I21) -> 0
C28: Paid hours for cost | D28: =IF(OR(COUNT(D25,Assumptions!$D$7,Assumptions!D$19)<3,Assumptions!$D$7<=0,Assumptions!D$19<=0),"",D25*Assumptions!$D$7*Assumptions!D$19) -> 4702.6087 | E28: =IF(OR(COUNT(E25,Assumptions!$D$7,Assumptions!E$19)<3,Assumptions!$D$7<=0,Assumptions!E$19<=0),"",E25*Assumptions!$D$7*Assumptions!E$19) -> 4702.6087 | F28: =IF(OR(COUNT(F25,Assumptions!$D$7,Assumptions!F$19)<3,Assumptions!$D$7<=0,Assumptions!F$19<=0),"",F25*Assumptions!$D$7*Assumptions!F$19) -> 4702.6087 | G28: =IF(OR(COUNT(G25,Assumptions!$D$7,Assumptions!G$19)<3,Assumptions!$D$7<=0,Assumptions!G$19<=0),"",G25*Assumptions!$D$7*Assumptions!G$19) -> 4702.6087 | H28: =IF(OR(COUNT(H25,Assumptions!$D$7,Assumptions!H$19)<3,Assumptions!$D$7<=0,Assumptions!H$19<=0),"",H25*Assumptions!$D$7*Assumptions!H$19) -> 4702.6087 | I28: =IF(OR(COUNT(I25,Assumptions!$D$7,Assumptions!I$19)<3,Assumptions!$D$7<=0,Assumptions!I$19<=0),"",I25*Assumptions!$D$7*Assumptions!I$19) -> 2351.3043
C29: Input status | D29: =IF(COUNTIFS('Source Data'!$C$21:$C$26,$C20)<>1,"Duplicate / missing role",IF(OR($D20="",COUNT(D21:D22)<2,COUNT(D23,D25,D27)<3),"Missing / invalid",IF(OR(D21<0,D22<0),"Invalid input",IF(D27<-0.01,"Staffing shortfall","Complete")))) -> Complete | E29: =IF(COUNTIFS('Source Data'!$C$21:$C$26,$C20)<>1,"Duplicate / missing role",IF(OR($D20="",COUNT(E21:E22)<2,COUNT(E23,E25,E27)<3),"Missing / invalid",IF(OR(E21<0,E22<0),"Invalid input",IF(E27<-0.01,"Staffing shortfall","Complete")))) -> Complete | F29: =IF(COUNTIFS('Source Data'!$C$21:$C$26,$C20)<>1,"Duplicate / missing role",IF(OR($D20="",COUNT(F21:F22)<2,COUNT(F23,F25,F27)<3),"Missing / invalid",IF(OR(F21<0,F22<0),"Invalid input",IF(F27<-0.01,"Staffing shortfall","Complete")))) -> Complete | G29: =IF(COUNTIFS('Source Data'!$C$21:$C$26,$C20)<>1,"Duplicate / missing role",IF(OR($D20="",COUNT(G21:G22)<2,COUNT(G23,G25,G27)<3),"Missing / invalid",IF(OR(G21<0,G22<0),"Invalid input",IF(G27<-0.01,"Staffing shortfall","Complete")))) -> Complete | H29: =IF(COUNTIFS('Source Data'!$C$21:$C$26,$C20)<>1,"Duplicate / missing role",IF(OR($D20="",COUNT(H21:H22)<2,COUNT(H23,H25,H27)<3),"Missing / invalid",IF(OR(H21<0,H22<0),"Invalid input",IF(H27<-0.01,"Staffing shortfall","Complete")))) -> Complete | I29: =IF(COUNTIFS('Source Data'!$C$21:$C$26,$C20)<>1,"Duplicate / missing role",IF(OR($D20="",COUNT(I21:I22)<2,COUNT(I23,I25,I27)<3),"Missing / invalid",IF(OR(I21<0,I22<0),"Invalid input",IF(I27<-0.01,"Staffing shortfall","Complete")))) -> Complete
C32: R03 | D32: =IF(COUNTIFS('Source Data'!$C$21:$C$26,$C32)<>1,"",IF(INDEX('Source Data'!$D$21:$D$26,MATCH($C32,'Source Data'!$C$21:$C$26,0))="","",INDEX('Source Data'!$D$21:$D$26,MATCH($C32,'Source Data'!$C$21:$C$26,0)))) -> Administrative Assistant
C33: Requested hours | D33: =IF(COUNTIFS('Source Data'!$C$30:$C$35,$C32)<>1,"",IF(INDEX('Source Data'!$D$30:$D$35,MATCH($C32,'Source Data'!$C$30:$C$35,0))="","",INDEX('Source Data'!$D$30:$D$35,MATCH($C32,'Source Data'!$C$30:$C$35,0)))) -> 2080 | E33: =IF(COUNTIFS('Source Data'!$C$30:$C$35,$C32)<>1,"",IF(INDEX('Source Data'!$E$30:$E$35,MATCH($C32,'Source Data'!$C$30:$C$35,0))="","",INDEX('Source Data'!$E$30:$E$35,MATCH($C32,'Source Data'!$C$30:$C$35,0)))) -> 2080 | F33: =IF(COUNTIFS('Source Data'!$C$30:$C$35,$C32)<>1,"",IF(INDEX('Source Data'!$F$30:$F$35,MATCH($C32,'Source Data'!$C$30:$C$35,0))="","",INDEX('Source Data'!$F$30:$F$35,MATCH($C32,'Source Data'!$C$30:$C$35,0)))) -> 2080 | G33: =IF(COUNTIFS('Source Data'!$C$30:$C$35,$C32)<>1,"",IF(INDEX('Source Data'!$G$30:$G$35,MATCH($C32,'Source Data'!$C$30:$C$35,0))="","",INDEX('Source Data'!$G$30:$G$35,MATCH($C32,'Source Data'!$C$30:$C$35,0)))) -> 2080 | H33: =IF(COUNTIFS('Source Data'!$C$30:$C$35,$C32)<>1,"",IF(INDEX('Source Data'!$H$30:$H$35,MATCH($C32,'Source Data'!$C$30:$C$35,0))="","",INDEX('Source Data'!$H$30:$H$35,MATCH($C32,'Source Data'!$C$30:$C$35,0)))) -> 2080 | I33: =IF(COUNTIFS('Source Data'!$C$30:$C$35,$C32)<>1,"",IF(INDEX('Source Data'!$I$30:$I$35,MATCH($C32,'Source Data'!$C$30:$C$35,0))="","",INDEX('Source Data'!$I$30:$I$35,MATCH($C32,'Source Data'!$C$30:$C$35,0)))) -> 1040
C34: Estimated positions | D34: =IF(COUNTIFS('Source Data'!$C$21:$C$26,$C32)<>1,"",IF(INDEX('Source Data'!$E$21:$E$26,MATCH($C32,'Source Data'!$C$21:$C$26,0))="","",INDEX('Source Data'!$E$21:$E$26,MATCH($C32,'Source Data'!$C$21:$C$26,0)))) -> 1 | E34: =IF(COUNTIFS('Source Data'!$C$21:$C$26,$C32)<>1,"",IF(INDEX('Source Data'!$E$21:$E$26,MATCH($C32,'Source Data'!$C$21:$C$26,0))="","",INDEX('Source Data'!$E$21:$E$26,MATCH($C32,'Source Data'!$C$21:$C$26,0)))) -> 1 | F34: =IF(COUNTIFS('Source Data'!$C$21:$C$26,$C32)<>1,"",IF(INDEX('Source Data'!$E$21:$E$26,MATCH($C32,'Source Data'!$C$21:$C$26,0))="","",INDEX('Source Data'!$E$21:$E$26,MATCH($C32,'Source Data'!$C$21:$C$26,0)))) -> 1 | G34: =IF(COUNTIFS('Source Data'!$C$21:$C$26,$C32)<>1,"",IF(INDEX('Source Data'!$E$21:$E$26,MATCH($C32,'Source Data'!$C$21:$C$26,0))="","",INDEX('Source Data'!$E$21:$E$26,MATCH($C32,'Source Data'!$C$21:$C$26,0)))) -> 1 | H34: =IF(COUNTIFS('Source Data'!$C$21:$C$26,$C32)<>1,"",IF(INDEX('Source Data'!$E$21:$E$26,MATCH($C32,'Source Data'!$C$21:$C$26,0))="","",INDEX('Source Data'!$E$21:$E$26,MATCH($C32,'Source Data'!$C$21:$C$26,0)))) -> 1 | I34: =IF(COUNTIFS('Source Data'!$C$21:$C$26,$C32)<>1,"",IF(INDEX('Source Data'!$E$21:$E$26,MATCH($C32,'Source Data'!$C$21:$C$26,0))="","",INDEX('Source Data'!$E$21:$E$26,MATCH($C32,'Source Data'!$C$21:$C$26,0)))) -> 1
C35: Required paid FTE | D35: =IF(COUNT(D33,Assumptions!$D$7,Assumptions!$D$8,Assumptions!D$19)<4,"",IF(OR(D33<0,Assumptions!$D$7<=Assumptions!$D$8,Assumptions!$D$8<0,Assumptions!D$19<=0),"",D33/((Assumptions!$D$7-Assumptions!$D$8)*Assumptions!D$19))) -> 1.1304348 | E35: =IF(COUNT(E33,Assumptions!$D$7,Assumptions!$D$8,Assumptions!E$19)<4,"",IF(OR(E33<0,Assumptions!$D$7<=Assumptions!$D$8,Assumptions!$D$8<0,Assumptions!E$19<=0),"",E33/((Assumptions!$D$7-Assumptions!$D$8)*Assumptions!E$19))) -> 1.1304348 | F35: =IF(COUNT(F33,Assumptions!$D$7,Assumptions!$D$8,Assumptions!F$19)<4,"",IF(OR(F33<0,Assumptions!$D$7<=Assumptions!$D$8,Assumptions!$D$8<0,Assumptions!F$19<=0),"",F33/((Assumptions!$D$7-Assumptions!$D$8)*Assumptions!F$19))) -> 1.1304348 | G35: =IF(COUNT(G33,Assumptions!$D$7,Assumptions!$D$8,Assumptions!G$19)<4,"",IF(OR(G33<0,Assumptions!$D$7<=Assumptions!$D$8,Assumptions!$D$8<0,Assumptions!G$19<=0),"",G33/((Assumptions!$D$7-Assumptions!$D$8)*Assumptions!G$19))) -> 1.1304348 | H35: =IF(COUNT(H33,Assumptions!$D$7,Assumptions!$D$8,Assumptions!H$19)<4,"",IF(OR(H33<0,Assumptions!$D$7<=Assumptions!$D$8,Assumptions!$D$8<0,Assumptions!H$19<=0),"",H33/((Assumptions!$D$7-Assumptions!$D$8)*Assumptions!H$19))) -> 1.1304348 | I35: =IF(COUNT(I33,Assumptions!$D$7,Assumptions!$D$8,Assumptions!I$19)<4,"",IF(OR(I33<0,Assumptions!$D$7<=Assumptions!$D$8,Assumptions!$D$8<0,Assumptions!I$19<=0),"",I33/((Assumptions!$D$7-Assumptions!$D$8)*Assumptions!I$19))) -> 1.1304348
C36: Proposed FTE override
C37: Paid FTE used | D37: =IF(D36="",IF(D35="","",D35),IF(AND(ISNUMBER(D36),D36>=0),D36,"")) -> 1.1304348 | E37: =IF(E36="",IF(E35="","",E35),IF(AND(ISNUMBER(E36),E36>=0),E36,"")) -> 1.1304348 | F37: =IF(F36="",IF(F35="","",F35),IF(AND(ISNUMBER(F36),F36>=0),F36,"")) -> 1.1304348 | G37: =IF(G36="",IF(G35="","",G35),IF(AND(ISNUMBER(G36),G36>=0),G36,"")) -> 1.1304348 | H37: =IF(H36="",IF(H35="","",H35),IF(AND(ISNUMBER(H36),H36>=0),H36,"")) -> 1.1304348 | I37: =IF(I36="",IF(I35="","",I35),IF(AND(ISNUMBER(I36),I36>=0),I36,"")) -> 1.1304348
C38: Available billable hours | D38: =IF(OR(COUNT(D37,Assumptions!$D$7,Assumptions!$D$8,Assumptions!D$19)<4,Assumptions!$D$7<=Assumptions!$D$8,Assumptions!$D$8<0,Assumptions!D$19<=0),"",D37*(Assumptions!$D$7-Assumptions!$D$8)*Assumptions!D$19) -> 2080 | E38: =IF(OR(COUNT(E37,Assumptions!$D$7,Assumptions!$D$8,Assumptions!E$19)<4,Assumptions!$D$7<=Assumptions!$D$8,Assumptions!$D$8<0,Assumptions!E$19<=0),"",E37*(Assumptions!$D$7-Assumptions!$D$8)*Assumptions!E$19) -> 2080 | F38: =IF(OR(COUNT(F37,Assumptions!$D$7,Assumptions!$D$8,Assumptions!F$19)<4,Assumptions!$D$7<=Assumptions!$D$8,Assumptions!$D$8<0,Assumptions!F$19<=0),"",F37*(Assumptions!$D$7-Assumptions!$D$8)*Assumptions!F$19) -> 2080 | G38: =IF(OR(COUNT(G37,Assumptions!$D$7,Assumptions!$D$8,Assumptions!G$19)<4,Assumptions!$D$7<=Assumptions!$D$8,Assumptions!$D$8<0,Assumptions!G$19<=0),"",G37*(Assumptions!$D$7-Assumptions!$D$8)*Assumptions!G$19) -> 2080 | H38: =IF(OR(COUNT(H37,Assumptions!$D$7,Assumptions!$D$8,Assumptions!H$19)<4,Assumptions!$D$7<=Assumptions!$D$8,Assumptions!$D$8<0,Assumptions!H$19<=0),"",H37*(Assumptions!$D$7-Assumptions!$D$8)*Assumptions!H$19) -> 2080 | I38: =IF(OR(COUNT(I37,Assumptions!$D$7,Assumptions!$D$8,Assumptions!I$19)<4,Assumptions!$D$7<=Assumptions!$D$8,Assumptions!$D$8<0,Assumptions!I$19<=0),"",I37*(Assumptions!$D$7-Assumptions!$D$8)*Assumptions!I$19) -> 1040
C39: Hours above / (below) need | D39: =IF(COUNT(D38,D33)<2,"",D38-D33) -> 0 | E39: =IF(COUNT(E38,E33)<2,"",E38-E33) -> 0 | F39: =IF(COUNT(F38,F33)<2,"",F38-F33) -> 0 | G39: =IF(COUNT(G38,G33)<2,"",G38-G33) -> 0 | H39: =IF(COUNT(H38,H33)<2,"",H38-H33) -> 0 | I39: =IF(COUNT(I38,I33)<2,"",I38-I33) -> 0
C40: Paid hours for cost | D40: =IF(OR(COUNT(D37,Assumptions!$D$7,Assumptions!D$19)<3,Assumptions!$D$7<=0,Assumptions!D$19<=0),"",D37*Assumptions!$D$7*Assumptions!D$19) -> 2351.3043 | E40: =IF(OR(COUNT(E37,Assumptions!$D$7,Assumptions!E$19)<3,Assumptions!$D$7<=0,Assumptions!E$19<=0),"",E37*Assumptions!$D$7*Assumptions!E$19) -> 2351.3043 | F40: =IF(OR(COUNT(F37,Assumptions!$D$7,Assumptions!F$19)<3,Assumptions!$D$7<=0,Assumptions!F$19<=0),"",F37*Assumptions!$D$7*Assumptions!F$19) -> 2351.3043 | G40: =IF(OR(COUNT(G37,Assumptions!$D$7,Assumptions!G$19)<3,Assumptions!$D$7<=0,Assumptions!G$19<=0),"",G37*Assumptions!$D$7*Assumptions!G$19) -> 2351.3043 | H40: =IF(OR(COUNT(H37,Assumptions!$D$7,Assumptions!H$19)<3,Assumptions!$D$7<=0,Assumptions!H$19<=0),"",H37*Assumptions!$D$7*Assumptions!H$19) -> 2351.3043 | I40: =IF(OR(COUNT(I37,Assumptions!$D$7,Assumptions!I$19)<3,Assumptions!$D$7<=0,Assumptions!I$19<=0),"",I37*Assumptions!$D$7*Assumptions!I$19) -> 1175.6522
C41: Input status | D41: =IF(COUNTIFS('Source Data'!$C$21:$C$26,$C32)<>1,"Duplicate / missing role",IF(OR($D32="",COUNT(D33:D34)<2,COUNT(D35,D37,D39)<3),"Missing / invalid",IF(OR(D33<0,D34<0),"Invalid input",IF(D39<-0.01,"Staffing shortfall","Complete")))) -> Complete | E41: =IF(COUNTIFS('Source Data'!$C$21:$C$26,$C32)<>1,"Duplicate / missing role",IF(OR($D32="",COUNT(E33:E34)<2,COUNT(E35,E37,E39)<3),"Missing / invalid",IF(OR(E33<0,E34<0),"Invalid input",IF(E39<-0.01,"Staffing shortfall","Complete")))) -> Complete | F41: =IF(COUNTIFS('Source Data'!$C$21:$C$26,$C32)<>1,"Duplicate / missing role",IF(OR($D32="",COUNT(F33:F34)<2,COUNT(F35,F37,F39)<3),"Missing / invalid",IF(OR(F33<0,F34<0),"Invalid input",IF(F39<-0.01,"Staffing shortfall","Complete")))) -> Complete | G41: =IF(COUNTIFS('Source Data'!$C$21:$C$26,$C32)<>1,"Duplicate / missing role",IF(OR($D32="",COUNT(G33:G34)<2,COUNT(G35,G37,G39)<3),"Missing / invalid",IF(OR(G33<0,G34<0),"Invalid input",IF(G39<-0.01,"Staffing shortfall","Complete")))) -> Complete | H41: =IF(COUNTIFS('Source Data'!$C$21:$C$26,$C32)<>1,"Duplicate / missing role",IF(OR($D32="",COUNT(H33:H34)<2,COUNT(H35,H37,H39)<3),"Missing / invalid",IF(OR(H33<0,H34<0),"Invalid input",IF(H39<-0.01,"Staffing shortfall","Complete")))) -> Complete | I41: =IF(COUNTIFS('Source Data'!$C$21:$C$26,$C32)<>1,"Duplicate / missing role",IF(OR($D32="",COUNT(I33:I34)<2,COUNT(I35,I37,I39)<3),"Missing / invalid",IF(OR(I33<0,I34<0),"Invalid input",IF(I39<-0.01,"Staffing shortfall","Complete")))) -> Complete
C44: R04 | D44: =IF(COUNTIFS('Source Data'!$C$21:$C$26,$C44)<>1,"",IF(INDEX('Source Data'!$D$21:$D$26,MATCH($C44,'Source Data'!$C$21:$C$26,0))="","",INDEX('Source Data'!$D$21:$D$26,MATCH($C44,'Source Data'!$C$21:$C$26,0)))) -> Program Analyst I
C45: Requested hours | D45: =IF(COUNTIFS('Source Data'!$C$30:$C$35,$C44)<>1,"",IF(INDEX('Source Data'!$D$30:$D$35,MATCH($C44,'Source Data'!$C$30:$C$35,0))="","",INDEX('Source Data'!$D$30:$D$35,MATCH($C44,'Source Data'!$C$30:$C$35,0)))) -> 2080 | E45: =IF(COUNTIFS('Source Data'!$C$30:$C$35,$C44)<>1,"",IF(INDEX('Source Data'!$E$30:$E$35,MATCH($C44,'Source Data'!$C$30:$C$35,0))="","",INDEX('Source Data'!$E$30:$E$35,MATCH($C44,'Source Data'!$C$30:$C$35,0)))) -> 2080 | F45: =IF(COUNTIFS('Source Data'!$C$30:$C$35,$C44)<>1,"",IF(INDEX('Source Data'!$F$30:$F$35,MATCH($C44,'Source Data'!$C$30:$C$35,0))="","",INDEX('Source Data'!$F$30:$F$35,MATCH($C44,'Source Data'!$C$30:$C$35,0)))) -> 2080 | G45: =IF(COUNTIFS('Source Data'!$C$30:$C$35,$C44)<>1,"",IF(INDEX('Source Data'!$G$30:$G$35,MATCH($C44,'Source Data'!$C$30:$C$35,0))="","",INDEX('Source Data'!$G$30:$G$35,MATCH($C44,'Source Data'!$C$30:$C$35,0)))) -> 2080 | H45: =IF(COUNTIFS('Source Data'!$C$30:$C$35,$C44)<>1,"",IF(INDEX('Source Data'!$H$30:$H$35,MATCH($C44,'Source Data'!$C$30:$C$35,0))="","",INDEX('Source Data'!$H$30:$H$35,MATCH($C44,'Source Data'!$C$30:$C$35,0)))) -> 2080 | I45: =IF(COUNTIFS('Source Data'!$C$30:$C$35,$C44)<>1,"",IF(INDEX('Source Data'!$I$30:$I$35,MATCH($C44,'Source Data'!$C$30:$C$35,0))="","",INDEX('Source Data'!$I$30:$I$35,MATCH($C44,'Source Data'!$C$30:$C$35,0)))) -> 1040
C46: Estimated positions | D46: =IF(COUNTIFS('Source Data'!$C$21:$C$26,$C44)<>1,"",IF(INDEX('Source Data'!$E$21:$E$26,MATCH($C44,'Source Data'!$C$21:$C$26,0))="","",INDEX('Source Data'!$E$21:$E$26,MATCH($C44,'Source Data'!$C$21:$C$26,0)))) -> 1 | E46: =IF(COUNTIFS('Source Data'!$C$21:$C$26,$C44)<>1,"",IF(INDEX('Source Data'!$E$21:$E$26,MATCH($C44,'Source Data'!$C$21:$C$26,0))="","",INDEX('Source Data'!$E$21:$E$26,MATCH($C44,'Source Data'!$C$21:$C$26,0)))) -> 1 | F46: =IF(COUNTIFS('Source Data'!$C$21:$C$26,$C44)<>1,"",IF(INDEX('Source Data'!$E$21:$E$26,MATCH($C44,'Source Data'!$C$21:$C$26,0))="","",INDEX('Source Data'!$E$21:$E$26,MATCH($C44,'Source Data'!$C$21:$C$26,0)))) -> 1 | G46: =IF(COUNTIFS('Source Data'!$C$21:$C$26,$C44)<>1,"",IF(INDEX('Source Data'!$E$21:$E$26,MATCH($C44,'Source Data'!$C$21:$C$26,0))="","",INDEX('Source Data'!$E$21:$E$26,MATCH($C44,'Source Data'!$C$21:$C$26,0)))) -> 1 | H46: =IF(COUNTIFS('Source Data'!$C$21:$C$26,$C44)<>1,"",IF(INDEX('Source Data'!$E$21:$E$26,MATCH($C44,'Source Data'!$C$21:$C$26,0))="","",INDEX('Source Data'!$E$21:$E$26,MATCH($C44,'Source Data'!$C$21:$C$26,0)))) -> 1 | I46: =IF(COUNTIFS('Source Data'!$C$21:$C$26,$C44)<>1,"",IF(INDEX('Source Data'!$E$21:$E$26,MATCH($C44,'Source Data'!$C$21:$C$26,0))="","",INDEX('Source Data'!$E$21:$E$26,MATCH($C44,'Source Data'!$C$21:$C$26,0)))) -> 1
C47: Required paid FTE | D47: =IF(COUNT(D45,Assumptions!$D$7,Assumptions!$D$8,Assumptions!D$19)<4,"",IF(OR(D45<0,Assumptions!$D$7<=Assumptions!$D$8,Assumptions!$D$8<0,Assumptions!D$19<=0),"",D45/((Assumptions!$D$7-Assumptions!$D$8)*Assumptions!D$19))) -> 1.1304348 | E47: =IF(COUNT(E45,Assumptions!$D$7,Assumptions!$D$8,Assumptions!E$19)<4,"",IF(OR(E45<0,Assumptions!$D$7<=Assumptions!$D$8,Assumptions!$D$8<0,Assumptions!E$19<=0),"",E45/((Assumptions!$D$7-Assumptions!$D$8)*Assumptions!E$19))) -> 1.1304348 | F47: =IF(COUNT(F45,Assumptions!$D$7,Assumptions!$D$8,Assumptions!F$19)<4,"",IF(OR(F45<0,Assumptions!$D$7<=Assumptions!$D$8,Assumptions!$D$8<0,Assumptions!F$19<=0),"",F45/((Assumptions!$D$7-Assumptions!$D$8)*Assumptions!F$19))) -> 1.1304348 | G47: =IF(COUNT(G45,Assumptions!$D$7,Assumptions!$D$8,Assumptions!G$19)<4,"",IF(OR(G45<0,Assumptions!$D$7<=Assumptions!$D$8,Assumptions!$D$8<0,Assumptions!G$19<=0),"",G45/((Assumptions!$D$7-Assumptions!$D$8)*Assumptions!G$19))) -> 1.1304348 | H47: =IF(COUNT(H45,Assumptions!$D$7,Assumptions!$D$8,Assumptions!H$19)<4,"",IF(OR(H45<0,Assumptions!$D$7<=Assumptions!$D$8,Assumptions!$D$8<0,Assumptions!H$19<=0),"",H45/((Assumptions!$D$7-Assumptions!$D$8)*Assumptions!H$19))) -> 1.1304348 | I47: =IF(COUNT(I45,Assumptions!$D$7,Assumptions!$D$8,Assumptions!I$19)<4,"",IF(OR(I45<0,Assumptions!$D$7<=Assumptions!$D$8,Assumptions!$D$8<0,Assumptions!I$19<=0),"",I45/((Assumptions!$D$7-Assumptions!$D$8)*Assumptions!I$19))) -> 1.1304348
C48: Proposed FTE override
C49: Paid FTE used | D49: =IF(D48="",IF(D47="","",D47),IF(AND(ISNUMBER(D48),D48>=0),D48,"")) -> 1.1304348 | E49: =IF(E48="",IF(E47="","",E47),IF(AND(ISNUMBER(E48),E48>=0),E48,"")) -> 1.1304348 | F49: =IF(F48="",IF(F47="","",F47),IF(AND(ISNUMBER(F48),F48>=0),F48,"")) -> 1.1304348 | G49: =IF(G48="",IF(G47="","",G47),IF(AND(ISNUMBER(G48),G48>=0),G48,"")) -> 1.1304348 | H49: =IF(H48="",IF(H47="","",H47),IF(AND(ISNUMBER(H48),H48>=0),H48,"")) -> 1.1304348 | I49: =IF(I48="",IF(I47="","",I47),IF(AND(ISNUMBER(I48),I48>=0),I48,"")) -> 1.1304348
C50: Available billable hours | D50: =IF(OR(COUNT(D49,Assumptions!$D$7,Assumptions!$D$8,Assumptions!D$19)<4,Assumptions!$D$7<=Assumptions!$D$8,Assumptions!$D$8<0,Assumptions!D$19<=0),"",D49*(Assumptions!$D$7-Assumptions!$D$8)*Assumptions!D$19) -> 2080 | E50: =IF(OR(COUNT(E49,Assumptions!$D$7,Assumptions!$D$8,Assumptions!E$19)<4,Assumptions!$D$7<=Assumptions!$D$8,Assumptions!$D$8<0,Assumptions!E$19<=0),"",E49*(Assumptions!$D$7-Assumptions!$D$8)*Assumptions!E$19) -> 2080 | F50: =IF(OR(COUNT(F49,Assumptions!$D$7,Assumptions!$D$8,Assumptions!F$19)<4,Assumptions!$D$7<=Assumptions!$D$8,Assumptions!$D$8<0,Assumptions!F$19<=0),"",F49*(Assumptions!$D$7-Assumptions!$D$8)*Assumptions!F$19) -> 2080 | G50: =IF(OR(COUNT(G49,Assumptions!$D$7,Assumptions!$D$8,Assumptions!G$19)<4,Assumptions!$D$7<=Assumptions!$D$8,Assumptions!$D$8<0,Assumptions!G$19<=0),"",G49*(Assumptions!$D$7-Assumptions!$D$8)*Assumptions!G$19) -> 2080 | H50: =IF(OR(COUNT(H49,Assumptions!$D$7,Assumptions!$D$8,Assumptions!H$19)<4,Assumptions!$D$7<=Assumptions!$D$8,Assumptions!$D$8<0,Assumptions!H$19<=0),"",H49*(Assumptions!$D$7-Assumptions!$D$8)*Assumptions!H$19) -> 2080 | I50: =IF(OR(COUNT(I49,Assumptions!$D$7,Assumptions!$D$8,Assumptions!I$19)<4,Assumptions!$D$7<=Assumptions!$D$8,Assumptions!$D$8<0,Assumptions!I$19<=0),"",I49*(Assumptions!$D$7-Assumptions!$D$8)*Assumptions!I$19) -> 1040
...

Sheet Labor Rates
C2: Labor Rates
C4: Scenario | D4: =Assumptions!$D$4 -> Base
D5: Base | E5: Option 1 | F5: Option 2 | G5: Option 3 | H5: Option 4 | I5: Extension
C8: R01 | D8: =IF(COUNTIFS('Source Data'!$C$21:$C$26,$C8)<>1,"",IF(INDEX('Source Data'!$D$21:$D$26,MATCH($C8,'Source Data'!$C$21:$C$26,0))="","",INDEX('Source Data'!$D$21:$D$26,MATCH($C8,'Source Data'!$C$21:$C$26,0)))) -> On-Site Supervisor
C9: Rate basis | D9: =IF(COUNTIFS('Source Data'!$C$21:$C$26,$C8)<>1,"",IF(INDEX('Source Data'!$H$21:$H$26,MATCH($C8,'Source Data'!$C$21:$C$26,0))="","",INDEX('Source Data'!$H$21:$H$26,MATCH($C8,'Source Data'!$C$21:$C$26,0)))) -> Build from wage | E9: =IF(COUNTIFS('Source Data'!$C$21:$C$26,$C8)<>1,"",IF(INDEX('Source Data'!$H$21:$H$26,MATCH($C8,'Source Data'!$C$21:$C$26,0))="","",INDEX('Source Data'!$H$21:$H$26,MATCH($C8,'Source Data'!$C$21:$C$26,0)))) -> Build from wage | F9: =IF(COUNTIFS('Source Data'!$C$21:$C$26,$C8)<>1,"",IF(INDEX('Source Data'!$H$21:$H$26,MATCH($C8,'Source Data'!$C$21:$C$26,0))="","",INDEX('Source Data'!$H$21:$H$26,MATCH($C8,'Source Data'!$C$21:$C$26,0)))) -> Build from wage | G9: =IF(COUNTIFS('Source Data'!$C$21:$C$26,$C8)<>1,"",IF(INDEX('Source Data'!$H$21:$H$26,MATCH($C8,'Source Data'!$C$21:$C$26,0))="","",INDEX('Source Data'!$H$21:$H$26,MATCH($C8,'Source Data'!$C$21:$C$26,0)))) -> Build from wage | H9: =IF(COUNTIFS('Source Data'!$C$21:$C$26,$C8)<>1,"",IF(INDEX('Source Data'!$H$21:$H$26,MATCH($C8,'Source Data'!$C$21:$C$26,0))="","",INDEX('Source Data'!$H$21:$H$26,MATCH($C8,'Source Data'!$C$21:$C$26,0)))) -> Build from wage | I9: =IF(COUNTIFS('Source Data'!$C$21:$C$26,$C8)<>1,"",IF(INDEX('Source Data'!$H$21:$H$26,MATCH($C8,'Source Data'!$C$21:$C$26,0))="","",INDEX('Source Data'!$H$21:$H$26,MATCH($C8,'Source Data'!$C$21:$C$26,0)))) -> Build from wage
C10: Benchmark wage / hour | D10: =IF(COUNTIFS('Source Data'!$C$21:$C$26,$C8)<>1,"",IF(INDEX('Source Data'!$F$21:$F$26,MATCH($C8,'Source Data'!$C$21:$C$26,0))="","",INDEX('Source Data'!$F$21:$F$26,MATCH($C8,'Source Data'!$C$21:$C$26,0)))) -> 46.21 | E10: =IF(COUNTIFS('Source Data'!$C$21:$C$26,$C8)<>1,"",IF(INDEX('Source Data'!$F$21:$F$26,MATCH($C8,'Source Data'!$C$21:$C$26,0))="","",INDEX('Source Data'!$F$21:$F$26,MATCH($C8,'Source Data'!$C$21:$C$26,0)))) -> 46.21 | F10: =IF(COUNTIFS('Source Data'!$C$21:$C$26,$C8)<>1,"",IF(INDEX('Source Data'!$F$21:$F$26,MATCH($C8,'Source Data'!$C$21:$C$26,0))="","",INDEX('Source Data'!$F$21:$F$26,MATCH($C8,'Source Data'!$C$21:$C$26,0)))) -> 46.21 | G10: =IF(COUNTIFS('Source Data'!$C$21:$C$26,$C8)<>1,"",IF(INDEX('Source Data'!$F$21:$F$26,MATCH($C8,'Source Data'!$C$21:$C$26,0))="","",INDEX('Source Data'!$F$21:$F$26,MATCH($C8,'Source Data'!$C$21:$C$26,0)))) -> 46.21 | H10: =IF(COUNTIFS('Source Data'!$C$21:$C$26,$C8)<>1,"",IF(INDEX('Source Data'!$F$21:$F$26,MATCH($C8,'Source Data'!$C$21:$C$26,0))="","",INDEX('Source Data'!$F$21:$F$26,MATCH($C8,'Source Data'!$C$21:$C$26,0)))) -> 46.21 | I10: =IF(COUNTIFS('Source Data'!$C$21:$C$26,$C8)<>1,"",IF(INDEX('Source Data'!$F$21:$F$26,MATCH($C8,'Source Data'!$C$21:$C$26,0))="","",INDEX('Source Data'!$F$21:$F$26,MATCH($C8,'Source Data'!$C$21:$C$26,0)))) -> 46.21
C11: Benchmark year | D11: =IF(COUNTIFS('Source Data'!$C$21:$C$26,$C8)<>1,"",IF(INDEX('Source Data'!$G$21:$G$26,MATCH($C8,'Source Data'!$C$21:$C$26,0))="","",INDEX('Source Data'!$G$21:$G$26,MATCH($C8,'Source Data'!$C$21:$C$26,0)))) -> 2025 | E11: =IF(COUNTIFS('Source Data'!$C$21:$C$26,$C8)<>1,"",IF(INDEX('Source Data'!$G$21:$G$26,MATCH($C8,'Source Data'!$C$21:$C$26,0))="","",INDEX('Source Data'!$G$21:$G$26,MATCH($C8,'Source Data'!$C$21:$C$26,0)))) -> 2025 | F11: =IF(COUNTIFS('Source Data'!$C$21:$C$26,$C8)<>1,"",IF(INDEX('Source Data'!$G$21:$G$26,MATCH($C8,'Source Data'!$C$21:$C$26,0))="","",INDEX('Source Data'!$G$21:$G$26,MATCH($C8,'Source Data'!$C$21:$C$26,0)))) -> 2025 | G11: =IF(COUNTIFS('Source Data'!$C$21:$C$26,$C8)<>1,"",IF(INDEX('Source Data'!$G$21:$G$26,MATCH($C8,'Source Data'!$C$21:$C$26,0))="","",INDEX('Source Data'!$G$21:$G$26,MATCH($C8,'Source Data'!$C$21:$C$26,0)))) -> 2025 | H11: =IF(COUNTIFS('Source Data'!$C$21:$C$26,$C8)<>1,"",IF(INDEX('Source Data'!$G$21:$G$26,MATCH($C8,'Source Data'!$C$21:$C$26,0))="","",INDEX('Source Data'!$G$21:$G$26,MATCH($C8,'Source Data'!$C$21:$C$26,0)))) -> 2025 | I11: =IF(COUNTIFS('Source Data'!$C$21:$C$26,$C8)<>1,"",IF(INDEX('Source Data'!$G$21:$G$26,MATCH($C8,'Source Data'!$C$21:$C$26,0))="","",INDEX('Source Data'!$G$21:$G$26,MATCH($C8,'Source Data'!$C$21:$C$26,0)))) -> 2025
C12: Wage adjustment factor | D12: =IF(COUNT(D11,Assumptions!D$22,Assumptions!D$17)<3,"",IF(OR(Assumptions!D$22<0,Assumptions!D$22>1,YEAR(Assumptions!D$17)<D11),"",(1+Assumptions!D$22)^(YEAR(Assumptions!D$17)-D11))) -> 1.03 | E12: =IF(COUNT(E11,Assumptions!E$22,Assumptions!E$17)<3,"",IF(OR(Assumptions!E$22<0,Assumptions!E$22>1,YEAR(Assumptions!E$17)<E11),"",IF(D12="","",D12*(1+Assumptions!E$22)))) -> 1.0609 | F12: =IF(COUNT(F11,Assumptions!F$22,Assumptions!F$17)<3,"",IF(OR(Assumptions!F$22<0,Assumptions!F$22>1,YEAR(Assumptions!F$17)<F11),"",IF(E12="","",E12*(1+Assumptions!F$22)))) -> 1.092727 | G12: =IF(COUNT(G11,Assumptions!G$22,Assumptions!G$17)<3,"",IF(OR(Assumptions!G$22<0,Assumptions!G$22>1,YEAR(Assumptions!G$17)<G11),"",IF(F12="","",F12*(1+Assumptions!G$22)))) -> 1.1255088 | H12: =IF(COUNT(H11,Assumptions!H$22,Assumptions!H$17)<3,"",IF(OR(Assumptions!H$22<0,Assumptions!H$22>1,YEAR(Assumptions!H$17)<H11),"",IF(G12="","",G12*(1+Assumptions!H$22)))) -> 1.1592741 | I12: =IF(H12="","",H12) -> 1.1592741
C13: Adjusted wage / hour | D13: =IF(OR(D9<>"Build from wage",COUNT(D10,D12)<2,D10<0),"",D10*D12) -> 47.5963 | E13: =IF(OR(E9<>"Build from wage",COUNT(E10,E12)<2,E10<0),"",E10*E12) -> 49.024189 | F13: =IF(OR(F9<>"Build from wage",COUNT(F10,F12)<2,F10<0),"",F10*F12) -> 50.494915 | G13: =IF(OR(G9<>"Build from wage",COUNT(G10,G12)<2,G10<0),"",G10*G12) -> 52.009762 | H13: =IF(OR(H9<>"Build from wage",COUNT(H10,H12)<2,H10<0),"",H10*H12) -> 53.570055 | I13: =IF(OR(I9<>"Build from wage",COUNT(I10,I12)<2,I10<0),"",I10*I12) -> 53.570055
C14: Paid hours for cost | D14: =IF(Staffing!D16="","",Staffing!D16) -> 2351.3043 | E14: =IF(Staffing!E16="","",Staffing!E16) -> 2351.3043 | F14: =IF(Staffing!F16="","",Staffing!F16) -> 2351.3043 | G14: =IF(Staffing!G16="","",Staffing!G16) -> 2351.3043 | H14: =IF(Staffing!H16="","",Staffing!H16) -> 2351.3043 | I14: =IF(Staffing!I16="","",Staffing!I16) -> 1175.6522
